Workbook

Sheet Mecânica
C35: Disponível | D35: Pago | E35: %
B36: GERENTE COMERCIAL | C36: 0 | D36: 0 | E36: =IFERROR(D36/C36,) -> 0
B37: GERENTE DE VENDAS | C37: 0 | D37: 0 | E37: =IFERROR(D37/C37,) -> 0
B38: SUPERVISORES/CONSULTORES | C38: =300*2+500*2+750 -> 2350 | D38: 0 | E38: =IFERROR(D38/C38,) -> 0
B39: VENDEDORES | C39: =16*300 -> 4800 | D39: 0 | E39: =IFERROR(D39/C39,) -> 0
B40: MERCHANDISING EXTERNO | C40: 0 | D40: 0 | E40: =IFERROR(D40/C40,) -> 0
B41: MERCHANDISING INTERNO | C41: 0 | D41: 0 | E41: =IFERROR(D41/C41,) -> 0
B42: TOTAL | C42: =SUM(C35:C41) -> 7150 | D42: =SUM(D35:D41) -> 0 | E42: =IFERROR(D42/C42,) -> 0

Sheet Top Contas
C43: Disponível | D43: Pago | E43: %
B44: GERENTE COMERCIAL | C44: 0 | D44: 0 | E44: =IFERROR(D44/C44,) -> 0
B45: GERENTE DE VENDAS | C45: 0 | D45: 0 | E45: =IFERROR(D45/C45,) -> 0
B46: SUPERVISORES/CONSULTORES | C46: 0 | D46: 0 | E46: =IFERROR(D46/C46,) -> 0
B47: VENDEDORES | C47: 33600 | D47: 900 | E47: =IFERROR(D47/C47,) -> 0.026785714
B48: MERCHANDISING EXTERNO | C48: 0 | D48: 0 | E48: =IFERROR(D48/C48,) -> 0
B49: MERCHANDISING INTERNO | C49: 0 | D49: 0 | E49: =IFERROR(D49/C49,) -> 0
B50: TOTAL | C50: =SUM(C43:C49) -> 33600 | D50: =SUM(D43:D49) -> 900 | E50: =IFERROR(D50/C50,) -> 0.026785714

Sheet VENCEDORES
B3: CÓD | C3: ÁREA | D3: VENDEDOR/REPRESENTANTE | E3: TOP CONTAS | F3: % | G3: LOJA PERFEITA | H3: PONTOS
B4: 4054 | C4: MC-ARA D | D4: RAFAEL IZIDIO DE FARIAS | E4: 1039.625 | F4: 1.7304217 | G4: 81.883056 | H4: 300
B5: 3655 | C5: KA-BNU | D5: NATHAN FREITAS FUZINATO | E5: 3134.992 | F5: 1.523884 | G5: 83.07277 | H5: 300
B6: 3919 | C6: MC-TBCR D | D6: GISLAINE BORGES RODRIGUES | E6: 2809.707 | F6: 1.2974361 | G6: 79.834421
B7: 4066 | C7: MC-BNU D | D7: MURIEL DERCIO VOCKES | E7: 402.167 | F7: 1.2549639 | G7: 85.578333 | H7: 300
B8: 771 | C8: MC-FLP D | D8: JOAO JOSE NASCIMENTO | E8: 761.767 | F8: 1.0516404 | G8: 78.904167
B9: 179 | C9: KA-BRQ | D9: PEDRO PAULO ECCEL | E9: 1739.875 | F9: 0.98943851 | G9: 74.015278
B10: 3956 | C10: MC-IMB D | D10: RAFAEL BERNARDO VIEIRA | E10: 405.834 | F10: 0.73533905 | G10: 87.269444
B11: 359 | C11: MC-ITPE D | D11: MARCELO SCHEFFLER | E11: 1177.79 | F11: 0.58524215 | G11: 84.385

Sheet Geral
E3: EQUIPE | F3: REDE | G3: Q1 - JULHO A SETEMBRO | O3: JULHO | S3: AGOSTO | W3: SETEMBRO | AB3: Q2 - OUTUBRO A DEZEMBRO | AJ3: OUTUBRO | AN3: NOVEMBRO | AR3: DEZEMBRO | AW3: Q3 - JANEIRO A MARÇO | BE3: JANEIRO | BI3: FEVEREIRO | BM3: MARÇO | BR3: Q4 - ABRIL A JUNHO | BZ3: ABRIL | CD3: MAIO | CH3: JUNHO | CM3: TOP CONTAS FY26 ANO FISCAL
G4: HIST | H4: META | I4: FAT | J4: BONIF | K4: MÁQ | L4: % META | M4: % HIST | N4: GAP META | O4: HIST | P4: FAT | Q4: BONIF | R4: MÁQ | S4: HIST | T4: FAT | U4: BONIF | V4: MÁQ | W4: HIST | X4: FAT | Y4: BONIF | Z4: MÁQ | AB4: HIST | AC4: META | AD4: FAT | AE4: BONIF | AF4: MÁQ | AG4: % META | AH4: % HIST | AI4: GAP META | AJ4: HIST | AK4: FAT | AL4: BONIF | AM4: MÁQ | AN4: HIST | AO4: FAT | AP4: BONIF | AQ4: MÁQ | AR4: HIST | AS4: FAT | AT4: BONIF | AU4: MÁQ | AW4: HIST | AX4: META | AY4: FAT | AZ4: BONIF | BA4: MÁQ | BB4: % META | BC4: % HIST | BD4: GAP META | BE4: HIST | BF4: FAT | BG4: BONIF | BH4: MÁQ | BI4: HIST | BJ4: FAT | BK4: BONIF | BL4: MÁQ | BM4: HIST | BN4: FAT | BO4: BONIF | BP4: MÁQ | BR4: HIST | BS4: META | BT4: FAT | BU4: BONIF | BV4: MÁQ | BW4: % META | BX4: % HIST | BY4: GAP META | BZ4: HIST | CA4: FAT | CB4: BONIF | CC4: MÁQ | CD4: HIST | CE4: FAT | CF4: BONIF | CG4: MÁQ | CH4: HIST | CI4: FAT | CJ4: BONIF | CK4: MÁQ | CM4: HIST | CN4: META | CO4: FAT | CP4: BONIF | CQ4: MÁQ | CR4: % META | CS4: % HIST | CT4: GAP META
E5: FLP-SUL MC/KA D | F5: =SUMIF($B:$B,$E5,$F:$F) -> 8 | G5: =SUMIF(Rede!$C:$C,Geral!E5,Rede!$G:$G) -> 7355.454 | H5: =SUMIF(Rede!$C:$C,Geral!E5,Rede!$H:$H) -> 5014.67 | I5: =SUMIF(Rede!$C:$C,Geral!E5,Rede!$I:$I) -> 8042.895 | J5: =SUMIF(Rede!$C:$C,Geral!E5,Rede!$J:$J) -> 76.083 | K5: =SUMIF(Rede!$C:$C,Geral!E5,Rede!$K:$K) -> 0 | L5: =IFERROR((I5+K5+J5)/H5,0) -> 1.6190453 | M5: =IFERROR(((I5+K5+J5)/G5-1),0) -> 0.10380379 | N5: =H5-I5-J5-K5 -> -3104.308 | O5: =SUMIF(Rede!$C:$C,Geral!$E5,Rede!$O:$O) -> 672.315 | P5: =SUMIF(Rede!$C:$C,Geral!$E5,Rede!$P:$P) -> 965.562 | Q5: =SUMIF(Rede!$C:$C,Geral!$E5,Rede!$Q:$Q) -> 32.5 | R5: =SUMIF(Rede!$C:$C,Geral!$E5,Rede!$R:$R) -> 0 | S5: =SUMIF(Rede!$C:$C,Geral!$E5,Rede!$S:$S) -> 2531.329 | T5: =SUMIF(Rede!$C:$C,Geral!$E5,Rede!$T:$T) -> 2637.221 | U5: =SUMIF(Rede!$C:$C,Geral!$E5,Rede!$U:$U) -> 22.583 | V5: =SUMIF(Rede!$C:$C,Geral!$E5,Rede!$V:$V) -> 0 | W5: =SUMIF(Rede!$C:$C,Geral!$E5,Rede!$W:$W) -> 4151.81 | X5: =SUMIF(Rede!$C:$C,Geral!$E5,Rede!$X:$X) -> 4440.112 | Y5: =SUMIF(Rede!$C:$C,Geral!$E5,Rede!$Y:$Y) -> 21 | Z5: =SUMIF(Rede!$C:$C,Geral!$E5,Rede!$Z:$Z) -> 0 | AB5: =SUMIF(Rede!C:C,Geral!E5,Rede!$AB:$AB) -> 5155.36 | AC5: =SUMIF(Rede!C:C,Geral!E5,Rede!$AC:$AC) -> 4298.2769 | AD5: =SUMIF(Rede!C:C,Geral!E5,Rede!$AD:$AD) -> 4664.462 | AE5: =SUMIF(Rede!$C:$C,Geral!$E5,Rede!$AE:$AE) -> 121.375 | AF5: =SUMIF(Rede!C:C,Geral!E5,Rede!$AF:$AF) -> 0 | AG5: =(AD5+AF5+AE5)/AC5 -> 1.1134315 | AH5: =IFERROR(((AD5+AF5+AE5)/AB5-1),0) -> -0.071677439 | AI5: =AC5-AD5-AF5-AE5 -> -487.56007 | AJ5: =SUMIF(Rede!$C:$C,Geral!$E5,Rede!$AJ:$AJ) -> 2689.487 | AK5: =SUMIF(Rede!$C:$C,Geral!$E5,Rede!$AK:$AK) -> 1002.691 | AL5: =SUMIF(Rede!$C:$C,Geral!$E5,Rede!$AL:$AL) -> 45.125 | AM5: =SUMIF(Rede!$C:$C,Geral!$E5,Rede!$AM:$AM) -> 0 | AN5: =SUMIF(Rede!$C:$C,Geral!$E5,Rede!$AN:$AN) -> 577.554 | AO5: =SUMIF(Rede!$C:$C,Geral!$E5,Rede!$AO:$AO) -> 1355.487 | AP5: =SUMIF(Rede!$C:$C,Geral!$E5,Rede!$AP:$AP) -> 21.25 | AQ5: =SUMIF(Rede!$C:$C,Geral!$E5,Rede!$AQ:$AQ) -> 0 | AR5: =SUMIF(Rede!$C:$C,Geral!$E5,Rede!$AR:$AR) -> 1888.319 | AS5: =SUMIF(Rede!$C:$C,Geral!$E5,Rede!$AS:$AS) -> 2306.284 | AT5: =SUMIF(Rede!$C:$C,Geral!$E5,Rede!$AT:$AT) -> 55 | AU5: =SUMIF(Rede!$C:$C,Geral!$E5,Rede!$AU:$AU) -> 0 | AW5: =SUMIF(Rede!$C:$C,Geral!E5,Rede!$AW:$AW) -> 2879.008 | AX5: =SUMIF(Rede!$C:$C,Geral!E5,Rede!$AX:$AX) -> 4042.6382 | AY5: =SUMIF(Rede!$C:$C,Geral!E5,Rede!$AY:$AY) -> 4785.059 | AZ5: =SUMIF(Rede!$C:$C,Geral!E5,Rede!$AZ:$AZ) -> 231.874 | BA5: =SUMIF(Rede!$C:$C,Geral!E5,Rede!$BA:$BA) -> 0 | BB5: =(AY5+AZ5+BA5)/AX5 -> 1.2410047 | BC5: =IFERROR(((AY5+AZ5+BA5)/AW5-1),0) -> 0.74259085 | BD5: =AX5-AY5-BA5-AZ5 -> -974.29482 | BE5: =SUMIF(Rede!$C:$C,Geral!E5,Rede!$BE:$BE) -> 978.18 | BF5: =SUMIF(Rede!$C:$C,Geral!E5,Rede!$BF:$BF) -> 1112.809 | BG5: =SUMIF(Rede!$C:$C,Geral!E5,Rede!$BG:$BG) -> 38.833 | BH5: =SUMIF(Rede!$C:$C,Geral!E5,Rede!$BH:$BH) -> 0 | BI5: =SUMIF(Rede!$C:$C,Geral!E5,Rede!$BI:$BI) -> 705.655 | BJ5: =SUMIF(Rede!$C:$C,Geral!E5,Rede!$BJ:$BJ) -> 878.167 | BK5: =SUMIF(Rede!$C:$C,Geral!E5,Rede!$BK:$BK) -> 30.833 | BL5: =SUMIF(Rede!$C:$C,Geral!E5,Rede!$BL:$BL) -> 0 | BM5: =SUMIF(Rede!$C:$C,Geral!E5,Rede!$BM:$BM) -> 1195.173 | BN5: =SUMIF(Rede!$C:$C,Geral!E5,Rede!$BN:$BN) -> 2794.083 | BO5: =SUMIF(Rede!$C:$C,Geral!E5,Rede!$BO:$BO) -> 162.208 | BP5: =SUMIF(Rede!$C:$C,Geral!E5,Rede!$BP:$BP) -> 0 | BR5: =SUMIF(Rede!$C:$C,Geral!E5,Rede!$BR:$BR) -> 1380.273 | BS5: =SUMIF(Rede!$C:$C,Geral!E5,Rede!$BS:$BS) -> 4311 | BT5: =SUMIF(Rede!$C:$C,Geral!E5,Rede!$BT:$BT) -> 2336.748 | BU5: =SUMIF(Rede!$C:$C,Geral!E5,Rede!$BU:$BU) -> 0 | BV5: =SUMIF(Rede!$C:$C,Geral!E5,Rede!$BV:$BV) -> 67.333 | BW5: =(BT5+BU5+BV5)/BS5 -> 0.55766203 | BX5: =IFERROR(((BT5+BU5+BV5)/BR5-1),0) -> 0.74174312 | BY5: =BS5-BT5-BU5-BV5 -> 1906.919 | BZ5: =SUMIF(Rede!$C:$C,Geral!E5,Rede!$BZ:$BZ) -> 181.166 | CA5: =SUMIF(Rede!$C:$C,Geral!E5,Rede!$CA:$CA) -> 425.417 | CB5: =SUMIF(Rede!$C:$C,Geral!E5,Rede!$CB:$CB) -> 24.75 | CC5: =SUMIF(Rede!$C:$C,Geral!E5,Rede!$CC:$CC) -> 0 | CD5: =SUMIF(Rede!$C:$C,Geral!E5,Rede!$CD:$CD) -> 731.418 | CE5: =SUMIF(Rede!$C:$C,Geral!E5,Rede!$CE:$CE) -> 1002.013 | CF5: =SUMIF(Rede!$C:$C,Geral!E5,Rede!$CF:$CF) -> 21.083 | CG5: =SUMIF(Rede!$C:$C,Geral!E5,Rede!$CG:$CG) -> 0 | CH5: =SUMIF(Rede!$C:$C,Geral!E5,Rede!$CH:$CH) -> 467.689 | CI5: =SUMIF(Rede!$C:$C,Geral!E5,Rede!$CI:$CI) -> 909.318 | CJ5: =SUMIF(Rede!$C:$C,Geral!E5,Rede!$CJ:$CJ) -> 21.5 | CK5: =SUMIF(Rede!$C:$C,Geral!E5,Rede!$CK:$CK) -> 0 | CM5: =G5+AB5+AW5+BR5 -> 16770.095 | CN5: =H5+AC5+AX5+BS5 -> 17666.585 | CO5: =I5+AD5+AY5+BT5 -> 19829.164 | CP5: =J5+AE5+AZ5+BU5 -> 429.332 | CQ5: =K5+AF5+BA5+BV5 -> 67.333 | CR5: =(CO5+CP5+CQ5)/CN5 -> 1.1505239 | CS5: =IFERROR(((CO5+CP5+CQ5)/CM5-1),0) -> 0.21202826 | CT5: =CN5-CO5-CQ5-CP5 -> -2659.2439
E6: NORTE MC/KA D | F6: =SUMIF($B:$B,$E6,$F:$F) -> 6 | G6: =SUMIF(Rede!$C:$C,Geral!E6,Rede!$G:$G) -> 6984.345 | H6: =SUMIF(Rede!$C:$C,Geral!E6,Rede!$H:$H) -> 7627.01 | I6: =SUMIF(Rede!$C:$C,Geral!E6,Rede!$I:$I) -> 7415.409 | J6: =SUMIF(Rede!$C:$C,Geral!E6,Rede!$J:$J) -> 49.417 | K6: =SUMIF(Rede!$C:$C,Geral!E6,Rede!$K:$K) -> 0 | L6: =IFERROR((I6+K6+J6)/H6,0) -> 0.97873557 | M6: =IFERROR(((I6+K6+J6)/G6-1),0) -> 0.068793996 | N6: =H6-I6-J6-K6 -> 162.184 | O6: =SUMIF(Rede!$C:$C,Geral!$E6,Rede!$O:$O) -> 1183.824 | P6: =SUMIF(Rede!$C:$C,Geral!$E6,Rede!$P:$P) -> 976.417 | Q6: =SUMIF(Rede!$C:$C,Geral!$E6,Rede!$Q:$Q) -> 21.5 | R6: =SUMIF(Rede!$C:$C,Geral!$E6,Rede!$R:$R) -> 0 | S6: =SUMIF(Rede!$C:$C,Geral!$E6,Rede!$S:$S) -> 2362.854 | T6: =SUMIF(Rede!$C:$C,Geral!$E6,Rede!$T:$T) -> 2796.75 | U6: =SUMIF(Rede!$C:$C,Geral!$E6,Rede!$U:$U) -> 23.417 | V6: =SUMIF(Rede!$C:$C,Geral!$E6,Rede!$V:$V) -> 0 | W6: =SUMIF(Rede!$C:$C,Geral!$E6,Rede!$W:$W) -> 3437.667 | X6: =SUMIF(Rede!$C:$C,Geral!$E6,Rede!$X:$X) -> 3642.242 | Y6: =SUMIF(Rede!$C:$C,Geral!$E6,Rede!$Y:$Y) -> 4.5 | Z6: =SUMIF(Rede!$C:$C,Geral!$E6,Rede!$Z:$Z) -> 0 | AB6: =SUMIF(Rede!C:C,Geral!E6,Rede!$AB:$AB) -> 9176.73 | AC6: =SUMIF(Rede!C:C,Geral!E6,Rede!$AC:$AC) -> 6537.4414 | AD6: =SUMIF(Rede!C:C,Geral!E6,Rede!$AD:$AD) -> 4787.376 | AE6: =SUMIF(Rede!$C:$C,Geral!$E6,Rede!$AE:$AE) -> 42.583 | AF6: =SUMIF(Rede!C:C,Geral!E6,Rede!$AF:$AF) -> 0 | AG6: =(AD6+AF6+AE6)/AC6 -> 0.73881489 | AH6: =IFERROR(((AD6+AF6+AE6)/AB6-1),0) -> -0.47367319 | AI6: =AC6-AD6-AF6-AE6 -> 1707.4824 | AJ6: =SUMIF(Rede!$C:$C,Geral!$E6,Rede!$AJ:$AJ) -> 3747.229 | AK6: =SUMIF(Rede!$C:$C,Geral!$E6,Rede!$AK:$AK) -> 1864.833 | AL6: =SUMIF(Rede!$C:$C,Geral!$E6,Rede!$AL:$AL) -> 0 | AM6: =SUMIF(Rede!$C:$C,Geral!$E6,Rede!$AM:$AM) -> 0 | AN6: =SUMIF(Rede!$C:$C,Geral!$E6,Rede!$AN:$AN) -> 3037.917 | AO6: =SUMIF(Rede!$C:$C,Geral!$E6,Rede!$AO:$AO) -> 1235.876 | AP6: =SUMIF(Rede!$C:$C,Geral!$E6,Rede!$AP:$AP) -> 11.583 | AQ6: =SUMIF(Rede!$C:$C,Geral!$E6,Rede!$AQ:$AQ) -> 0 | AR6: =SUMIF(Rede!$C:$C,Geral!$E6,Rede!$AR:$AR) -> 2391.584 | AS6: =SUMIF(Rede!$C:$C,Geral!$E6,Rede!$AS:$AS) -> 1686.667 | AT6: =SUMIF(Rede!$C:$C,Geral!$E6,Rede!$AT:$AT) -> 31 | AU6: =SUMIF(Rede!$C:$C,Geral!$E6,Rede!$AU:$AU) -> 0 | AW6: =SUMIF(Rede!$C:$C,Geral!E6,Rede!$AW:$AW) -> 5615.021 | AX6: =SUMIF(Rede!$C:$C,Geral!E6,Rede!$AX:$AX) -> 6148.629 | AY6: =SUMIF(Rede!$C:$C,Geral!E6,Rede!$AY:$AY) -> 6309.574 | AZ6: =SUMIF(Rede!$C:$C,Geral!E6,Rede!$AZ:$AZ) -> 145.25 | BA6: =SUMIF(Rede!$C:$C,Geral!E6,Rede!$BA:$BA) -> 0 | BB6: =(AY6+AZ6+BA6)/AX6 -> 1.0497989 | BC6: =IFERROR(((AY6+AZ6+BA6)/AW6-1),0) -> 0.14956364 | BD6: =AX6-AY6-BA6-AZ6 -> -306.19503 | BE6: =SUMIF(Rede!$C:$C,Geral!E6,Rede!$BE:$BE) -> 1086.667 | BF6: =SUMIF(Rede!$C:$C,Geral!E6,Rede!$BF:$BF) -> 1425.708 | BG6: =SUMIF(Rede!$C:$C,Geral!E6,Rede!$BG:$BG) -> 21.75 | BH6: =SUMIF(Rede!$C:$C,Geral!E6,Rede!$BH:$BH) -> 0 | BI6: =SUMIF(Rede!$C:$C,Geral!E6,Rede!$BI:$BI) -> 1754.396 | BJ6: =SUMIF(Rede!$C:$C,Geral!E6,Rede!$BJ:$BJ) -> 2214.325 | BK6: =SUMIF(Rede!$C:$C,Geral!E6,Rede!$BK:$BK) -> 39.5 | BL6: =SUMIF(Rede!$C:$C,Geral!E6,Rede!$BL:$BL) -> 0 | BM6: =SUMIF(Rede!$C:$C,Geral!E6,Rede!$BM:$BM) -> 2773.958 | BN6: =SUMIF(Rede!$C:$C,Geral!E6,Rede!$BN:$BN) -> 2669.541 | BO6: =SUMIF(Rede!$C:$C,Geral!E6,Rede!$BO:$BO) -> 84 | BP6: =SUMIF(Rede!$C:$C,Geral!E6,Rede!$BP:$BP) -> 0 | BR6: =SUMIF(Rede!$C:$C,Geral!E6,Rede!$BR:$BR) -> 3588.429 | BS6: =SUMIF(Rede!$C:$C,Geral!E6,Rede!$BS:$BS) -> 6546 | BT6: =SUMIF(Rede!$C:$C,Geral!E6,Rede!$BT:$BT) -> 3378.96 | BU6: =SUMIF(Rede!$C:$C,Geral!E6,Rede!$BU:$BU) -> 225 | BV6: =SUMIF(Rede!$C:$C,Geral!E6,Rede!$BV:$BV) -> 132.5 | BW6: =(BT6+BU6+BV6)/BS6 -> 0.57080049 | BX6: =IFERROR(((BT6+BU6+BV6)/BR6-1),0) -> 0.041252314 | BY6: =BS6-BT6-BU6-BV6 -> 2809.54 | BZ6: =SUMIF(Rede!$C:$C,Geral!E6,Rede!$BZ:$BZ) -> 899.887 | CA6: =SUMIF(Rede!$C:$C,Geral!E6,Rede!$CA:$CA) -> 802.604 | CB6: =SUMIF(Rede!$C:$C,Geral!E6,Rede!$CB:$CB) -> 34.125 | CC6: =SUMIF(Rede!$C:$C,Geral!E6,Rede!$CC:$CC) -> 0 | CD6: =SUMIF(Rede!$C:$C,Geral!E6,Rede!$CD:$CD) -> 1268.625 | CE6: =SUMIF(Rede!$C:$C,Geral!E6,Rede!$CE:$CE) -> 1878.918 | CF6: =SUMIF(Rede!$C:$C,Geral!E6,Rede!$CF:$CF) -> 26.584 | CG6: =SUMIF(Rede!$C:$C,Geral!E6,Rede!$CG:$CG) -> 0 | CH6: =SUMIF(Rede!$C:$C,Geral!E6,Rede!$CH:$CH) -> 1419.917 | CI6: =SUMIF(Rede!$C:$C,Geral!E6,Rede!$CI:$CI) -> 697.438 | CJ6: =SUMIF(Rede!$C:$C,Geral!E6,Rede!$CJ:$CJ) -> 71.791 | CK6: =SUMIF(Rede!$C:$C,Geral!E6,Rede!$CK:$CK) -> 225 | CM6: =G6+AB6+AW6+BR6 -> 25364.525 | CN6: =H6+AC6+AX6+BS6 -> 26859.08 | CO6: =I6+AD6+AY6+BT6 -> 21891.319 | CP6: =J6+AE6+AZ6+BU6 -> 462.25 | CQ6: =K6+AF6+BA6+BV6 -> 132.5 | CR6: =(CO6+CP6+CQ6)/CN6 -> 0.83718686 | CS6: =IFERROR(((CO6+CP6+CQ6)/CM6-1),0) -> -0.11348354 | CT6: =CN6-CO6-CQ6-CP6 -> 4373.0113
F7: =SUM(F5:F6) -> 14 | G7: =SUM(G5:G6) -> 14339.799 | H7: =SUM(H5:H6) -> 12641.68 | I7: =SUM(I5:I6) -> 15458.304 | J7: =SUM(J5:J6) -> 125.5 | K7: =SUM(K5:K6) -> 0 | L7: =IFERROR((I7+K7+J7)/H7,0) -> 1.232732 | M7: =IFERROR(((I7+K7+J7)/G7-1),0) -> 0.086751913 | N7: =H7-I7-J7-K7 -> -2942.124 | O7: =SUM(O5:O6) -> 1856.139 | P7: =SUM(P5:P6) -> 1941.979 | Q7: =SUM(Q5:Q6) -> 54 | R7: =SUM(R5:R6) -> 0 | S7: =SUM(S5:S6) -> 4894.183 | T7: =SUM(T5:T6) -> 5433.971 | U7: =SUM(U5:U6) -> 46 | V7: =SUM(V5:V6) -> 0 | ... Z7: =SUM(Z5:Z6) -> 0 | AB7: =SUM(AB5:AB6) -> 14332.09 | AC7: =SUM(AC5:AC6) -> 10835.718 | AD7: =SUM(AD5:AD6) -> 9451.838 | AE7: =SUM(AE5:AE6) -> 163.958 | AF7: =SUM(AF5:AF6) -> 0 | AG7: =(AD7+AF7+AE7)/AC7 -> 0.88741657 | AH7: =IFERROR(((AD7+AF7+AE7)/AB7-1),0) -> -0.32907231 | AI7: =AC7-AD7-AF7-AE7 -> 1219.9223 | AJ7: =SUM(AJ5:AJ6) -> 6436.716 | AK7: =SUM(AK5:AK6) -> 2867.524 | AL7: =SUM(AL5:AL6) -> 45.125 | AM7: =SUM(AM5:AM6) -> 0 | AN7: =SUM(AN5:AN6) -> 3615.471 | AO7: =SUM(AO5:AO6) -> 2591.363 | AP7: =SUM(AP5:AP6) -> 32.833 | AQ7: =SUM(AQ5:AQ6) -> 0 | ... AU7: =SUM(AU5:AU6) -> 0 | AW7: =SUM(AW5:AW6) -> 8494.029 | AX7: =SUM(AX5:AX6) -> 10191.267 | AY7: =SUM(AY5:AY6) -> 11094.633 | AZ7: =SUM(AZ5:AZ6) -> 377.124 | BA7: =SUM(BA5:BA6) -> 0 | BB7: =(AY7+AZ7+BA7)/AX7 -> 1.1256458 | BC7: =IFERROR(((AY7+AZ7+BA7)/AW7-1),0) -> 0.3505672 | BD7: =AX7-AY7-BA7-AZ7 -> -1280.4899 | BE7: =SUM(BE5:BE6) -> 2064.847 | BF7: =SUM(BF5:BF6) -> 2538.517 | BG7: =SUM(BG5:BG6) -> 60.583 | BH7: =SUM(BH5:BH6) -> 0 | BI7: =SUM(BI5:BI6) -> 2460.051 | BJ7: =SUM(BJ5:BJ6) -> 3092.492 | BK7: =SUM(BK5:BK6) -> 70.333 | BL7: =SUM(BL5:BL6) -> 0 | ... BP7: =SUM(BP5:BP6) -> 0 | BR7: =SUM(BR5:BR6) -> 4968.702 | BS7: =SUM(BS5:BS6) -> 10857 | BT7: =SUM(BT5:BT6) -> 5715.708 | BU7: =SUM(BU5:BU6) -> 225 | BV7: =SUM(BV5:BV6) -> 199.833 | BW7: =(BT7+BU7+BV7)/BS7 -> 0.56558359 | BX7: =IFERROR(((BT7+BU7+BV7)/BR7-1),0) -> 0.23584409 | BY7: =BS7-BT7-BU7-BV7 -> 4716.459 | BZ7: =SUM(BZ5:BZ6) -> 1081.053 | CA7: =SUM(CA5:CA6) -> 1228.021 | CB7: =SUM(CB5:CB6) -> 58.875 | CC7: =SUM(CC5:CC6) -> 0 | CD7: =SUM(CD5:CD6) -> 2000.043 | CE7: =SUM(CE5:CE6) -> 2880.931 | CF7: =SUM(CF5:CF6) -> 47.667 | CG7: =SUM(CG5:CG6) -> 0 | ... CK7: =SUM(CK5:CK6) -> 225 | CM7: =SUM(CM5:CM6) -> 42134.62 | CN7: =SUM(CN5:CN6) -> 44525.665 | CO7: =SUM(CO5:CO6) -> 41720.483 | CP7: =SUM(CP5:CP6) -> 891.582 | CQ7: =SUM(CQ5:CQ6) -> 199.833 | CR7: =(CO7+CP7+CQ7)/CN7 -> 0.96151057 | CS7: =IFERROR(((CO7+CP7+CQ7)/CM7-1),0) -> 0.016074145 | CT7: =CN7-CO7-CQ7-CP7 -> 1713.7674
E8: ATUALIZADO:
E9: 46197
B10: JOHNSON - TOP CONTAS FY26 | F10: REDE | G10: Q1 - JULHO A SETEMBRO | O10: JULHO | S10: AGOSTO | W10: SETEMBRO | AB10: Q2 - OUTUBRO A DEZEMBRO | AJ10: OUTUBRO | AN10: NOVEMBRO | AR10: DEZEMBRO | AW10: Q3 - JANEIRO A MARÇO | BE10: JANEIRO | BI10: FEVEREIRO | BM10: MARÇO | BR10: Q4 - ABRIL A JUNHO | BZ10: ABRIL | CD10: MAIO | CH10: JUNHO | CM10: TOP CONTAS FY26 ANO FISCAL
B11: EQUIPE | C11: CÓD | D11: ÁREA | E11: VENDEDOR/REPRESENTANTE | G11: HIST | H11: META | I11: FAT | J11: BONIF | K11: MÁQ | L11: % META | M11: % HIST | N11: GAP META | O11: HIST | P11: FAT | Q11: BONIF | R11: MÁQ | S11: HIST | T11: FAT | U11: BONIF | V11: MÁQ | W11: HIST | X11: FAT | Y11: BONIF | Z11: MÁQ | AB11: HIST | AC11: META | AD11: FAT | AE11: BONIF | AF11: MÁQ | AG11: % META | AH11: % HIST | AI11: GAP META | AJ11: HIST | AK11: FAT | AL11: BONIF | AM11: MÁQ | AN11: HIST | AO11: FAT | AP11: BONIF | AQ11: MÁQ | AR11: HIST | AS11: FAT | AT11: BONIF | AU11: MÁQ | AW11: HIST | AX11: META | AY11: FAT | AZ11: BONIF | BA11: MÁQ | BB11: % META | BC11: % HIST | BD11: GAP META | BE11: HIST | BF11: FAT | BG11: BONIF | BH11: MÁQ | BI11: HIST | BJ11: FAT | BK11: BONIF | BL11: MÁQ | BM11: HIST | BN11: FAT | BO11: BONIF | BP11: MÁQ | BR11: HIST | BS11: META | BT11: FAT | BU11: BONIF | BV11: MÁQ | BW11: % META | BX11: % HIST | BY11: GAP META | BZ11: HIST | CA11: FAT | CB11: BONIF | CC11: MÁQ | CD11: HIST | CE11: FAT | CF11: BONIF | CG11: MÁQ | CH11: HIST | CI11: FAT | CJ11: BONIF | CK11: MÁQ | CM11: HIST | CN11: META | CO11: FAT | CP11: BONIF | CQ11: MÁQ | CR11: % META | CS11: % HIST | CT11: GAP META
B12: FLP-SUL MC/KA D | C12: 771 | D12: MC-FLP D | E12: JOAO JOSE NASCIMENTO | F12: =COUNTIF(Rede!$D:$D,Geral!$C12) -> 1 | G12: =SUMIF(Rede!$D:$D,Geral!C12,Rede!$G:$G) -> 1650.944 | H12: =SUMIF(Rede!$D:$D,Geral!C12,Rede!$H:$H) -> 898.53 | I12: =SUMIF(Rede!$D:$D,Geral!C12,Rede!$I:$I) -> 690.575 | J12: =SUMIF(Rede!$D:$D,Geral!$C12,Rede!$J:$J) -> 0 | K12: =SUMIF(Rede!$D:$D,Geral!C12,Rede!$K:$K) -> 0 | L12: =IFERROR((I12+K12+J12)/H12,0) -> 0.76856087 | M12: =IFERROR(((I12+K12+J12)/G12-1),0) -> -0.58170901 | N12: =H12-I12-J12-K12 -> 207.955 | O12: =SUMIF(Rede!$D:$D,Geral!$C12,Rede!$O:$O) -> 270.844 | P12: =SUMIF(Rede!$D:$D,Geral!$C12,Rede!$P:$P) -> 10.708 | Q12: =SUMIF(Rede!$D:$D,Geral!$C12,Rede!$Q:$Q) -> 0 | R12: =SUMIF(Rede!$D:$D,Geral!$C12,Rede!$R:$R) -> 0 | S12: =SUMIF(Rede!$D:$D,Geral!$C12,Rede!$S:$S) -> 854.558 | T12: =SUMIF(Rede!$D:$D,Geral!$C12,Rede!$T:$T) -> 803.7 | U12: =SUMIF(Rede!$D:$D,Geral!$C12,Rede!$U:$U) -> 0 | V12: =SUMIF(Rede!$D:$D,Geral!$C12,Rede!$V:$V) -> 0 | W12: =SUMIF(Rede!$D:$D,Geral!$C12,Rede!$W:$W) -> 525.542 | X12: =SUMIF(Rede!$D:$D,Geral!$C12,Rede!$X:$X) -> -123.833 | Y12: =SUMIF(Rede!$D:$D,Geral!$C12,Rede!$Y:$Y) -> 0 | Z12: =SUMIF(Rede!$D:$D,Geral!$C12,Rede!$Z:$Z) -> 0 | AB12: =SUMIF(Rede!D:D,Geral!C12,Rede!$AB:$AB) -> 1068.366 | AC12: =SUMIF(Rede!D:D,Geral!C12,Rede!$AC:$AC) -> 770.16614 | AD12: =SUMIF(Rede!D:D,Geral!C12,Rede!$AD:$AD) -> 557.392 | AE12: =SUMIF(Rede!$D:$D,Geral!$C12,Rede!$AE:$AE) -> 0 | AF12: =SUMIF(Rede!D:D,Geral!C12,Rede!$AF:$AF) -> 0 | AG12: =(AD12+AF12+AE12)/AC12 -> 0.72372955 | AH12: =IFERROR(((AD12+AF12+AE12)/AB12-1),0) -> -0.47827617 | AI12: =AC12-AD12-AF12-AE12 -> 212.77414 | AJ12: =SUMIF(Rede!$D:$D,Geral!$C12,Rede!$AJ:$AJ) -> 814.133 | AK12: =SUMIF(Rede!$D:$D,Geral!$C12,Rede!$AK:$AK) -> 230.108 | AL12: =SUMIF(Rede!$D:$D,Geral!$C12,Rede!$AL:$AL) -> 0 | AM12: =SUMIF(Rede!$D:$D,Geral!$C12,Rede!$AM:$AM) -> 0 | AN12: =SUMIF(Rede!$D:$D,Geral!$C12,Rede!$AN:$AN) -> 111.858 | AO12: =SUMIF(Rede!$D:$D,Geral!$C12,Rede!$AO:$AO) -> 158.5 | AP12: =SUMIF(Rede!$D:$D,Geral!$C12,Rede!$AP:$AP) -> 0 | AQ12: =SUMIF(Rede!$D:$D,Geral!$C12,Rede!$AQ:$AQ) -> 0 | AR12: =SUMIF(Rede!$D:$D,Geral!$C12,Rede!$AR:$AR) -> 142.375 | AS12: =SUMIF(Rede!$D:$D,Geral!$C12,Rede!$AS:$AS) -> 168.784 | AT12: =SUMIF(Rede!$D:$D,Geral!$C12,Rede!$AT:$AT) -> 0 | AU12: =SUMIF(Rede!$D:$D,Geral!$C12,Rede!$AU:$AU) -> 0 | AW12: =SUMIF(Rede!$D:$D,Geral!C12,Rede!$AW:$AW) -> 455.592 | AX12: =SUMIF(Rede!$D:$D,Geral!C12,Rede!$AX:$AX) -> 724.36074 | AY12: =SUMIF(Rede!$D:$D,Geral!C12,Rede!$AY:$AY) -> 761.767 | AZ12: =SUMIF(Rede!$D:$D,Geral!C12,Rede!$AZ:$AZ) -> 0 | BA12: =SUMIF(Rede!$D:$D,Geral!C12,Rede!$BA:$BA) -> 0 | BB12: =(AY12+AZ12+BA12)/AX12 -> 1.0516404 | BC12: =IFERROR(((AY12+AZ12+BA12)/AW12-1),0) -> 0.6720377 | BD12: =AX12-AY12-BA12-AZ12 -> -37.40626 | BE12: =SUMIF(Rede!$D:$D,Geral!C12,Rede!$BE:$BE) -> 286.55 | BF12: =SUMIF(Rede!$D:$D,Geral!C12,Rede!$BF:$BF) -> 102.017 | BG12: =SUMIF(Rede!$D:$D,Geral!C12,Rede!$BG:$BG) -> 0 | BH12: =SUMIF(Rede!D:D,Geral!C12,Rede!$BH:$BH) -> 0 | BI12: =SUMIF(Rede!$D:$D,Geral!C12,Rede!$BI:$BI) -> 82.959 | BJ12: =SUMIF(Rede!$D:$D,Geral!C12,Rede!$BJ:$BJ) -> 68.25 | BK12: =SUMIF(Rede!$D:$D,Geral!C12,Rede!$BK:$BK) -> 0 | BL12: =SUMIF(Rede!$D:$D,Geral!C12,Rede!$BL:$BL) -> 0 | BM12: =SUMIF(Rede!$D:$D,Geral!C12,Rede!$BM:$BM) -> 86.083 | BN12: =SUMIF(Rede!$D:$D,Geral!C12,Rede!$BN:$BN) -> 591.5 | BO12: =SUMIF(Rede!$D:$D,Geral!C12,Rede!$BO:$BO) -> 0 | BP12: =SUMIF(Rede!$D:$D,Geral!C12,Rede!$BP:$BP) -> 0 | BR12: =SUMIF(Rede!$D:$D,Geral!C12,Rede!$BR:$BR) -> 151.605 | BS12: =SUMIF(Rede!$D:$D,Geral!C12,Rede!$BS:$BS) -> 771 | BT12: =SUMIF(Rede!$D:$D,Geral!C12,Rede!$BT:$BT) -> 79.889 | BU12: =SUMIF(Rede!$D:$D,Geral!C12,Rede!$BU:$BU) -> 0 | BV12: =SUMIF(Rede!$D:$D,Geral!C12,Rede!$BV:$BV) -> 0 | BW12: =(BT12+BU12+BV12)/BS12 -> 0.10361738 | BX12: =IFERROR(((BT12+BU12+BV12)/BR12-1),0) -> -0.47304508 | BY12: =BS12-BT12-BU12-BV12 -> 691.111 | BZ12: =SUMIF(Rede!$D:$D,Geral!C12,Rede!$BZ:$BZ) -> 24.083 | CA12: =SUMIF(Rede!$D:$D,Geral!C12,Rede!$CA:$CA) -> -121 | CB12: =SUMIF(Rede!$D:$D,Geral!C12,Rede!$CB:$CB) -> 0 | CC12: =SUMIF(Rede!$D:$D,Geral!C12,Rede!$CC:$CC) -> 0 | CD12: =SUMIF(Rede!$D:$D,Geral!C12,Rede!$CD:$CD) -> 59.867 | CE12: =SUMIF(Rede!$D:$D,Geral!C12,Rede!$CE:$CE) -> 111.25 | CF12: =SUMIF(Rede!$D:$D,Geral!C12,Rede!$CF:$CF) -> 0 | CG12: =SUMIF(Rede!$D:$D,Geral!C12,Rede!$CG:$CG) -> 0 | CH12: =SUMIF(Rede!$D:$D,Geral!C12,Rede!$CH:$CH) -> 67.655 | CI12: =SUMIF(Rede!$D:$D,Geral!C12,Rede!$CI:$CI) -> 89.639 | CJ12: =SUMIF(Rede!$D:$D,Geral!C12,Rede!$CJ:$CJ) -> 0 | CK12: =SUMIF(Rede!$D:$D,Geral!C12,Rede!$CK:$CK) -> 0 | CM12: =G12+AB12+AW12+BR12 -> 3326.507 | CN12: =H12+AC12+AX12+BS12 -> 3164.0569 | CO12: =I12+AD12+AY12+BT12 -> 2089.623 | CP12: =J12+AE12+AZ12+BU12 -> 0 | CQ12: =K12+AF12+BA12+BV12 -> 0 | CR12: =(CO12+CP12+CQ12)/CN12 -> 0.66042523 | CS12: =IFERROR(((CO12+CP12+CQ12)/CM12-1),0) -> -0.37182666 | CT12: =CN12-CO12-CQ12-CP12 -> 1074.4339
B13: FLP-SUL MC/KA D | C13: 3919 | D13: MC-TBCR D | E13: GISLAINE BORGES RODRIGUES | F13: =COUNTIF(Rede!$D:$D,Geral!$C13) -> 4 | G13: =SUMIF(Rede!$D:$D,Geral!C13,Rede!$G:$G) -> 3551.218 | H13: =SUMIF(Rede!$D:$D,Geral!C13,Rede!$H:$H) -> 2686.29 | I13: =SUMIF(Rede!$D:$D,Geral!C13,Rede!$I:$I) -> 5346.376 | J13: =SUMIF(Rede!$D:$D,Geral!$C13,Rede!$J:$J) -> 75.083 | K13: =SUMIF(Rede!$D:$D,Geral!C13,Rede!$K:$K) -> 0 | L13: =IFERROR((I13+K13+J13)/H13,0) -> 2.0181957 | M13: =IFERROR(((I13+K13+J13)/G13-1),0) -> 0.52664776 | N13: =H13-I13-J13-K13 -> -2735.169 | O13: =SUMIF(Rede!$D:$D,Geral!$C13,Rede!$O:$O) -> 214.888 | P13: =SUMIF(Rede!$D:$D,Geral!$C13,Rede!$P:$P) -> 750.521 | Q13: =SUMIF(Rede!$D:$D,Geral!$C13,Rede!$Q:$Q) -> 31.5 | R13: =SUMIF(Rede!$D:$D,Geral!$C13,Rede!$R:$R) -> 0 | S13: =SUMIF(Rede!$D:$D,Geral!$C13,Rede!$S:$S) -> 307.271 | T13: =SUMIF(Rede!$D:$D,Geral!$C13,Rede!$T:$T) -> 1621.521 | U13: =SUMIF(Rede!$D:$D,Geral!$C13,Rede!$U:$U) -> 22.583 | V13: =SUMIF(Rede!$D:$D,Geral!$C13,Rede!$V:$V) -> 0 | W13: =SUMIF(Rede!$D:$D,Geral!$C13,Rede!$W:$W) -> 3029.059 | X13: =SUMIF(Rede!$D:$D,Geral!$C13,Rede!$X:$X) -> 2974.334 | Y13: =SUMIF(Rede!$D:$D,Geral!$C13,Rede!$Y:$Y) -> 21 | Z13: =SUMIF(Rede!$D:$D,Geral!$C13,Rede!$Z:$Z) -> 0 | AB13: =SUMIF(Rede!D:D,Geral!C13,Rede!$AB:$AB) -> 3310.571 | AC13: =SUMIF(Rede!D:D,Geral!C13,Rede!$AC:$AC) -> 2302.5261 | AD13: =SUMIF(Rede!D:D,Geral!C13,Rede!$AD:$AD) -> 3064.618 | AE13: =SUMIF(Rede!$D:$D,Geral!$C13,Rede!$AE:$AE) -> 90.375 | AF13: =SUMIF(Rede!D:D,Geral!C13,Rede!$AF:$AF) -> 0 | AG13: =(AD13+AF13+AE13)/AC13 -> 1.3702311 | AH13: =IFERROR(((AD13+AF13+AE13)/AB13-1),0) -> -0.04699431 | AI13: =AC13-AD13-AF13-AE13 -> -852.46689 | AJ13: =SUMIF(Rede!$D:$D,Geral!$C13,Rede!$AJ:$AJ) -> 1575.708 | AK13: =SUMIF(Rede!$D:$D,Geral!$C13,Rede!$AK:$AK) -> 631.833 | AL13: =SUMIF(Rede!$D:$D,Geral!$C13,Rede!$AL:$AL) -> 41.625 | AM13: =SUMIF(Rede!$D:$D,Geral!$C13,Rede!$AM:$AM) -> 0 | AN13: =SUMIF(Rede!$D:$D,Geral!$C13,Rede!$AN:$AN) -> 313.613 | AO13: =SUMIF(Rede!$D:$D,Geral!$C13,Rede!$AO:$AO) -> 1032.952 | AP13: =SUMIF(Rede!$D:$D,Geral!$C13,Rede!$AP:$AP) -> 18 | AQ13: =SUMIF(Rede!$D:$D,Geral!$C13,Rede!$AQ:$AQ) -> 0 | AR13: =SUMIF(Rede!$D:$D,Geral!$C13,Rede!$AR:$AR) -> 1421.25 | AS13: =SUMIF(Rede!$D:$D,Geral!$C13,Rede!$AS:$AS) -> 1399.833 | AT13: =SUMIF(Rede!$D:$D,Geral!$C13,Rede!$AT:$AT) -> 30.75 | AU13: =SUMIF(Rede!$D:$D,Geral!$C13,Rede!$AU:$AU) -> 0 | AW13: =SUMIF(Rede!$D:$D,Geral!C13,Rede!$AW:$AW) -> 1272.979 | AX13: =SUMIF(Rede!$D:$D,Geral!C13,Rede!$AX:$AX) -> 2165.5841 | AY13: =SUMIF(Rede!$D:$D,Geral!C13,Rede!$AY:$AY) -> 2641.541 | AZ13: =SUMIF(Rede!$D:$D,Geral!C13,Rede!$AZ:$AZ) -> 168.166 | BA13: =SUMIF(Rede!$D:$D,Geral!C13,Rede!$BA:$BA) -> 0 | BB13: =(AY13+AZ13+BA13)/AX13 -> 1.2974361 | BC13: =IFERROR(((AY13+AZ13+BA13)/AW13-1),0) -> 1.2071904 | BD13: =AX13-AY13-BA13-AZ13 -> -644.12295 | BE13: =SUMIF(Rede!D:D,Geral!C13,Rede!$BE:$BE) -> 210.538 | BF13: =SUMIF(Rede!D:D,Geral!C13,Rede!$BF:$BF) -> 664.625 | BG13: =SUMIF(Rede!D:D,Geral!C13,Rede!$BG:$BG) -> 33.833 | BH13: =SUMIF(Rede!D:D,Geral!C13,Rede!$BH:$BH) -> 0 | BI13: =SUMIF(Rede!$D:$D,Geral!C13,Rede!$BI:$BI) -> 351.755 | BJ13: =SUMIF(Rede!$D:$D,Geral!C13,Rede!$BJ:$BJ) -> 666.583 | BK13: =SUMIF(Rede!$D:$D,Geral!C13,Rede!$BK:$BK) -> 30.833 | BL13: =SUMIF(Rede!$D:$D,Geral!C13,Rede!$BL:$BL) -> 0 | BM13: =SUMIF(Rede!$D:$D,Geral!C13,Rede!$BM:$BM) -> 710.686 | BN13: =SUMIF(Rede!$D:$D,Geral!C13,Rede!$BN:$BN) -> 1310.333 | BO13: =SUMIF(Rede!$D:$D,Geral!C13,Rede!$BO:$BO) -> 103.5 | BP13: =SUMIF(Rede!$D:$D,Geral!C13,Rede!$BP:$BP) -> 0 | BR13: =SUMIF(Rede!$D:$D,Geral!C13,Rede!$BR:$BR) -> 640.002 | BS13: =SUMIF(Rede!$D:$D,Geral!C13,Rede!$BS:$BS) -> 2310 | BT13: =SUMIF(Rede!$D:$D,Geral!C13,Rede!$BT:$BT) -> 1492.776 | BU13: =SUMIF(Rede!$D:$D,Geral!C13,Rede!$BU:$BU) -> 0 | BV13: =SUMIF(Rede!$D:$D,Geral!C13,Rede!$BV:$BV) -> 62.583 | BW13: =(BT13+BU13+BV13)/BS13 -> 0.67331558 | BX13: =IFERROR(((BT13+BU13+BV13)/BR13-1),0) -> 1.4302408 | BY13: =BS13-BT13-BU13-BV13 -> 754.641 | BZ13: =SUMIF(Rede!$D:$D,Geral!C13,Rede!$BZ:$BZ) -> 28.959 | CA13: =SUMIF(Rede!$D:$D,Geral!C13,Rede!$CA:$CA) -> 405.501 | CB13: =SUMIF(Rede!$D:$D,Geral!C13,Rede!$CB:$CB) -> 24.75 | CC13: =SUMIF(Rede!$D:$D,Geral!C13,Rede!$CC:$CC) -> 0 | CD13: =SUMIF(Rede!$D:$D,Geral!C13,Rede!$CD:$CD) -> 474.217 | CE13: =SUMIF(Rede!$D:$D,Geral!C13,Rede!$CE:$CE) -> 635.596 | CF13: =SUMIF(Rede!$D:$D,Geral!C13,Rede!$CF:$CF) -> 21.083 | CG13: =SUMIF(Rede!$D:$D,Geral!C13,Rede!$CG:$CG) -> 0 | CH13: =SUMIF(Rede!$D:$D,Geral!C13,Rede!$CH:$CH) -> 136.826 | CI13: =SUMIF(Rede!$D:$D,Geral!C13,Rede!$CI:$CI) -> 451.679 | CJ13: =SUMIF(Rede!$D:$D,Geral!C13,Rede!$CJ:$CJ) -> 16.75 | CK13: =SUMIF(Rede!$D:$D,Geral!C13,Rede!$CK:$CK) -> 0 | CM13: =G13+AB13+AW13+BR13 -> 8774.77 | CN13: =H13+AC13+AX13+BS13 -> 9464.4002 | CO13: =I13+AD13+AY13+BT13 -> 12545.311 | CP13: =J13+AE13+AZ13+BU13 -> 333.624 | CQ13: =K13+AF13+BA13+BV13 -> 62.583 | CR13: =(CO13+CP13+CQ13)/CN13 -> 1.3673891 | CS13: =IFERROR(((CO13+CP13+CQ13)/CM13-1),0) -> 0.47485552 | CT13: =CN13-CO13-CQ13-CP13 -> -3477.1178
B14: FLP-SUL MC/KA D | C14: 3956 | D14: MC-IMB D | E14: RAFAEL BERNARDO VIEIRA | F14: =COUNTIF(Rede!$D:$D,Geral!$C14) -> 1 | G14: =SUMIF(Rede!$D:$D,Geral!C14,Rede!$G:$G) -> 902.167 | H14: =SUMIF(Rede!$D:$D,Geral!C14,Rede!$H:$H) -> 684.6 | I14: =SUMIF(Rede!$D:$D,Geral!C14,Rede!$I:$I) -> 1216.569 | J14: =SUMIF(Rede!$D:$D,Geral!$C14,Rede!$J:$J) -> 0 | K14: =SUMIF(Rede!$D:$D,Geral!C14,Rede!$K:$K) -> 0 | L14: =IFERROR((I14+K14+J14)/H14,0) -> 1.7770508 | M14: =IFERROR(((I14+K14+J14)/G14-1),0) -> 0.34849645 | N14: =H14-I14-J14-K14 -> -531.969 | O14: =SUMIF(Rede!$D:$D,Geral!$C14,Rede!$O:$O) -> 44.625 | P14: =SUMIF(Rede!$D:$D,Geral!$C14,Rede!$P:$P) -> 70.833 | Q14: =SUMIF(Rede!$D:$D,Geral!$C14,Rede!$Q:$Q) -> 0 | R14: =SUMIF(Rede!$D:$D,Geral!$C14,Rede!$R:$R) -> 0 | S14: =SUMIF(Rede!$D:$D,Geral!$C14,Rede!$S:$S) -> 854.875 | T14: =SUMIF(Rede!$D:$D,Geral!$C14,Rede!$T:$T) -> 10.5 | U14: =SUMIF(Rede!$D:$D,Geral!$C14,Rede!$U:$U) -> 0 | V14: =SUMIF(Rede!$D:$D,Geral!$C14,Rede!$V:$V) -> 0 | W14: =SUMIF(Rede!$D:$D,Geral!$C14,Rede!$W:$W) -> 2.667 | X14: =SUMIF(Rede!$D:$D,Geral!$C14,Rede!$X:$X) -> 1135.236 | Y14: =SUMIF(Rede!$D:$D,Geral!$C14,Rede!$Y:$Y) -> 0 | Z14: =SUMIF(Rede!$D:$D,Geral!$C14,Rede!$Z:$Z) -> 0 | AB14: =SUMIF(Rede!D:D,Geral!C14,Rede!$AB:$AB) -> 468.896 | AC14: =SUMIF(Rede!D:D,Geral!C14,Rede!$AC:$AC) -> 586.80029 | AD14: =SUMIF(Rede!D:D,Geral!C14,Rede!$AD:$AD) -> 259.119 | AE14: =SUMIF(Rede!$D:$D,Geral!$C14,Rede!$AE:$AE) -> 3.5 | AF14: =SUMIF(Rede!D:D,Geral!C14,Rede!$AF:$AF) -> 0 | AG14: =(AD14+AF14+AE14)/AC14 -> 0.44754409 | AH14: =IFERROR(((AD14+AF14+AE14)/AB14-1),0) -> -0.43992058 | AI14: =AC14-AD14-AF14-AE14 -> 324.18129 | AJ14: =SUMIF(Rede!$D:$D,Geral!$C14,Rede!$AJ:$AJ) -> 259.313 | AK14: =SUMIF(Rede!$D:$D,Geral!$C14,Rede!$AK:$AK) -> 22.167 | AL14: =SUMIF(Rede!$D:$D,Geral!$C14,Rede!$AL:$AL) -> 3.5 | AM14: =SUMIF(Rede!$D:$D,Geral!$C14,Rede!$AM:$AM) -> 0 | AN14: =SUMIF(Rede!$D:$D,Geral!$C14,Rede!$AN:$AN) -> 15 | AO14: =SUMIF(Rede!$D:$D,Geral!$C14,Rede!$AO:$AO) -> 42.285 | AP14: =SUMIF(Rede!$D:$D,Geral!$C14,Rede!$AP:$AP) -> 0 | AQ14: =SUMIF(Rede!$D:$D,Geral!$C14,Rede!$AQ:$AQ) -> 0 | AR14: =SUMIF(Rede!$D:$D,Geral!$C14,Rede!$AR:$AR) -> 194.583 | AS14: =SUMIF(Rede!$D:$D,Geral!$C14,Rede!$AS:$AS) -> 194.667 | AT14: =SUMIF(Rede!$D:$D,Geral!$C14,Rede!$AT:$AT) -> 0 | AU14: =SUMIF(Rede!$D:$D,Geral!$C14,Rede!$AU:$AU) -> 0 | AW14: =SUMIF(Rede!$D:$D,Geral!C14,Rede!$AW:$AW) -> 660.291 | AX14: =SUMIF(Rede!$D:$D,Geral!C14,Rede!$AX:$AX) -> 551.90051 | AY14: =SUMIF(Rede!$D:$D,Geral!C14,Rede!$AY:$AY) -> 399.251 | AZ14: =SUMIF(Rede!$D:$D,Geral!C14,Rede!$AZ:$AZ) -> 6.583 | BA14: =SUMIF(Rede!$D:$D,Geral!C14,Rede!$BA:$BA) -> 0 | BB14: =(AY14+AZ14+BA14)/AX14 -> 0.73533905 | BC14: =IFERROR(((AY14+AZ14+BA14)/AW14-1),0) -> -0.385371 | BD14: =AX14-AY14-BA14-AZ14 -> 146.06651 | BE14: =SUMIF(Rede!D:D,Geral!C14,Rede!$BE:$BE) -> 281.667 | BF14: =SUMIF(Rede!D:D,Geral!C14,Rede!$BF:$BF) -> 183.667 | BG14: =SUMIF(Rede!D:D,Geral!C14,Rede!$BG:$BG) -> 5 | BH14: =SUMIF(Rede!D:D,Geral!C14,Rede!$BH:$BH) -> 0 | BI14: =SUMIF(Rede!$D:$D,Geral!C14,Rede!$BI:$BI) -> 202.666 | BJ14: =SUMIF(Rede!$D:$D,Geral!C14,Rede!$BJ:$BJ) -> 37.334 | BK14: =SUMIF(Rede!$D:$D,Geral!C14,Rede!$BK:$BK) -> 0 | BL14: =SUMIF(Rede!$D:$D,Geral!C14,Rede!$BL:$BL) -> 0 | BM14: =SUMIF(Rede!$D:$D,Geral!C14,Rede!$BM:$BM) -> 175.958 | BN14: =SUMIF(Rede!$D:$D,Geral!C14,Rede!$BN:$BN) -> 178.25 | BO14: =SUMIF(Rede!$D:$D,Geral!C14,Rede!$BO:$BO) -> 1.583 | BP14: =SUMIF(Rede!$D:$D,Geral!C14,Rede!$BP:$BP) -> 0 | BR14: =SUMIF(Rede!$D:$D,Geral!C14,Rede!$BR:$BR) -> 181.833 | BS14: =SUMIF(Rede!$D:$D,Geral!C14,Rede!$BS:$BS) -> 588 | BT14: =SUMIF(Rede!$D:$D,Geral!C14,Rede!$BT:$BT) -> 202.083 | BU14: =SUMIF(Rede!$D:$D,Geral!C14,Rede!$BU:$BU) -> 0 | BV14: =SUMIF(Rede!$D:$D,Geral!C14,Rede!$BV:$BV) -> 4.75 | BW14: =(BT14+BU14+BV14)/BS14 -> 0.3517568 | BX14: =IFERROR(((BT14+BU14+BV14)/BR14-1),0) -> 0.13748879 | BY14: =BS14-BT14-BU14-BV14 -> 381.167 | BZ14: =SUMIF(Rede!$D:$D,Geral!C14,Rede!$BZ:$BZ) -> 50.791 | CA14: =SUMIF(Rede!$D:$D,Geral!C14,Rede!$CA:$CA) -> 102.458 | CB14: =SUMIF(Rede!$D:$D,Geral!C14,Rede!$CB:$CB) -> 0 | CC14: =SUMIF(Rede!$D:$D,Geral!C14,Rede!$CC:$CC) -> 0 | CD14: =SUMIF(Rede!$D:$D,Geral!C14,Rede!$CD:$CD) -> 73.334 | CE14: =SUMIF(Rede!$D:$D,Geral!C14,Rede!$CE:$CE) -> 50.167 | CF14: =SUMIF(Rede!$D:$D,Geral!C14,Rede!$CF:$CF) -> 0 | CG14: =SUMIF(Rede!$D:$D,Geral!C14,Rede!$CG:$CG) -> 0 | CH14: =SUMIF(Rede!$D:$D,Geral!C14,Rede!$CH:$CH) -> 57.708 | CI14: =SUMIF(Rede!$D:$D,Geral!C14,Rede!$CI:$CI) -> 49.458 | CJ14: =SUMIF(Rede!$D:$D,Geral!C14,Rede!$CJ:$CJ) -> 4.75 | CK14: =SUMIF(Rede!$D:$D,Geral!C14,Rede!$CK:$CK) -> 0 | CM14: =G14+AB14+AW14+BR14 -> 2213.187 | CN14: =H14+AC14+AX14+BS14 -> 2411.3008 | CO14: =I14+AD14+AY14+BT14 -> 2077.022 | CP14: =J14+AE14+AZ14+BU14 -> 10.083 | CQ14: =K14+AF14+BA14+BV14 -> 4.75 | CR14: =(CO14+CP14+CQ14)/CN14 -> 0.86752138 | CS14: =IFERROR(((CO14+CP14+CQ14)/CM14-1),0) -> -0.054822299 | CT14: =CN14-CO14-CQ14-CP14 -> 319.4458
B15: FLP-SUL MC/KA D | C15: 4054 | D15: MC-ARA D | E15: RAFAEL IZIDIO DE FARIAS | F15: =COUNTIF(Rede!$D:$D,Geral!$C15) -> 2 | G15: =SUMIF(Rede!$D:$D,Geral!C15,Rede!$G:$G) -> 1251.125 | H15: =SUMIF(Rede!$D:$D,Geral!C15,Rede!$H:$H) -> 745.25 | I15: =SUMIF(Rede!$D:$D,Geral!C15,Rede!$I:$I) -> 789.375 | J15: =SUMIF(Rede!$D:$D,Geral!$C15,Rede!$J:$J) -> 1 | K15: =SUMIF(Rede!$D:$D,Geral!C15,Rede!$K:$K) -> 0 | L15: =IFERROR((I15+K15+J15)/H15,0) -> 1.0605502 | M15: =IFERROR(((I15+K15+J15)/G15-1),0) -> -0.36826856 | N15: =H15-I15-J15-K15 -> -45.125 | O15: =SUMIF(Rede!$D:$D,Geral!$C15,Rede!$O:$O) -> 141.958 | P15: =SUMIF(Rede!$D:$D,Geral!$C15,Rede!$P:$P) -> 133.5 | Q15: =SUMIF(Rede!$D:$D,Geral!$C15,Rede!$Q:$Q) -> 1 | R15: =SUMIF(Rede!$D:$D,Geral!$C15,Rede!$R:$R) -> 0 | S15: =SUMIF(Rede!$D:$D,Geral!$C15,Rede!$S:$S) -> 514.625 | T15: =SUMIF(Rede!$D:$D,Geral!$C15,Rede!$T:$T) -> 201.5 | U15: =SUMIF(Rede!$D:$D,Geral!$C15,Rede!$U:$U) -> 0 | V15: =SUMIF(Rede!$D:$D,Geral!$C15,Rede!$V:$V) -> 0 | W15: =SUMIF(Rede!$D:$D,Geral!$C15,Rede!$W:$W) -> 594.542 | X15: =SUMIF(Rede!$D:$D,Geral!$C15,Rede!$X:$X) -> 454.375 | Y15: =SUMIF(Rede!$D:$D,Geral!$C15,Rede!$Y:$Y) -> 0 | Z15: =SUMIF(Rede!$D:$D,Geral!$C15,Rede!$Z:$Z) -> 0 | AB15: =SUMIF(Rede!D:D,Geral!C15,Rede!$AB:$AB) -> 307.527 | AC15: =SUMIF(Rede!D:D,Geral!C15,Rede!$AC:$AC) -> 638.78438 | AD15: =SUMIF(Rede!D:D,Geral!C15,Rede!$AD:$AD) -> 783.333 | AE15: =SUMIF(Rede!$D:$D,Geral!$C15,Rede!$AE:$AE) -> 27.5 | AF15: =SUMIF(Rede!D:D,Geral!C15,Rede!$AF:$AF) -> 0 | AG15: =(AD15+AF15+AE15)/AC15 -> 1.2693375 | AH15: =IFERROR(((AD15+AF15+AE15)/AB15-1),0) -> 1.6366238 | AI15: =AC15-AD15-AF15-AE15 -> -172.04862 | AJ15: =SUMIF(Rede!$D:$D,Geral!$C15,Rede!$AJ:$AJ) -> 40.333 | AK15: =SUMIF(Rede!$D:$D,Geral!$C15,Rede!$AK:$AK) -> 118.583 | AL15: =SUMIF(Rede!$D:$D,Geral!$C15,Rede!$AL:$AL) -> 0 | AM15: =SUMIF(Rede!$D:$D,Geral!$C15,Rede!$AM:$AM) -> 0 | AN15: =SUMIF(Rede!$D:$D,Geral!$C15,Rede!$AN:$AN) -> 137.083 | AO15: =SUMIF(Rede!$D:$D,Geral!$C15,Rede!$AO:$AO) -> 121.75 | AP15: =SUMIF(Rede!$D:$D,Geral!$C15,Rede!$AP:$AP) -> 3.25 | AQ15: =SUMIF(Rede!$D:$D,Geral!$C15,Rede!$AQ:$AQ) -> 0 | AR15: =SUMIF(Rede!$D:$D,Geral!$C15,Rede!$AR:$AR) -> 130.111 | AS15: =SUMIF(Rede!$D:$D,Geral!$C15,Rede!$AS:$AS) -> 543 | AT15: =SUMIF(Rede!$D:$D,Geral!$C15,Rede!$AT:$AT) -> 24.25 | AU15: =SUMIF(Rede!$D:$D,Geral!$C15,Rede!$AU:$AU) -> 0 | AW15: =SUMIF(Rede!$D:$D,Geral!C15,Rede!$AW:$AW) -> 490.146 | AX15: =SUMIF(Rede!$D:$D,Geral!C15,Rede!$AX:$AX) -> 600.79287 | AY15: =SUMIF(Rede!$D:$D,Geral!C15,Rede!$AY:$AY) -> 982.5 | AZ15: =SUMIF(Rede!$D:$D,Geral!C15,Rede!$AZ:$AZ) -> 57.125 | BA15: =SUMIF(Rede!$D:$D,Geral!C15,Rede!$BA:$BA) -> 0 | BB15: =(AY15+AZ15+BA15)/AX15 -> 1.7304217 | BC15: =IFERROR(((AY15+AZ15+BA15)/AW15-1),0) -> 1.1210517 | BD15: =AX15-AY15-BA15-AZ15 -> -438.83213 | BE15: =SUMIF(Rede!D:D,Geral!C15,Rede!$BE:$BE) -> 199.425 | BF15: =SUMIF(Rede!D:D,Geral!C15,Rede!$BF:$BF) -> 162.5 | BG15: =SUMIF(Rede!D:D,Geral!C15,Rede!$BG:$BG) -> 0 | BH15: =SUMIF(Rede!D:D,Geral!C15,Rede!$BH:$BH) -> 0 | BI15: =SUMIF(Rede!$D:$D,Geral!C15,Rede!$BI:$BI) -> 68.275 | BJ15: =SUMIF(Rede!$D:$D,Geral!C15,Rede!$BJ:$BJ) -> 106 | BK15: =SUMIF(Rede!$D:$D,Geral!C15,Rede!$BK:$BK) -> 0 | BL15: =SUMIF(Rede!$D:$D,Geral!C15,Rede!$BL:$BL) -> 0 | BM15: =SUMIF(Rede!$D:$D,Geral!C15,Rede!$BM:$BM) -> 222.446 | BN15: =SUMIF(Rede!$D:$D,Geral!C15,Rede!$BN:$BN) -> 714 | BO15: =SUMIF(Rede!$D:$D,Geral!C15,Rede!$BO:$BO) -> 57.125 | BP15: =SUMIF(Rede!$D:$D,Geral!C15,Rede!$BP:$BP) -> 0 | BR15: =SUMIF(Rede!$D:$D,Geral!C15,Rede!$BR:$BR) -> 406.833 | BS15: =SUMIF(Rede!$D:$D,Geral!C15,Rede!$BS:$BS) -> 642 | BT15: =SUMIF(Rede!$D:$D,Geral!C15,Rede!$BT:$BT) -> 562 | BU15: =SUMIF(Rede!$D:$D,Geral!C15,Rede!$BU:$BU) -> 0 | BV15: =SUMIF(Rede!$D:$D,Geral!C15,Rede!$BV:$BV) -> 0 | BW15: =(BT15+BU15+BV15)/BS15 -> 0.87538941 | BX15: =IFERROR(((BT15+BU15+BV15)/BR15-1),0) -> 0.3814022 | BY15: =BS15-BT15-BU15-BV15 -> 80 | BZ15: =SUMIF(Rede!$D:$D,Geral!C15,Rede!$BZ:$BZ) -> 77.333 | CA15: =SUMIF(Rede!$D:$D,Geral!C15,Rede!$CA:$CA) -> 38.458 | CB15: =SUMIF(Rede!$D:$D,Geral!C15,Rede!$CB:$CB) -> 0 | CC15: =SUMIF(Rede!$D:$D,Geral!C15,Rede!$CC:$CC) -> 0 | CD15: =SUMIF(Rede!$D:$D,Geral!C15,Rede!$CD:$CD) -> 124 | CE15: =SUMIF(Rede!$D:$D,Geral!C15,Rede!$CE:$CE) -> 205 | CF15: =SUMIF(Rede!$D:$D,Geral!C15,Rede!$CF:$CF) -> 0 | CG15: =SUMIF(Rede!$D:$D,Geral!C15,Rede!$CG:$CG) -> 0 | CH15: =SUMIF(Rede!$D:$D,Geral!C15,Rede!$CH:$CH) -> 205.5 | CI15: =SUMIF(Rede!$D:$D,Geral!C15,Rede!$CI:$CI) -> 318.542 | CJ15: =SUMIF(Rede!$D:$D,Geral!C15,Rede!$CJ:$CJ) -> 0 | CK15: =SUMIF(Rede!$D:$D,Geral!C15,Rede!$CK:$CK) -> 0 | CM15: =G15+AB15+AW15+BR15 -> 2455.631 | CN15: =H15+AC15+AX15+BS15 -> 2626.8273 | CO15: =I15+AD15+AY15+BT15 -> 3117.208 | CP15: =J15+AE15+AZ15+BU15 -> 85.625 | CQ15: =K15+AF15+BA15+BV15 -> 0 | CR15: =(CO15+CP15+CQ15)/CN15 -> 1.2192781 | CS15: =IFERROR(((CO15+CP15+CQ15)/CM15-1),0) -> 0.30428106 | CT15: =CN15-CO15-CQ15-CP15 -> -576.00574
B16: NORTE MC/KA D | C16: 179 | D16: KA-BRQ | E16: PEDRO PAULO ECCEL | F16: =COUNTIF(Rede!$D:$D,Geral!$C16) -> 1 | G16: =SUMIF(Rede!$D:$D,Geral!C16,Rede!$G:$G) -> 1707.958 | H16: =SUMIF(Rede!$D:$D,Geral!C16,Rede!$H:$H) -> 2181.26 | I16: =SUMIF(Rede!$D:$D,Geral!C16,Rede!$I:$I) -> 1828 | J16: =SUMIF(Rede!$D:$D,Geral!$C16,Rede!$J:$J) -> 15 | K16: =SUMIF(Rede!$D:$D,Geral!C16,Rede!$K:$K) -> 0 | L16: =IFERROR((I16+K16+J16)/H16,0) -> 0.84492449 | M16: =IFERROR(((I16+K16+J16)/G16-1),0) -> 0.079066347 | N16: =H16-I16-J16-K16 -> 338.26 | O16: =SUMIF(Rede!$D:$D,Geral!$C16,Rede!$O:$O) -> 504 | P16: =SUMIF(Rede!$D:$D,Geral!$C16,Rede!$P:$P) -> 109 | Q16: =SUMIF(Rede!$D:$D,Geral!$C16,Rede!$Q:$Q) -> 0 | R16: =SUMIF(Rede!$D:$D,Geral!$C16,Rede!$R:$R) -> 0 | S16: =SUMIF(Rede!$D:$D,Geral!$C16,Rede!$S:$S) -> 204.958 | T16: =SUMIF(Rede!$D:$D,Geral!$C16,Rede!$T:$T) -> 1458 | U16: =SUMIF(Rede!$D:$D,Geral!$C16,Rede!$U:$U) -> 15 | V16: =SUMIF(Rede!$D:$D,Geral!$C16,Rede!$V:$V) -> 0 | W16: =SUMIF(Rede!$D:$D,Geral!$C16,Rede!$W:$W) -> 999 | X16: =SUMIF(Rede!$D:$D,Geral!$C16,Rede!$X:$X) -> 261 | Y16: =SUMIF(Rede!$D:$D,Geral!$C16,Rede!$Y:$Y) -> 0 | Z16: =SUMIF(Rede!$D:$D,Geral!$C16,Rede!$Z:$Z) -> 0 | AB16: =SUMIF(Rede!D:D,Geral!C16,Rede!$AB:$AB) -> 2156 | AC16: =SUMIF(Rede!D:D,Geral!C16,Rede!$AC:$AC) -> 1869.6433 | AD16: =SUMIF(Rede!D:D,Geral!C16,Rede!$AD:$AD) -> 1741.75 | AE16: =SUMIF(Rede!$D:$D,Geral!$C16,Rede!$AE:$AE) -> 3 | AF16: =SUMIF(Rede!D:D,Geral!C16,Rede!$AF:$AF) -> 0 | AG16: =(AD16+AF16+AE16)/AC16 -> 0.9331994 | AH16: =IFERROR(((AD16+AF16+AE16)/AB16-1),0) -> -0.19074675 | AI16: =AC16-AD16-AF16-AE16 -> 124.8933 | AJ16: =SUMIF(Rede!$D:$D,Geral!$C16,Rede!$AJ:$AJ) -> 624 | AK16: =SUMIF(Rede!$D:$D,Geral!$C16,Rede!$AK:$AK) -> 548.75 | AL16: =SUMIF(Rede!$D:$D,Geral!$C16,Rede!$AL:$AL) -> 0 | AM16: =SUMIF(Rede!$D:$D,Geral!$C16,Rede!$AM:$AM) -> 0 | AN16: =SUMIF(Rede!$D:$D,Geral!$C16,Rede!$AN:$AN) -> 945 | AO16: =SUMIF(Rede!$D:$D,Geral!$C16,Rede!$AO:$AO) -> 578 | AP16: =SUMIF(Rede!$D:$D,Geral!$C16,Rede!$AP:$AP) -> 3 | AQ16: =SUMIF(Rede!$D:$D,Geral!$C16,Rede!$AQ:$AQ) -> 0 | AR16: =SUMIF(Rede!$D:$D,Geral!$C16,Rede!$AR:$AR) -> 587 | AS16: =SUMIF(Rede!$D:$D,Geral!$C16,Rede!$AS:$AS) -> 615 | AT16: =SUMIF(Rede!$D:$D,Geral!$C16,Rede!$AT:$AT) -> 0 | AU16: =SUMIF(Rede!$D:$D,Geral!$C16,Rede!$AU:$AU) -> 0 | AW16: =SUMIF(Rede!$D:$D,Geral!C16,Rede!$AW:$AW) -> 2145.417 | AX16: =SUMIF(Rede!$D:$D,Geral!C16,Rede!$AX:$AX) -> 1758.4468 | AY16: =SUMIF(Rede!$D:$D,Geral!C16,Rede!$AY:$AY) -> 1714.875 | AZ16: =SUMIF(Rede!$D:$D,Geral!C16,Rede!$AZ:$AZ) -> 25 | BA16: =SUMIF(Rede!$D:$D,Geral!C16,Rede!$BA:$BA) -> 0 | BB16: =(AY16+AZ16+BA16)/AX16 -> 0.98943851 | BC16: =IFERROR(((AY16+AZ16+BA16)/AW16-1),0) -> -0.18902712 | BD16: =AX16-AY16-BA16-AZ16 -> 18.571814 | BE16: =SUMIF(Rede!D:D,Geral!C16,Rede!$BE:$BE) -> 517 | BF16: =SUMIF(Rede!D:D,Geral!C16,Rede!$BF:$BF) -> 235.917 | BG16: =SUMIF(Rede!D:D,Geral!C16,Rede!$BG:$BG) -> 0 | BH16: =SUMIF(Rede!D:D,Geral!C16,Rede!$BH:$BH) -> 0 | BI16: =SUMIF(Rede!$D:$D,Geral!C16,Rede!$BI:$BI) -> 408 | BJ16: =SUMIF(Rede!$D:$D,Geral!C16,Rede!$BJ:$BJ) -> 790.958 | BK16: =SUMIF(Rede!$D:$D,Geral!C16,Rede!$BK:$BK) -> 12 | BL16: =SUMIF(Rede!$D:$D,Geral!C16,Rede!$BL:$BL) -> 0 | BM16: =SUMIF(Rede!$D:$D,Geral!C16,Rede!$BM:$BM) -> 1220.417 | BN16: =SUMIF(Rede!$D:$D,Geral!C16,Rede!$BN:$BN) -> 688 | BO16: =SUMIF(Rede!$D:$D,Geral!C16,Rede!$BO:$BO) -> 13 | BP16: =SUMIF(Rede!$D:$D,Geral!C16,Rede!$BP:$BP) -> 0 | BR16: =SUMIF(Rede!$D:$D,Geral!C16,Rede!$BR:$BR) -> 1078.25 | BS16: =SUMIF(Rede!$D:$D,Geral!C16,Rede!$BS:$BS) -> 1872 | BT16: =SUMIF(Rede!$D:$D,Geral!C16,Rede!$BT:$BT) -> 1087 | BU16: =SUMIF(Rede!$D:$D,Geral!C16,Rede!$BU:$BU) -> 59 | BV16: =SUMIF(Rede!$D:$D,Geral!C16,Rede!$BV:$BV) -> 18 | BW16: =(BT16+BU16+BV16)/BS16 -> 0.62179487 | BX16: =IFERROR(((BT16+BU16+BV16)/BR16-1),0) -> 0.079527011 | BY16: =BS16-BT16-BU16-BV16 -> 708 | BZ16: =SUMIF(Rede!$D:$D,Geral!C16,Rede!$BZ:$BZ) -> 179.25 | CA16: =SUMIF(Rede!$D:$D,Geral!C16,Rede!$CA:$CA) -> 365 | CB16: =SUMIF(Rede!$D:$D,Geral!C16,Rede!$CB:$CB) -> 3 | CC16: =SUMIF(Rede!$D:$D,Geral!C16,Rede!$CC:$CC) -> 0 | CD16: =SUMIF(Rede!$D:$D,Geral!C16,Rede!$CD:$CD) -> 490 | CE16: =SUMIF(Rede!$D:$D,Geral!C16,Rede!$CE:$CE) -> 518 | CF16: =SUMIF(Rede!$D:$D,Geral!C16,Rede!$CF:$CF) -> 15 | CG16: =SUMIF(Rede!$D:$D,Geral!C16,Rede!$CG:$CG) -> 0 | CH16: =SUMIF(Rede!$D:$D,Geral!C16,Rede!$CH:$CH) -> 409 | CI16: =SUMIF(Rede!$D:$D,Geral!C16,Rede!$CI:$CI) -> 204 | CJ16: =SUMIF(Rede!$D:$D,Geral!C16,Rede!$CJ:$CJ) -> 0 | CK16: =SUMIF(Rede!$D:$D,Geral!C16,Rede!$CK:$CK) -> 59 | CM16: =G16+AB16+AW16+BR16 -> 7087.625 | CN16: =H16+AC16+AX16+BS16 -> 7681.3501 | CO16: =I16+AD16+AY16+BT16 -> 6371.625 | CP16: =J16+AE16+AZ16+BU16 -> 102 | CQ16: =K16+AF16+BA16+BV16 -> 18 | CR16: =(CO16+CP16+CQ16)/CN16 -> 0.8451151 | CS16: =IFERROR(((CO16+CP16+CQ16)/CM16-1),0) -> -0.084090228 | CT16: =CN16-CO16-CQ16-CP16 -> 1189.7251
B17: NORTE MC/KA D | C17: 359 | D17: MC-ITPE D | E17: MARCELO SCHEFFLER | F17: =COUNTIF(Rede!$D:$D,Geral!$C17) -> 3 | G17: =SUMIF(Rede!$D:$D,Geral!C17,Rede!$G:$G) -> 3532.387 | H17: =SUMIF(Rede!$D:$D,Geral!C17,Rede!$H:$H) -> 2496.36 | I17: =SUMIF(Rede!$D:$D,Geral!C17,Rede!$I:$I) -> 2599.292 | J17: =SUMIF(Rede!$D:$D,Geral!$C17,Rede!$J:$J) -> 21.25 | K17: =SUMIF(Rede!$D:$D,Geral!C17,Rede!$K:$K) -> 0 | L17: =IFERROR((I17+K17+J17)/H17,0) -> 1.0497452 | M17: =IFERROR(((I17+K17+J17)/G17-1),0) -> -0.25813848 | N17: =H17-I17-J17-K17 -> -124.182 | O17: =SUMIF(Rede!$D:$D,Geral!$C17,Rede!$O:$O) -> 167.241 | P17: =SUMIF(Rede!$D:$D,Geral!$C17,Rede!$P:$P) -> 96.042 | Q17: =SUMIF(Rede!$D:$D,Geral!$C17,Rede!$Q:$Q) -> 11.75 | R17: =SUMIF(Rede!$D:$D,Geral!$C17,Rede!$R:$R) -> 0 | S17: =SUMIF(Rede!$D:$D,Geral!$C17,Rede!$S:$S) -> 1846.146 | T17: =SUMIF(Rede!$D:$D,Geral!$C17,Rede!$T:$T) -> 906.5 | U17: =SUMIF(Rede!$D:$D,Geral!$C17,Rede!$U:$U) -> 5 | V17: =SUMIF(Rede!$D:$D,Geral!$C17,Rede!$V:$V) -> 0 | W17: =SUMIF(Rede!$D:$D,Geral!$C17,Rede!$W:$W) -> 1519 | X17: =SUMIF(Rede!$D:$D,Geral!$C17,Rede!$X:$X) -> 1596.75 | Y17: =SUMIF(Rede!$D:$D,Geral!$C17,Rede!$Y:$Y) -> 4.5 | Z17: =SUMIF(Rede!$D:$D,Geral!$C17,Rede!$Z:$Z) -> 0 | AB17: =SUMIF(Rede!D:D,Geral!C17,Rede!$AB:$AB) -> 1915.563 | AC17: =SUMIF(Rede!D:D,Geral!C17,Rede!$AC:$AC) -> 2139.7439 | AD17: =SUMIF(Rede!D:D,Geral!C17,Rede!$AD:$AD) -> 788.877 | AE17: =SUMIF(Rede!$D:$D,Geral!$C17,Rede!$AE:$AE) -> 27.333 | AF17: =SUMIF(Rede!D:D,Geral!C17,Rede!$AF:$AF) -> 0 | AG17: =(AD17+AF17+AE17)/AC17 -> 0.3814522 | AH17: =IFERROR(((AD17+AF17+AE17)/AB17-1),0) -> -0.57390595 | AI17: =AC17-AD17-AF17-AE17 -> 1323.5339 | AJ17: =SUMIF(Rede!$D:$D,Geral!$C17,Rede!$AJ:$AJ) -> 651.146 | AK17: =SUMIF(Rede!$D:$D,Geral!$C17,Rede!$AK:$AK) -> 131.167 | AL17: =SUMIF(Rede!$D:$D,Geral!$C17,Rede!$AL:$AL) -> 0 | AM17: =SUMIF(Rede!$D:$D,Geral!$C17,Rede!$AM:$AM) -> 0 | AN17: =SUMIF(Rede!$D:$D,Geral!$C17,Rede!$AN:$AN) -> 546.5 | AO17: =SUMIF(Rede!$D:$D,Geral!$C17,Rede!$AO:$AO) -> 273.876 | AP17: =SUMIF(Rede!$D:$D,Geral!$C17,Rede!$AP:$AP) -> 7.333 | AQ17: =SUMIF(Rede!$D:$D,Geral!$C17,Rede!$AQ:$AQ) -> 0 | AR17: =SUMIF(Rede!$D:$D,Geral!$C17,Rede!$AR:$AR) -> 717.917 | AS17: =SUMIF(Rede!$D:$D,Geral!$C17,Rede!$AS:$AS) -> 383.834 | AT17: =SUMIF(Rede!$D:$D,Geral!$C17,Rede!$AT:$AT) -> 20 | AU17: =SUMIF(Rede!$D:$D,Geral!$C17,Rede!$AU:$AU) -> 0 | AW17: =SUMIF(Rede!$D:$D,Geral!C17,Rede!$AW:$AW) -> 1699.604 | AX17: =SUMIF(Rede!$D:$D,Geral!C17,Rede!$AX:$AX) -> 2012.4832 | AY17: =SUMIF(Rede!$D:$D,Geral!C17,Rede!$AY:$AY) -> 1096.79 | AZ17: =SUMIF(Rede!$D:$D,Geral!C17,Rede!$AZ:$AZ) -> 81 | BA17: =SUMIF(Rede!$D:$D,Geral!C17,Rede!$BA:$BA) -> 0 | BB17: =(AY17+AZ17+BA17)/AX17 -> 0.58524215 | BC17: =IFERROR(((AY17+AZ17+BA17)/AW17-1),0) -> -0.30702093 | BD17: =AX17-AY17-BA17-AZ17 -> 834.69322 | BE17: =SUMIF(Rede!D:D,Geral!C17,Rede!$BE:$BE) -> 192.167 | BF17: =SUMIF(Rede!D:D,Geral!C17,Rede!$BF:$BF) -> 251.624 | BG17: =SUMIF(Rede!D:D,Geral!C17,Rede!$BG:$BG) -> 9 | BH17: =SUMIF(Rede!D:D,Geral!C17,Rede!$BH:$BH) -> 0 | BI17: =SUMIF(Rede!$D:$D,Geral!C17,Rede!$BI:$BI) -> 320.479 | BJ17: =SUMIF(Rede!$D:$D,Geral!C17,Rede!$BJ:$BJ) -> 192.958 | BK17: =SUMIF(Rede!$D:$D,Geral!C17,Rede!$BK:$BK) -> 25 | BL17: =SUMIF(Rede!$D:$D,Geral!C17,Rede!$BL:$BL) -> 0 | BM17: =SUMIF(Rede!$D:$D,Geral!C17,Rede!$BM:$BM) -> 1186.958 | BN17: =SUMIF(Rede!$D:$D,Geral!C17,Rede!$BN:$BN) -> 652.208 | BO17: =SUMIF(Rede!$D:$D,Geral!C17,Rede!$BO:$BO) -> 47 | BP17: =SUMIF(Rede!$D:$D,Geral!C17,Rede!$BP:$BP) -> 0 | BR17: =SUMIF(Rede!$D:$D,Geral!C17,Rede!$BR:$BR) -> 1171.812 | BS17: =SUMIF(Rede!$D:$D,Geral!C17,Rede!$BS:$BS) -> 2142 | BT17: =SUMIF(Rede!$D:$D,Geral!C17,Rede!$BT:$BT) -> 902.793 | BU17: =SUMIF(Rede!$D:$D,Geral!C17,Rede!$BU:$BU) -> 121 | BV17: =SUMIF(Rede!$D:$D,Geral!C17,Rede!$BV:$BV) -> 94.542 | BW17: =(BT17+BU17+BV17)/BS17 -> 0.52209851 | BX17: =IFERROR(((BT17+BU17+BV17)/BR17-1),0) -> -0.04563616 | BY17: =BS17-BT17-BU17-BV17 -> 1023.665 | BZ17: =SUMIF(Rede!$D:$D,Geral!C17,Rede!$BZ:$BZ) -> 332.062 | CA17: =SUMIF(Rede!$D:$D,Geral!C17,Rede!$CA:$CA) -> 284.937 | CB17: =SUMIF(Rede!$D:$D,Geral!C17,Rede!$CB:$CB) -> 30.292 | CC17: =SUMIF(Rede!$D:$D,Geral!C17,Rede!$CC:$CC) -> 0 | CD17: =SUMIF(Rede!$D:$D,Geral!C17,Rede!$CD:$CD) -> 121.75 | CE17: =SUMIF(Rede!$D:$D,Geral!C17,Rede!$CE:$CE) -> 223.751 | CF17: =SUMIF(Rede!$D:$D,Geral!C17,Rede!$CF:$CF) -> 8.417 | CG17: =SUMIF(Rede!$D:$D,Geral!C17,Rede!$CG:$CG) -> 0 | CH17: =SUMIF(Rede!$D:$D,Geral!C17,Rede!$CH:$CH) -> 718 | CI17: =SUMIF(Rede!$D:$D,Geral!C17,Rede!$CI:$CI) -> 394.105 | CJ17: =SUMIF(Rede!$D:$D,Geral!C17,Rede!$CJ:$CJ) -> 55.833 | CK17: =SUMIF(Rede!$D:$D,Geral!C17,Rede!$CK:$CK) -> 121 | CM17: =G17+AB17+AW17+BR17 -> 8319.366 | CN17: =H17+AC17+AX17+BS17 -> 8790.5871 | CO17: =I17+AD17+AY17+BT17 -> 5387.752 | CP17: =J17+AE17+AZ17+BU17 -> 250.583 | CQ17: =K17+AF17+BA17+BV17 -> 94.542 | CR17: =(CO17+CP17+CQ17)/CN17 -> 0.65216088 | CS17: =IFERROR(((CO17+CP17+CQ17)/CM17-1),0) -> -0.31089977 | CT17: =CN17-CO17-CQ17-CP17 -> 3057.7101
B18: NORTE MC/KA D | C18: 4066 | D18: MC-BNU D | E18: MURIEL DERCIO VOCKES | F18: =COUNTIF(Rede!$D:$D,Geral!$C18) -> 1 | G18: =SUMIF(Rede!$D:$D,Geral!C18,Rede!$G:$G) -> 651.25 | H18: =SUMIF(Rede!$D:$D,Geral!C18,Rede!$H:$H) -> 397.51 | I18: =SUMIF(Rede!$D:$D,Geral!C18,Rede!$I:$I) -> 396.458 | J18: =SUMIF(Rede!$D:$D,Geral!$C18,Rede!$J:$J) -> 12.75 | K18: =SUMIF(Rede!$D:$D,Geral!C18,Rede!$K:$K) -> 0 | L18: =IFERROR((I18+K18+J18)/H18,0) -> 1.0294282 | M18: =IFERROR(((I18+K18+J18)/G18-1),0) -> -0.37165758 | N18: =H18-I18-J18-K18 -> -11.698 | O18: =SUMIF(Rede!$D:$D,Geral!$C18,Rede!$O:$O) -> 75.833 | P18: =SUMIF(Rede!$D:$D,Geral!$C18,Rede!$P:$P) -> 145.375 | Q18: =SUMIF(Rede!$D:$D,Geral!$C18,Rede!$Q:$Q) -> 9.75 | R18: =SUMIF(Rede!$D:$D,Geral!$C18,Rede!$R:$R) -> 0 | S18: =SUMIF(Rede!$D:$D,Geral!$C18,Rede!$S:$S) -> 72.75 | T18: =SUMIF(Rede!$D:$D,Geral!$C18,Rede!$T:$T) -> 259.583 | U18: =SUMIF(Rede!$D:$D,Geral!$C18,Rede!$U:$U) -> 3 | V18: =SUMIF(Rede!$D:$D,Geral!$C18,Rede!$V:$V) -> 0 | W18: =SUMIF(Rede!$D:$D,Geral!$C18,Rede!$W:$W) -> 502.667 | X18: =SUMIF(Rede!$D:$D,Geral!$C18,Rede!$X:$X) -> -8.5 | Y18: =SUMIF(Rede!$D:$D,Geral!$C18,Rede!$Y:$Y) -> 0 | Z18: =SUMIF(Rede!$D:$D,Geral!$C18,Rede!$Z:$Z) -> 0 | AB18: =SUMIF(Rede!D:D,Geral!C18,Rede!$AB:$AB) -> 179 | AC18: =SUMIF(Rede!D:D,Geral!C18,Rede!$AC:$AC) -> 340.72555 | AD18: =SUMIF(Rede!D:D,Geral!C18,Rede!$AD:$AD) -> 113.916 | AE18: =SUMIF(Rede!$D:$D,Geral!$C18,Rede!$AE:$AE) -> 1.25 | AF18: =SUMIF(Rede!D:D,Geral!C18,Rede!$AF:$AF) -> 0 | AG18: =(AD18+AF18+AE18)/AC18 -> 0.33800224 | AH18: =IFERROR(((AD18+AF18+AE18)/AB18-1),0) -> -0.35661453 | AI18: =AC18-AD18-AF18-AE18 -> 225.55955 | AJ18: =SUMIF(Rede!$D:$D,Geral!$C18,Rede!$AJ:$AJ) -> 78.5 | AK18: =SUMIF(Rede!$D:$D,Geral!$C18,Rede!$AK:$AK) -> 25.083 | AL18: =SUMIF(Rede!$D:$D,Geral!$C18,Rede!$AL:$AL) -> 0 | AM18: =SUMIF(Rede!$D:$D,Geral!$C18,Rede!$AM:$AM) -> 0 | AN18: =SUMIF(Rede!$D:$D,Geral!$C18,Rede!$AN:$AN) -> 58.5 | AO18: =SUMIF(Rede!$D:$D,Geral!$C18,Rede!$AO:$AO) -> 65 | AP18: =SUMIF(Rede!$D:$D,Geral!$C18,Rede!$AP:$AP) -> 1.25 | AQ18: =SUMIF(Rede!$D:$D,Geral!$C18,Rede!$AQ:$AQ) -> 0 | AR18: =SUMIF(Rede!$D:$D,Geral!$C18,Rede!$AR:$AR) -> 42 | AS18: =SUMIF(Rede!$D:$D,Geral!$C18,Rede!$AS:$AS) -> 23.833 | AT18: =SUMIF(Rede!$D:$D,Geral!$C18,Rede!$AT:$AT) -> 0 | AU18: =SUMIF(Rede!$D:$D,Geral!$C18,Rede!$AU:$AU) -> 0 | AW18: =SUMIF(Rede!$D:$D,Geral!C18,Rede!$AW:$AW) -> 358.75 | AX18: =SUMIF(Rede!$D:$D,Geral!C18,Rede!$AX:$AX) -> 320.461 | AY18: =SUMIF(Rede!$D:$D,Geral!C18,Rede!$AY:$AY) -> 373.917 | AZ18: =SUMIF(Rede!$D:$D,Geral!C18,Rede!$AZ:$AZ) -> 28.25 | BA18: =SUMIF(Rede!$D:$D,Geral!C18,Rede!$BA:$BA) -> 0 | BB18: =(AY18+AZ18+BA18)/AX18 -> 1.2549639 | BC18: =IFERROR(((AY18+AZ18+BA18)/AW18-1),0) -> 0.121023 | BD18: =AX18-AY18-BA18-AZ18 -> -81.705999 | BE18: =SUMIF(Rede!D:D,Geral!C18,Rede!$BE:$BE) -> 38.5 | BF18: =SUMIF(Rede!D:D,Geral!C18,Rede!$BF:$BF) -> 65.167 | BG18: =SUMIF(Rede!D:D,Geral!C18,Rede!$BG:$BG) -> 1.75 | BH18: =SUMIF(Rede!D:D,Geral!C18,Rede!$BH:$BH) -> 0 | BI18: =SUMIF(Rede!$D:$D,Geral!C18,Rede!$BI:$BI) -> 152.25 | BJ18: =SUMIF(Rede!$D:$D,Geral!C18,Rede!$BJ:$BJ) -> 113.417 | BK18: =SUMIF(Rede!$D:$D,Geral!C18,Rede!$BK:$BK) -> 2.5 | BL18: =SUMIF(Rede!$D:$D,Geral!C18,Rede!$BL:$BL) -> 0 | BM18: =SUMIF(Rede!$D:$D,Geral!C18,Rede!$BM:$BM) -> 168 | BN18: =SUMIF(Rede!$D:$D,Geral!C18,Rede!$BN:$BN) -> 195.333 | BO18: =SUMIF(Rede!$D:$D,Geral!C18,Rede!$BO:$BO) -> 24 | BP18: =SUMIF(Rede!$D:$D,Geral!C18,Rede!$BP:$BP) -> 0 | BR18: =SUMIF(Rede!$D:$D,Geral!C18,Rede!$BR:$BR) -> 121.125 | BS18: =SUMIF(Rede!$D:$D,Geral!C18,Rede!$BS:$BS) -> 342 | BT18: =SUMIF(Rede!$D:$D,Geral!C18,Rede!$BT:$BT) -> 160.667 | BU18: =SUMIF(Rede!$D:$D,Geral!C18,Rede!$BU:$BU) -> 45 | BV18: =SUMIF(Rede!$D:$D,Geral!C18,Rede!$BV:$BV) -> 19.958 | BW18: =(BT18+BU18+BV18)/BS18 -> 0.65972222 | BX18: =IFERROR(((BT18+BU18+BV18)/BR18-1),0) -> 0.8627451 | BY18: =BS18-BT18-BU18-BV18 -> 116.375 | BZ18: =SUMIF(Rede!$D:$D,Geral!C18,Rede!$BZ:$BZ) -> 62.25 | CA18: =SUMIF(Rede!$D:$D,Geral!C18,Rede!$CA:$CA) -> 26.667 | CB18: =SUMIF(Rede!$D:$D,Geral!C18,Rede!$CB:$CB) -> 0.833 | CC18: =SUMIF(Rede!$D:$D,Geral!C18,Rede!$CC:$CC) -> 0 | CD18: =SUMIF(Rede!$D:$D,Geral!C18,Rede!$CD:$CD) -> 50.875 | CE18: =SUMIF(Rede!$D:$D,Geral!C18,Rede!$CE:$CE) -> 30.667 | CF18: =SUMIF(Rede!$D:$D,Geral!C18,Rede!$CF:$CF) -> 3.167 | CG18: =SUMIF(Rede!$D:$D,Geral!C18,Rede!$CG:$CG) -> 0 | CH18: =SUMIF(Rede!$D:$D,Geral!C18,Rede!$CH:$CH) -> 8 | CI18: =SUMIF(Rede!$D:$D,Geral!C18,Rede!$CI:$CI) -> 103.333 | CJ18: =SUMIF(Rede!$D:$D,Geral!C18,Rede!$CJ:$CJ) -> 15.958 | CK18: =SUMIF(Rede!$D:$D,Geral!C18,Rede!$CK:$CK) -> 45 | CM18: =G18+AB18+AW18+BR18 -> 1310.125 | CN18: =H18+AC18+AX18+BS18 -> 1400.6966 | CO18: =I18+AD18+AY18+BT18 -> 1044.958 | CP18: =J18+AE18+AZ18+BU18 -> 87.25 | CQ18: =K18+AF18+BA18+BV18 -> 19.958 | CR18: =(CO18+CP18+CQ18)/CN18 -> 0.82256646 | CS18: =IFERROR(((CO18+CP18+CQ18)/CM18-1),0) -> -0.12056788 | CT18: =CN18-CO18-CQ18-CP18 -> 248.53055
B19: NORTE MC/KA D | C19: 3655 | D19: KA-BNU | E19: NATHAN FREITAS FUZINATO | F19: =COUNTIF(Rede!$D:$D,Geral!$C19) -> 1 | G19: =SUMIF(Rede!$D:$D,Geral!C19,Rede!$G:$G) -> 1092.75 | H19: =SUMIF(Rede!$D:$D,Geral!C19,Rede!$H:$H) -> 2551.88 | I19: =SUMIF(Rede!$D:$D,Geral!C19,Rede!$I:$I) -> 2591.659 | J19: =SUMIF(Rede!$D:$D,Geral!$C19,Rede!$J:$J) -> 0.417 | K19: =SUMIF(Rede!$D:$D,Geral!C19,Rede!$K:$K) -> 0 | L19: =IFERROR((I19+K19+J19)/H19,0) -> 1.0157515 | M19: =IFERROR(((I19+K19+J19)/G19-1),0) -> 1.3720668 | N19: =H19-I19-J19-K19 -> -40.196 | O19: =SUMIF(Rede!$D:$D,Geral!$C19,Rede!$O:$O) -> 436.75 | P19: =SUMIF(Rede!$D:$D,Geral!$C19,Rede!$P:$P) -> 626 | Q19: =SUMIF(Rede!$D:$D,Geral!$C19,Rede!$Q:$Q) -> 0 | R19: =SUMIF(Rede!$D:$D,Geral!$C19,Rede!$R:$R) -> 0 | S19: =SUMIF(Rede!$D:$D,Geral!$C19,Rede!$S:$S) -> 239 | T19: =SUMIF(Rede!$D:$D,Geral!$C19,Rede!$T:$T) -> 172.667 | U19: =SUMIF(Rede!$D:$D,Geral!$C19,Rede!$U:$U) -> 0.417 | V19: =SUMIF(Rede!$D:$D,Geral!$C19,Rede!$V:$V) -> 0 | W19: =SUMIF(Rede!$D:$D,Geral!$C19,Rede!$W:$W) -> 417 | X19: =SUMIF(Rede!$D:$D,Geral!$C19,Rede!$X:$X) -> 1792.992 | Y19: =SUMIF(Rede!$D:$D,Geral!$C19,Rede!$Y:$Y) -> 0 | Z19: =SUMIF(Rede!$D:$D,Geral!$C19,Rede!$Z:$Z) -> 0 | AB19: =SUMIF(Rede!D:D,Geral!C19,Rede!$AB:$AB) -> 4926.167 | AC19: =SUMIF(Rede!D:D,Geral!C19,Rede!$AC:$AC) -> 2187.3287 | AD19: =SUMIF(Rede!D:D,Geral!C19,Rede!$AD:$AD) -> 2142.833 | AE19: =SUMIF(Rede!$D:$D,Geral!$C19,Rede!$AE:$AE) -> 11 | AF19: =SUMIF(Rede!D:D,Geral!C19,Rede!$AF:$AF) -> 0 | AG19: =(AD19+AF19+AE19)/AC19 -> 0.9846865 | AH19: =IFERROR(((AD19+AF19+AE19)/AB19-1),0) -> -0.5627771 | AI19: =AC19-AD19-AF19-AE19 -> 33.495656 | AJ19: =SUMIF(Rede!$D:$D,Geral!$C19,Rede!$AJ:$AJ) -> 2393.583 | AK19: =SUMIF(Rede!$D:$D,Geral!$C19,Rede!$AK:$AK) -> 1159.833 | AL19: =SUMIF(Rede!$D:$D,Geral!$C19,Rede!$AL:$AL) -> 0 | AM19: =SUMIF(Rede!$D:$D,Geral!$C19,Rede!$AM:$AM) -> 0 | AN19: =SUMIF(Rede!$D:$D,Geral!$C19,Rede!$AN:$AN) -> 1487.917 | AO19: =SUMIF(Rede!$D:$D,Geral!$C19,Rede!$AO:$AO) -> 319 | AP19: =SUMIF(Rede!$D:$D,Geral!$C19,Rede!$AP:$AP) -> 0 | AQ19: =SUMIF(Rede!$D:$D,Geral!$C19,Rede!$AQ:$AQ) -> 0 | AR19: =SUMIF(Rede!$D:$D,Geral!$C19,Rede!$AR:$AR) -> 1044.667 | AS19: =SUMIF(Rede!$D:$D,Geral!$C19,Rede!$AS:$AS) -> 664 | AT19: =SUMIF(Rede!$D:$D,Geral!$C19,Rede!$AT:$AT) -> 11 | AU19: =SUMIF(Rede!$D:$D,Geral!$C19,Rede!$AU:$AU) -> 0 | AW19: =SUMIF(Rede!$D:$D,Geral!C19,Rede!$AW:$AW) -> 1411.25 | AX19: =SUMIF(Rede!$D:$D,Geral!C19,Rede!$AX:$AX) -> 2057.2379 | AY19: =SUMIF(Rede!$D:$D,Geral!C19,Rede!$AY:$AY) -> 3123.992 | AZ19: =SUMIF(Rede!$D:$D,Geral!C19,Rede!$AZ:$AZ) -> 11 | BA19: =SUMIF(Rede!$D:$D,Geral!C19,Rede!$BA:$BA) -> 0 | BB19: =(AY19+AZ19+BA19)/AX19 -> 1.523884 | BC19: =IFERROR(((AY19+AZ19+BA19)/AW19-1),0) -> 1.2214292 | BD19: =AX19-AY19-BA19-AZ19 -> -1077.7541 | BE19: =SUMIF(Rede!D:D,Geral!C19,Rede!$BE:$BE) -> 339 | BF19: =SUMIF(Rede!D:D,Geral!C19,Rede!$BF:$BF) -> 873 | BG19: =SUMIF(Rede!D:D,Geral!C19,Rede!$BG:$BG) -> 11 | BH19: =SUMIF(Rede!D:D,Geral!C19,Rede!$BH:$BH) -> 0 | BI19: =SUMIF(Rede!$D:$D,Geral!C19,Rede!$BI:$BI) -> 873.667 | BJ19: =SUMIF(Rede!$D:$D,Geral!C19,Rede!$BJ:$BJ) -> 1116.992 | BK19: =SUMIF(Rede!$D:$D,Geral!C19,Rede!$BK:$BK) -> 0 | BL19: =SUMIF(Rede!$D:$D,Geral!C19,Rede!$BL:$BL) -> 0 | BM19: =SUMIF(Rede!$D:$D,Geral!C19,Rede!$BM:$BM) -> 198.583 | BN19: =SUMIF(Rede!$D:$D,Geral!C19,Rede!$BN:$BN) -> 1134 | BO19: =SUMIF(Rede!$D:$D,Geral!C19,Rede!$BO:$BO) -> 0 | BP19: =SUMIF(Rede!$D:$D,Geral!C19,Rede!$BP:$BP) -> 0 | BR19: =SUMIF(Rede!$D:$D,Geral!C19,Rede!$BR:$BR) -> 1217.242 | BS19: =SUMIF(Rede!$D:$D,Geral!C19,Rede!$BS:$BS) -> 2190 | BT19: =SUMIF(Rede!$D:$D,Geral!C19,Rede!$BT:$BT) -> 1228.5 | BU19: =SUMIF(Rede!$D:$D,Geral!C19,Rede!$BU:$BU) -> 0 | BV19: =SUMIF(Rede!$D:$D,Geral!C19,Rede!$BV:$BV) -> 0 | BW19: =(BT19+BU19+BV19)/BS19 -> 0.5609589 | BX19: =IFERROR(((BT19+BU19+BV19)/BR19-1),0) -> 0.0092487772 | BY19: =BS19-BT19-BU19-BV19 -> 961.5 | BZ19: =SUMIF(Rede!$D:$D,Geral!C19,Rede!$BZ:$BZ) -> 326.325 | CA19: =SUMIF(Rede!$D:$D,Geral!C19,Rede!$CA:$CA) -> 126 | CB19: =SUMIF(Rede!$D:$D,Geral!C19,Rede!$CB:$CB) -> 0 | CC19: =SUMIF(Rede!$D:$D,Geral!C19,Rede!$CC:$CC) -> 0 | CD19: =SUMIF(Rede!$D:$D,Geral!C19,Rede!$CD:$CD) -> 606 | CE19: =SUMIF(Rede!$D:$D,Geral!C19,Rede!$CE:$CE) -> 1106.5 | CF19: =SUMIF(Rede!$D:$D,Geral!C19,Rede!$CF:$CF) -> 0 | CG19: =SUMIF(Rede!$D:$D,Geral!C19,Rede!$CG:$CG) -> 0 | CH19: =SUMIF(Rede!$D:$D,Geral!C19,Rede!$CH:$CH) -> 284.917 | CI19: =SUMIF(Rede!$D:$D,Geral!C19,Rede!$CI:$CI) -> -4 | CJ19: =SUMIF(Rede!$D:$D,Geral!C19,Rede!$CJ:$CJ) -> 0 | CK19: =SUMIF(Rede!$D:$D,Geral!C19,Rede!$CK:$CK) -> 0 | CM19: =G19+AB19+AW19+BR19 -> 8647.409 | CN19: =H19+AC19+AX19+BS19 -> 8986.4466 | CO19: =I19+AD19+AY19+BT19 -> 9086.984 | CP19: =J19+AE19+AZ19+BU19 -> 22.417 | CQ19: =K19+AF19+BA19+BV19 -> 0 | CR19: =(CO19+CP19+CQ19)/CN19 -> 1.0136822 | CS19: =IFERROR(((CO19+CP19+CQ19)/CM19-1),0) -> 0.053425483 | CT19: =CN19-CO19-CQ19-CP19 -> -122.95441
B20: TT | F20: =SUM(F12:F19) -> 14 | G20: =SUBTOTAL(9,G12:G19) -> 14339.799 | H20: =SUBTOTAL(9,H12:H19) -> 12641.68 | I20: =SUBTOTAL(9,I12:I19) -> 15458.304 | J20: =SUBTOTAL(9,J12:J19) -> 125.5 | K20: =SUBTOTAL(9,K12:K19) -> 0 | L20: =IFERROR((I20+K20+J20)/H20,0) -> 1.232732 | M20: =IFERROR(((I20+K20+J20)/G20-1),0) -> 0.086751913 | N20: =H20-I20-J20-K20 -> -2942.124 | O20: =SUM(O12:O19) -> 1856.139 | P20: =SUM(P12:P19) -> 1941.979 | Q20: =SUM(Q12:Q19) -> 54 | R20: =SUM(R12:R19) -> 0 | S20: =SUM(S12:S19) -> 4894.183 | T20: =SUM(T12:T19) -> 5433.971 | U20: =SUM(U12:U19) -> 46 | V20: =SUM(V12:V19) -> 0 | ... Z20: =SUM(Z12:Z19) -> 0 | AB20: =SUBTOTAL(9,AB12:AB19) -> 14332.09 | AC20: =SUBTOTAL(9,AC12:AC19) -> 10835.718 | AD20: =SUBTOTAL(9,AD12:AD19) -> 9451.838 | AE20: =SUBTOTAL(9,AE12:AE19) -> 163.958 | AF20: =SUBTOTAL(9,AF12:AF19) -> 0 | AG20: =(AD20+AF20+AE20)/AC20 -> 0.88741657 | AH20: =IFERROR(((AD20+AF20+AE20)/AB20-1),0) -> -0.32907231 | AI20: =AC20-AD20-AF20-AE20 -> 1219.9223 | AJ20: =SUM(AJ12:AJ19) -> 6436.716 | AK20: =SUM(AK12:AK19) -> 2867.524 | AL20: =SUM(AL12:AL19) -> 45.125 | AM20: =SUM(AM12:AM19) -> 0 | AN20: =SUM(AN12:AN19) -> 3615.471 | AO20: =SUM(AO12:AO19) -> 2591.363 | AP20: =SUM(AP12:AP19) -> 32.833 | AQ20: =SUM(AQ12:AQ19) -> 0 | ... AU20: =SUM(AU12:AU19) -> 0 | AW20: =SUBTOTAL(9,AW12:AW19) -> 8494.029 | AX20: =SUBTOTAL(9,AX12:AX19) -> 10191.267 | AY20: =SUBTOTAL(9,AY12:AY19) -> 11094.633 | AZ20: =SUBTOTAL(9,AZ12:AZ19) -> 377.124 | BA20: =SUBTOTAL(9,BA12:BA19) -> 0 | BB20: =(AY20+AZ20+BA20)/AX20 -> 1.1256458 | BC20: =IFERROR(((AY20+AZ20+BA20)/AW20-1),0) -> 0.3505672 | BD20: =AX20-AY20-BA20-AZ20 -> -1280.4899 | BE20: =SUM(BE12:BE19) -> 2064.847 | BF20: =SUM(BF12:BF19) -> 2538.517 | BG20: =SUM(BG12:BG19) -> 60.583 | BH20: =SUM(BH12:BH19) -> 0 | BI20: =SUM(BI12:BI19) -> 2460.051 | BJ20: =SUM(BJ12:BJ19) -> 3092.492 | BK20: =SUM(BK12:BK19) -> 70.333 | BL20: =SUM(BL12:BL19) -> 0 | ... BP20: =SUM(BP12:BP19) -> 0 | BR20: =SUBTOTAL(9,BR12:BR19) -> 4968.702 | BS20: =SUBTOTAL(9,BS12:BS19) -> 10857 | BT20: =SUBTOTAL(9,BT12:BT19) -> 5715.708 | BU20: =SUBTOTAL(9,BU12:BU19) -> 225 | BV20: =SUBTOTAL(9,BV12:BV19) -> 199.833 | BW20: =(BT20+BU20+BV20)/BS20 -> 0.56558359 | BX20: =IFERROR(((BT20+BU20+BV20)/BR20-1),0) -> 0.23584409 | BY20: =BS20-BT20-BU20-BV20 -> 4716.459 | BZ20: =SUM(BZ12:BZ19) -> 1081.053 | CA20: =SUM(CA12:CA19) -> 1228.021 | CB20: =SUM(CB12:CB19) -> 58.875 | CC20: =SUM(CC12:CC19) -> 0 | CD20: =SUM(CD12:CD19) -> 2000.043 | CE20: =SUM(CE12:CE19) -> 2880.931 | CF20: =SUM(CF12:CF19) -> 47.667 | CG20: =SUM(CG12:CG19) -> 0 | ... CK20: =SUM(CK12:CK19) -> 225 | CM20: =SUBTOTAL(9,CM12:CM19) -> 42134.62 | CN20: =SUBTOTAL(9,CN12:CN19) -> 44525.665 | CO20: =SUBTOTAL(9,CO12:CO19) -> 41720.483 | CP20: =SUBTOTAL(9,CP12:CP19) -> 891.582 | CQ20: =SUBTOTAL(9,CQ12:CQ19) -> 199.833 | CR20: =(CO20+CP20+CQ20)/CN20 -> 0.96151057 | CS20: =IFERROR(((CO20+CP20+CQ20)/CM20-1),0) -> 0.016074145 | CT20: =CN20-CO20-CQ20-CP20 -> 1713.7674

Sheet Rede
