Workbook

Sheet Geral
E4: EQUIPE | F4: REDE | G4: Q1 - JULHO A SETEMBRO 2025 | L4: JULHO | Q4: AGOSTO | V4: SETEMBRO | AA4: Q2 - OUTUBRO A DEZEMBRO 2025 | AF4: OUTUBRO | AK4: NOVEMBRO | AP4: DEZEMBRO | AU4: Q3 - JANEIRO A MARÇO 2026 | AZ4: JANEIRO | BE4: FEVEREIRO | BJ4: MARÇO | BO4: Q4 - ABRIL A JUNHO 2026 | BT4: ABRIL | BY4: MAIO | CD4: JUNHO
G5: LOJAS | H5: AUDITADA | I5: % | J5: GAP | K5: MÉDIA | L5: LOJAS | M5: AUDITADA | N5: % | O5: GAP | P5: MÉDIA | Q5: LOJAS | R5: AUDITADA | S5: % | T5: GAP | U5: MÉDIA | V5: LOJAS | W5: AUDITADA | X5: % | Y5: GAP | Z5: MÉDIA | AA5: LOJAS | AB5: AUDITADA | AC5: % | AD5: GAP | AE5: MÉDIA | AF5: LOJAS | AG5: AUDITADA | AH5: % | AI5: GAP | AJ5: MÉDIA | AK5: LOJAS | AL5: AUDITADA | AM5: % | AN5: GAP | AO5: MÉDIA | AP5: LOJAS | AQ5: AUDITADA | AR5: % | AS5: GAP | AT5: MÉDIA | AU5: LOJAS | AV5: AUDITADA | AW5: % | AX5: GAP | AY5: MÉDIA | AZ5: LOJAS | BA5: AUDITADA | BB5: % | BC5: GAP | BD5: MÉDIA | BE5: LOJAS | BF5: AUDITADA | BG5: % | BH5: GAP | BI5: MÉDIA | BJ5: LOJAS | BK5: AUDITADA | BL5: % | BM5: GAP | BN5: MÉDIA | BO5: LOJAS | BP5: AUDITADA | BQ5: % | BR5: GAP | BS5: MÉDIA | BT5: LOJAS | BU5: AUDITADA | BV5: % | BW5: GAP | BX5: MÉDIA | BY5: LOJAS | BZ5: AUDITADA | CA5: % | CB5: GAP | CC5: MÉDIA | CD5: LOJAS | CE5: AUDITADA | CF5: % | CG5: GAP | CH5: MÉDIA
E6: FLP-SUL MC/KA D | F6: =SUMIF($B:$B,$E6,$F:$F) -> 8 | G6: =COUNTIF(Cliente!$B:$B,Geral!$E6) -> 33 | H6: =SUMIF($B:$B,$E6,H:H) -> 24 | I6: =IFERROR(H6/G6,0) -> 0.72727273 | J6: =H6-G6 -> -9 | K6: =IFERROR(AVERAGEIFS(Cliente!$L:$L,Cliente!$B:$B,Geral!$E6,Cliente!$L:$L,">0"),0) -> 58.243131 | L6: =COUNTIF(Cliente!$B:$B,Geral!$E6) -> 33 | M6: =SUMIF($B:$B,$E6,M:M) -> 29 | N6: =IFERROR(M6/L6,0) -> 0.87878788 | O6: =M6-L6 -> -4 | P6: =IFERROR(AVERAGEIFS(Cliente!$S:$S,Cliente!$B:$B,Geral!$E6,Cliente!$S:$S,">0"),0) -> 55.799828 | Q6: =COUNTIF(Cliente!$B:$B,Geral!$E6) -> 33 | R6: =SUMIF($B:$B,$E6,R:R) -> 31 | S6: =IFERROR(R6/Q6,0) -> 0.93939394 | T6: =R6-Q6 -> -2 | U6: =IFERROR(AVERAGEIFS(Cliente!$Y:$Y,Cliente!$B:$B,Geral!$E6,Cliente!$Y:$Y,">0"),0) -> 62.550968 | V6: =COUNTIF(Cliente!$B:$B,Geral!$E6) -> 33 | W6: =SUMIF($B:$B,$E6,W:W) -> 30 | X6: =IFERROR(W6/V6,0) -> 0.90909091 | Y6: =W6-V6 -> -3 | Z6: =IFERROR(AVERAGEIFS(Cliente!$AE:$AE,Cliente!$B:$B,Geral!$E6,Cliente!$AE:$AE,">0"),0) -> 73.6265 | AA6: =COUNTIF(Cliente!$B:$B,Geral!$E6) -> 33 | AB6: =SUMIF($B:$B,$E6,AB:AB) -> 15 | AC6: =IFERROR(AB6/AA6,0) -> 0.45454545 | AD6: =AB6-AA6 -> -18 | AE6: =IFERROR(AVERAGEIFS(Cliente!$AG:$AG,Cliente!$B:$B,Geral!$E6,Cliente!$AG:$AG,">0"),0) -> 48.03125 | AF6: =COUNTIF(Cliente!$B:$B,Geral!$E6) -> 33 | AG6: =SUMIF($B:$B,$E6,AG:AG) -> 26 | AH6: =AG6/AF6 -> 0.78787879 | AI6: =AG6-AF6 -> -7 | AJ6: =IFERROR(AVERAGEIFS(Cliente!$AN:$AN,Cliente!$B:$B,Geral!$E6,Cliente!$AN:$AN,">0"),0) -> 62.235192 | AK6: =COUNTIF(Cliente!$B:$B,Geral!$E6) -> 33 | AL6: =SUMIF($B:$B,$E6,AL:AL) -> 21 | AM6: =AL6/AK6 -> 0.63636364 | AN6: =AL6-AK6 -> -12 | AO6: =IFERROR(AVERAGEIFS(Cliente!$AU:$AU,Cliente!$B:$B,Geral!$E6,Cliente!$AU:$AU,">0"),0) -> 63.68381 | AP6: =COUNTIF(Cliente!$B:$B,Geral!$E6) -> 33 | AQ6: =SUMIF($B:$B,$E6,AQ:AQ) -> 25 | AR6: =AQ6/AP6 -> 0.75757576 | AS6: =AQ6-AP6 -> -8 | AT6: =IFERROR(AVERAGEIFS(Cliente!$BB:$BB,Cliente!$B:$B,Geral!$E6,Cliente!$BB:$BB,">0"),0) -> 66.221 | AU6: =COUNTIF(Cliente!$B:$B,Geral!$E6) -> 33 | AV6: =SUMIF($B:$B,$E6,AV:AV) -> 22 | AW6: =IFERROR(AV6/AU6,0) -> 0.66666667 | AX6: =AV6-AU6 -> -11 | AY6: =AVERAGE(BD6,BI6,BN6) -> 80.644477 | AZ6: =COUNTIF(Cliente!$B:$B,Geral!$E6) -> 33 | BA6: =SUMIF($B:$B,$E6,BA:BA) -> 29 | BB6: =BA6/AZ6 -> 0.87878788 | BC6: =BA6-AZ6 -> -4 | BD6: =IFERROR(AVERAGEIFS(Cliente!$BL:$BL,Cliente!$B:$B,Geral!$E6,Cliente!$BL:$BL,">0"),0) -> 72.16431 | BE6: =COUNTIF(Cliente!$B:$B,Geral!$E6) -> 33 | BF6: =SUMIF($B:$B,$E6,BF:BF) -> 28 | BG6: =BF6/BE6 -> 0.84848485 | BH6: =BF6-BE6 -> -5 | BI6: =IFERROR(AVERAGEIFS(Cliente!$BS:$BS,Cliente!$B:$B,Geral!$E6,Cliente!$BS:$BS,">0"),0) -> 85.796429 | BJ6: =COUNTIF(Cliente!$B:$B,Geral!$E6) -> 33 | BK6: =SUMIF($B:$B,$E6,BK:BK) -> 26 | BL6: =BK6/BJ6 -> 0.78787879 | BM6: =BK6-BJ6 -> -7 | BN6: =IFERROR(AVERAGEIFS(Cliente!$BZ:$BZ,Cliente!$B:$B,Geral!$E6,Cliente!$BZ:$BZ,">0"),0) -> 83.972692 | BO6: =COUNTIF(Cliente!$B:$B,Geral!$E6) -> 33 | BP6: =SUMIF($B:$B,$E6,BP:BP) -> 19 | BQ6: =IFERROR(BP6/BO6,0) -> 0.57575758 | BR6: =BP6-BO6 -> -14 | BS6: =IFERROR(AVERAGEIFS(Cliente!$CB:$CB,Cliente!$B:$B,Geral!$E6,Cliente!$CB:$CB,">0"),0) -> 79.3875 | BT6: =COUNTIF(Cliente!$B:$B,Geral!$E6) -> 33 | BU6: =SUMIF($B:$B,$E6,BU:BU) -> 25 | BV6: =BU6/BT6 -> 0.75757576 | BW6: =BU6-BT6 -> -8 | BX6: =IFERROR(AVERAGEIFS(Cliente!$CL:$CL,Cliente!$B:$B,Geral!$E6,Cliente!$CL:$CL,">0"),0) -> 86.998 | BY6: =COUNTIF(Cliente!$B:$B,Geral!$E6) -> 33 | BZ6: =SUMIF($B:$B,$E6,BZ:BZ) -> 25 | CA6: =BZ6/BY6 -> 0.75757576 | CB6: =BZ6-BY6 -> -8 | CC6: =IFERROR(AVERAGEIFS(Cliente!$CU:$CU,Cliente!$B:$B,Geral!$E6,Cliente!$CU:$CU,">0"),0) -> 90.864 | CD6: =COUNTIF(Cliente!$B:$B,Geral!$E6) -> 33 | CE6: =SUMIF($B:$B,$E6,CE:CE) -> 20 | CF6: =CE6/CD6 -> 0.60606061 | CG6: =CE6-CD6 -> -13 | CH6: =IFERROR(AVERAGEIFS(Cliente!$DD:$DD,Cliente!$B:$B,Geral!$E6,Cliente!$DD:$DD,">0"),0) -> 87.28375
E7: NORTE MC/KA D | F7: =SUMIF($B:$B,$E7,$F:$F) -> 6 | G7: =COUNTIF(Cliente!$B:$B,Geral!$E7) -> 38 | H7: =SUMIF($B:$B,$E7,H:H) -> 34 | I7: =IFERROR(H7/G7,0) -> 0.89473684 | J7: =H7-G7 -> -4 | K7: =IFERROR(AVERAGEIFS(Cliente!$L:$L,Cliente!$B:$B,Geral!$E7,Cliente!$L:$L,">0"),0) -> 68.65261 | L7: =COUNTIF(Cliente!$B:$B,Geral!$E7) -> 38 | M7: =SUMIF($B:$B,$E7,M:M) -> 38 | N7: =IFERROR(M7/L7,0) -> 1 | O7: =M7-L7 -> 0 | P7: =IFERROR(AVERAGEIFS(Cliente!$S:$S,Cliente!$B:$B,Geral!$E7,Cliente!$S:$S,">0"),0) -> 66.205461 | Q7: =COUNTIF(Cliente!$B:$B,Geral!$E7) -> 38 | R7: =SUMIF($B:$B,$E7,R:R) -> 34 | S7: =IFERROR(R7/Q7,0) -> 0.89473684 | T7: =R7-Q7 -> -4 | U7: =IFERROR(AVERAGEIFS(Cliente!$Y:$Y,Cliente!$B:$B,Geral!$E7,Cliente!$Y:$Y,">0"),0) -> 69.305588 | V7: =COUNTIF(Cliente!$B:$B,Geral!$E7) -> 38 | W7: =SUMIF($B:$B,$E7,W:W) -> 38 | X7: =IFERROR(W7/V7,0) -> 1 | Y7: =W7-V7 -> 0 | Z7: =IFERROR(AVERAGEIFS(Cliente!$AE:$AE,Cliente!$B:$B,Geral!$E7,Cliente!$AE:$AE,">0"),0) -> 77.742105 | AA7: =COUNTIF(Cliente!$B:$B,Geral!$E7) -> 38 | AB7: =SUMIF($B:$B,$E7,AB:AB) -> 32 | AC7: =IFERROR(AB7/AA7,0) -> 0.84210526 | AD7: =AB7-AA7 -> -6 | AE7: =IFERROR(AVERAGEIFS(Cliente!$AG:$AG,Cliente!$B:$B,Geral!$E7,Cliente!$AG:$AG,">0"),0) -> 62.276404 | AF7: =COUNTIF(Cliente!$B:$B,Geral!$E7) -> 38 | AG7: =SUMIF($B:$B,$E7,AG:AG) -> 32 | AH7: =AG7/AF7 -> 0.84210526 | AI7: =AG7-AF7 -> -6 | AJ7: =IFERROR(AVERAGEIFS(Cliente!$AN:$AN,Cliente!$B:$B,Geral!$E7,Cliente!$AN:$AN,">0"),0) -> 62.924219 | AK7: =COUNTIF(Cliente!$B:$B,Geral!$E7) -> 38 | AL7: =SUMIF($B:$B,$E7,AL:AL) -> 38 | AM7: =AL7/AK7 -> 1 | AN7: =AL7-AK7 -> 0 | AO7: =IFERROR(AVERAGEIFS(Cliente!$AU:$AU,Cliente!$B:$B,Geral!$E7,Cliente!$AU:$AU,">0"),0) -> 59.748026 | AP7: =COUNTIF(Cliente!$B:$B,Geral!$E7) -> 38 | AQ7: =SUMIF($B:$B,$E7,AQ:AQ) -> 38 | AR7: =AQ7/AP7 -> 1 | AS7: =AQ7-AP7 -> 0 | AT7: =IFERROR(AVERAGEIFS(Cliente!$BB:$BB,Cliente!$B:$B,Geral!$E7,Cliente!$BB:$BB,">0"),0) -> 74.092368 | AU7: =COUNTIF(Cliente!$B:$B,Geral!$E7) -> 38 | AV7: =SUMIF($B:$B,$E7,AV:AV) -> 28 | AW7: =IFERROR(AV7/AU7,0) -> 0.73684211 | AX7: =AV7-AU7 -> -10 | AY7: =AVERAGE(BD7,BI7,BN7) -> 81.455104 | AZ7: =COUNTIF(Cliente!$B:$B,Geral!$E7) -> 38 | BA7: =SUMIF($B:$B,$E7,BA:BA) -> 34 | BB7: =BA7/AZ7 -> 0.89473684 | BC7: =BA7-AZ7 -> -4 | BD7: =IFERROR(AVERAGEIFS(Cliente!$BL:$BL,Cliente!$B:$B,Geral!$E7,Cliente!$BL:$BL,">0"),0) -> 72.031324 | BE7: =COUNTIF(Cliente!$B:$B,Geral!$E7) -> 38 | BF7: =SUMIF($B:$B,$E7,BF:BF) -> 30 | BG7: =BF7/BE7 -> 0.78947368 | BH7: =BF7-BE7 -> -8 | BI7: =IFERROR(AVERAGEIFS(Cliente!$BS:$BS,Cliente!$B:$B,Geral!$E7,Cliente!$BS:$BS,">0"),0) -> 82.706333 | BJ7: =COUNTIF(Cliente!$B:$B,Geral!$E7) -> 38 | BK7: =SUMIF($B:$B,$E7,BK:BK) -> 32 | BL7: =BK7/BJ7 -> 0.84210526 | BM7: =BK7-BJ7 -> -6 | BN7: =IFERROR(AVERAGEIFS(Cliente!$BZ:$BZ,Cliente!$B:$B,Geral!$E7,Cliente!$BZ:$BZ,">0"),0) -> 89.627656 | BO7: =COUNTIF(Cliente!$B:$B,Geral!$E7) -> 38 | BP7: =SUMIF($B:$B,$E7,BP:BP) -> 11 | BQ7: =IFERROR(BP7/BO7,0) -> 0.28947368 | BR7: =BP7-BO7 -> -27 | BS7: =IFERROR(AVERAGEIFS(Cliente!$CB:$CB,Cliente!$B:$B,Geral!$E7,Cliente!$CB:$CB,">0"),0) -> 66.031481 | BT7: =COUNTIF(Cliente!$B:$B,Geral!$E7) -> 38 | BU7: =SUMIF($B:$B,$E7,BU:BU) -> 33 | BV7: =BU7/BT7 -> 0.86842105 | BW7: =BU7-BT7 -> -5 | BX7: =IFERROR(AVERAGEIFS(Cliente!$CL:$CL,Cliente!$B:$B,Geral!$E7,Cliente!$CL:$CL,">0"),0) -> 89.071515 | BY7: =COUNTIF(Cliente!$B:$B,Geral!$E7) -> 38 | BZ7: =SUMIF($B:$B,$E7,BZ:BZ) -> 32 | CA7: =BZ7/BY7 -> 0.84210526 | CB7: =BZ7-BY7 -> -6 | CC7: =IFERROR(AVERAGEIFS(Cliente!$CU:$CU,Cliente!$B:$B,Geral!$E7,Cliente!$CU:$CU,">0"),0) -> 89.534063 | CD7: =COUNTIF(Cliente!$B:$B,Geral!$E7) -> 38 | CE7: =SUMIF($B:$B,$E7,CE:CE) -> 14 | CF7: =CE7/CD7 -> 0.36842105 | CG7: =CE7-CD7 -> -24 | CH7: =IFERROR(AVERAGEIFS(Cliente!$DD:$DD,Cliente!$B:$B,Geral!$E7,Cliente!$DD:$DD,">0"),0) -> 94.782143
E8: TT | F8: =SUM(F6:F7) -> 14 | G8: =SUM(G6:G7) -> 71 | H8: =SUM(H6:H7) -> 58 | I8: =IFERROR(H8/G8,0) -> 0.81690141 | J8: =H8-G8 -> -13 | K8: =Cliente!$L$2 -> 63.814401 | L8: =SUM(L6:L7) -> 71 | M8: =SUM(M6:M7) -> 67 | N8: =M8/L8 -> 0.94366197 | O8: =M8-L8 -> -4 | P8: =Cliente!$S$2 -> 61.70153 | Q8: =SUM(Q6:Q7) -> 71 | R8: =SUM(R6:R7) -> 65 | S8: =R8/Q8 -> 0.91549296 | T8: =R8-Q8 -> -6 | U8: =Cliente!$Y$2 -> 65.5923 | V8: =SUM(V6:V7) -> 71 | W8: =SUM(W6:W7) -> 68 | X8: =W8/V8 -> 0.95774648 | Y8: =W8-V8 -> -3 | Z8: =Cliente!$AE$2 -> 75.672451 | AA8: =SUM(AA6:AA7) -> 71 | AB8: =SUM(AB6:AB7) -> 47 | AC8: =IFERROR(AB8/AA8,0) -> 0.66197183 | AD8: =AB8-AA8 -> -24 | AE8: =Cliente!AG2 -> 52.335566 | AF8: =SUM(AF6:AF7) -> 71 | AG8: =SUM(AG6:AG7) -> 58 | AH8: =AG8/AF8 -> 0.81690141 | AI8: =AG8-AF8 -> -13 | AJ8: 80.4 | AK8: =SUM(AK6:AK7) -> 71 | AL8: =SUM(AL6:AL7) -> 59 | AM8: =AL8/AK8 -> 0.83098592 | AN8: =AL8-AK8 -> -12 | AO8: 80.4 | AP8: =SUM(AP6:AP7) -> 71 | AQ8: =SUM(AQ6:AQ7) -> 63 | AR8: =AQ8/AP8 -> 0.88732394 | AS8: =AQ8-AP8 -> -8 | AT8: =Cliente!$BB$2 -> 69.654891 | AU8: =SUM(AU6:AU7) -> 71 | AV8: =SUM(AV6:AV7) -> 50 | AW8: =IFERROR(AV8/AU8,0) -> 0.70422535 | AX8: =AV8-AU8 -> -21 | AY8: =AVERAGE(BD8,BI8,BN8) -> 81.127772 | AZ8: =SUM(AZ6:AZ7) -> 71 | BA8: =SUM(BA6:BA7) -> 63 | BB8: =BA8/AZ8 -> 0.88732394 | BC8: =BA8-AZ8 -> -8 | BD8: =Cliente!$BL$2 -> 72.09254 | BE8: =SUM(BE6:BE7) -> 71 | BF8: =SUM(BF6:BF7) -> 58 | BG8: =BF8/BE8 -> 0.81690141 | BH8: =BF8-BE8 -> -13 | BI8: =Cliente!$BS$2 -> 84.198103 | BJ8: =SUM(BJ6:BJ7) -> 71 | BK8: =SUM(BK6:BK7) -> 58 | BL8: =BK8/BJ8 -> 0.81690141 | BM8: =BK8-BJ8 -> -13 | BN8: =Cliente!$BZ$2 -> 87.092672 | BO8: =SUM(BO6:BO7) -> 71 | BP8: =SUM(BP6:BP7) -> 30 | BQ8: =IFERROR(BP8/BO8,0) -> 0.42253521 | BR8: =BP8-BO8 -> -41 | BS8: =Cliente!$CB$2 -> 89.555484 | BT8: =SUM(BT6:BT7) -> 71 | BU8: =SUM(BU6:BU7) -> 58 | BV8: =BU8/BT8 -> 0.81690141 | BW8: =BU8-BT8 -> -13 | BX8: =Cliente!$CL$2 -> 88.177759 | BY8: =SUM(BY6:BY7) -> 71 | BZ8: =SUM(BZ6:BZ7) -> 57 | CA8: =BZ8/BY8 -> 0.8028169 | CB8: =BZ8-BY8 -> -14 | CC8: =Cliente!$CU$2 -> 90.117368 | CD8: =SUM(CD6:CD7) -> 71 | CE8: =SUM(CE6:CE7) -> 34 | CF8: =CE8/CD8 -> 0.47887324 | CG8: =CE8-CD8 -> -37 | CH8: =Cliente!$DD$2 -> 90.371324
E9: ATUALIZADO:
E10: 46191
B13: JOHNSON - LOJA PERFEITA 360 | F13: REDE | G13: Q1 - JULHO A SETEMBRO 2025 | L13: JULHO | Q13: AGOSTO | V13: SETEMBRO | AA13: Q2 - OUTUBRO A DEZEMBRO 2025 | AF13: OUTUBRO | AK13: NOVEMBRO | AP13: DEZEMBRO | AU13: Q3 - JANEIRO A MARÇO 2026 | AZ13: JANEIRO | BE13: FEVEREIRO | BJ13: MARÇO | BO13: Q4 - ABRIL A JUNHO 2025 | BT13: ABRIL | BY13: MAIO | CD13: JUNHO
B14: EQUIPE | C14: CÓD | D14: ÁREA | E14: VENDEDOR/REPRESENTANTE | G14: LOJAS | H14: AUDITADA | I14: % | J14: GAP | K14: MÉDIA | L14: LOJAS | M14: AUDITADA | N14: % | O14: GAP | P14: MÉDIA | Q14: LOJAS | R14: AUDITADA | S14: % | T14: GAP | U14: MÉDIA | V14: LOJAS | W14: AUDITADA | X14: % | Y14: GAP | Z14: MÉDIA | AA14: LOJAS | AB14: AUDITADA | AC14: % | AD14: GAP | AE14: MÉDIA | AF14: LOJAS | AG14: AUDITADA | AH14: % | AI14: GAP | AJ14: MÉDIA | AK14: LOJAS | AL14: AUDITADA | AM14: % | AN14: GAP | AO14: MÉDIA | AP14: LOJAS | AQ14: AUDITADA | AR14: % | AS14: GAP | AT14: MÉDIA | AU14: LOJAS | AV14: AUDITADA | AW14: % | AX14: GAP | AY14: MÉDIA | AZ14: LOJAS | BA14: AUDITADA | BB14: % | BC14: GAP | BD14: MÉDIA | BE14: LOJAS | BF14: AUDITADA | BG14: % | BH14: GAP | BI14: MÉDIA | BJ14: LOJAS | BK14: AUDITADA | BL14: % | BM14: GAP | BN14: MÉDIA | BO14: LOJAS | BP14: AUDITADA | BQ14: % | BR14: GAP | BS14: MÉDIA | BT14: LOJAS | BU14: AUDITADA | BV14: % | BW14: GAP | BX14: MÉDIA | BY14: LOJAS | BZ14: AUDITADA | CA14: % | CB14: GAP | CC14: MÉDIA | CD14: LOJAS | CE14: AUDITADA | CF14: % | CG14: GAP | CH14: MÉDIA
B15: FLP-SUL MC/KA D | C15: 771 | D15: MC-FLP D | E15: JOAO JOSE NASCIMENTO | F15: =COUNTIF(Rede!$C:$C,Geral!$C15) -> 1 | G15: =COUNTIF(Cliente!$C:$C,Geral!$C15) -> 3 | H15: =SUMIF(Rede!$C:$C,Geral!$C15,Rede!$G:$G) -> 3 | I15: =IFERROR(H15/G15,0) -> 1 | J15: =H15-G15 -> 0 | K15: =IFERROR(AVERAGEIFS(Cliente!$L:$L,Cliente!$C:$C,Geral!$C15,Cliente!$L:$L,">0"),0) -> 50.060278 | L15: =COUNTIF(Cliente!$C:$C,Geral!$C15) -> 3 | M15: =SUMIF(Rede!$C:$C,Geral!$C15,Rede!$J:$J) -> 3 | N15: =IFERROR(M15/L15,0) -> 1 | O15: =M15-L15 -> 0 | P15: =IFERROR(AVERAGEIFS(Cliente!$S:$S,Cliente!$C:$C,Geral!$C15,Cliente!$S:$S,">0"),0) -> 32.814167 | Q15: =COUNTIF(Cliente!$C:$C,Geral!$C15) -> 3 | R15: =SUMIF(Rede!$C:$C,Geral!$C15,Rede!$M:$M) -> 3 | S15: =IFERROR(R15/Q15,0) -> 1 | T15: =R15-Q15 -> 0 | U15: =IFERROR(AVERAGEIFS(Cliente!$Y:$Y,Cliente!$C:$C,Geral!$C15,Cliente!$Y:$Y,">0"),0) -> 46.045 | V15: =COUNTIF(Cliente!$C:$C,Geral!$C15) -> 3 | W15: =SUMIF(Rede!$C:$C,Geral!$C15,Rede!$P:$P) -> 3 | X15: =IFERROR(W15/V15,0) -> 1 | Y15: =W15-V15 -> 0 | Z15: =IFERROR(AVERAGEIFS(Cliente!$AE:$AE,Cliente!$C:$C,Geral!$C15,Cliente!$AE:$AE,">0"),0) -> 71.321667 | AA15: =COUNTIF(Cliente!$C:$C,Geral!$C15) -> 3 | AB15: =SUMIF(Rede!$C:$C,Geral!$C15,Rede!$S:$S) -> 0 | AC15: =IFERROR(AB15/AA15,0) -> 0 | AD15: =AB15-AA15 -> -3 | AE15: =IFERROR(AVERAGEIFS(Cliente!$AG:$AG,Cliente!$C:$C,Geral!$C15,Cliente!$AG:$AG,">0"),0) -> 19.734167 | AF15: =COUNTIF(Cliente!$C:$C,Geral!$C15) -> 3 | AG15: =SUMIF(Rede!$C:$C,Geral!$C15,Rede!$V:$V) -> 2 | AH15: =AG15/AF15 -> 0.66666667 | AI15: =AG15-AF15 -> -1 | AJ15: =IFERROR(AVERAGEIFS(Cliente!$AN:$AN,Cliente!$C:$C,Geral!$C15,Cliente!$AN:$AN,">0"),0) -> 59.2025 | AK15: =COUNTIF(Cliente!$C:$C,Geral!$C15) -> 3 | AL15: =SUMIF(Rede!$C:$C,Geral!$C15,Rede!$Y:$Y) -> 0 | AM15: =AL15/AK15 -> 0 | AN15: =AL15-AK15 -> -3 | AO15: =IFERROR(AVERAGEIFS(Cliente!$AU:$AU,Cliente!$C:$C,Geral!$C15,Cliente!$AU:$AU,">0"),0) -> 0 | AP15: =COUNTIF(Cliente!$C:$C,Geral!$C15) -> 3 | AQ15: =SUMIF(Rede!$C:$C,Geral!$C15,Rede!$AB:$AB) -> 0 | AR15: =AQ15/AP15 -> 0 | AS15: =AQ15-AP15 -> -3 | AT15: =IFERROR(AVERAGEIFS(Cliente!$BB:$BB,Cliente!$C:$C,Geral!$C15,Cliente!$BB:$BB,">0"),0) -> 0 | AU15: =COUNTIF(Cliente!$C:$C,Geral!$C15) -> 3 | AV15: =SUMIF(Rede!$C:$C,Geral!$C15,Rede!$AE:$AE) -> 1 | AW15: =IFERROR(AV15/AU15,0) -> 0.33333333 | AX15: =AV15-AU15 -> -2 | AY15: =AVERAGE(BD15,BI15,BN15) -> 78.904167 | AZ15: =COUNTIF(Cliente!$C:$C,Geral!$C15) -> 3 | BA15: =SUMIF(Rede!$C:$C,Geral!$C15,Rede!$AH:$AH) -> 2 | BB15: =BA15/AZ15 -> 0.66666667 | BC15: =BA15-AZ15 -> -1 | BD15: =IFERROR(AVERAGEIFS(Cliente!$BL:$BL,Cliente!$C:$C,Geral!$C15,Cliente!$BL:$BL,">0"),0) -> 71.7125 | BE15: =COUNTIF(Cliente!$C:$C,Geral!$C15) -> 3 | BF15: =SUMIF(Rede!$C:$C,Geral!$C15,Rede!$AK:$AK) -> 2 | BG15: =BF15/BE15 -> 0.66666667 | BH15: =BF15-BE15 -> -1 | BI15: =IFERROR(AVERAGEIFS(Cliente!$BS:$BS,Cliente!$C:$C,Geral!$C15,Cliente!$BS:$BS,">0"),0) -> 79.4 | BJ15: =COUNTIF(Cliente!$C:$C,Geral!$C15) -> 3 | BK15: =SUMIF(Rede!$C:$C,Geral!$C15,Rede!$AN:$AN) -> 1 | BL15: =BK15/BJ15 -> 0.33333333 | BM15: =BK15-BJ15 -> -2 | BN15: =IFERROR(AVERAGEIFS(Cliente!$BZ:$BZ,Cliente!$C:$C,Geral!$C15,Cliente!$BZ:$BZ,">0"),0) -> 85.6 | BO15: =COUNTIF(Cliente!$C:$C,Geral!$C15) -> 3 | BP15: =SUMIF(Rede!$C:$C,Geral!$C15,Rede!$AQ:$AQ) -> 0 | BQ15: =IFERROR(BP15/BO15,0) -> 0 | BR15: =BP15-BO15 -> -3 | BS15: =IFERROR(AVERAGEIFS(Cliente!$CB:$CB,Cliente!$C:$C,Geral!$C15,Cliente!$CB:$CB,">0"),0) -> 25.95 | BT15: =COUNTIF(Cliente!$C:$C,Geral!$C15) -> 3 | BU15: =SUMIF(Rede!$C:$C,Geral!$C15,Rede!$AT:$AT) -> 0 | BV15: =BU15/BT15 -> 0 | BW15: =BU15-BT15 -> -3 | BX15: =IFERROR(AVERAGEIFS(Cliente!$CL:$CL,Cliente!$C:$C,Geral!$C15,Cliente!$CL:$CL,">0"),0) -> 0 | BY15: =COUNTIF(Cliente!$C:$C,Geral!$C15) -> 3 | BZ15: =SUMIF(Rede!$C:$C,Geral!$C15,Rede!$AW:$AW) -> 0 | CA15: =BZ15/BY15 -> 0 | CB15: =BZ15-BY15 -> -3 | CC15: =IFERROR(AVERAGEIFS(Cliente!$CU:$CU,Cliente!$C:$C,Geral!$C15,Cliente!$CU:$CU,">0"),0) -> 0 | CD15: =COUNTIF(Cliente!$C:$C,Geral!$C15) -> 3 | CE15: =SUMIF(Rede!$C:$C,Geral!$C15,Rede!$AZ:$AZ) -> 1 | CF15: =CE15/CD15 -> 0.33333333 | CG15: =CE15-CD15 -> -2 | CH15: =IFERROR(AVERAGEIFS(Cliente!$DD:$DD,Cliente!$C:$C,Geral!$C15,Cliente!$DD:$DD,">0"),0) -> 77.85
B16: FLP-SUL MC/KA D | C16: 3919 | D16: MC-TBCR D | E16: GISLAINE BORGES RODRIGUES | F16: =COUNTIF(Rede!$C:$C,Geral!$C16) -> 4 | G16: =COUNTIF(Cliente!$C:$C,Geral!$C16) -> 20 | H16: =SUMIF(Rede!$C:$C,Geral!$C16,Rede!$G:$G) -> 13 | I16: =IFERROR(H16/G16,0) -> 0.65 | J16: =H16-G16 -> -7 | K16: =IFERROR(AVERAGEIFS(Cliente!$L:$L,Cliente!$C:$C,Geral!$C16,Cliente!$L:$L,">0"),0) -> 57.598875 | L16: =COUNTIF(Cliente!$C:$C,Geral!$C16) -> 20 | M16: =SUMIF(Rede!$C:$C,Geral!$C16,Rede!$J:$J) -> 17 | N16: =IFERROR(M16/L16,0) -> 0.85 | O16: =M16-L16 -> -3 | P16: =IFERROR(AVERAGEIFS(Cliente!$S:$S,Cliente!$C:$C,Geral!$C16,Cliente!$S:$S,">0"),0) -> 54.314559 | Q16: =COUNTIF(Cliente!$C:$C,Geral!$C16) -> 20 | R16: =SUMIF(Rede!$C:$C,Geral!$C16,Rede!$M:$M) -> 19 | S16: =IFERROR(R16/Q16,0) -> 0.95 | T16: =R16-Q16 -> -1 | U16: =IFERROR(AVERAGEIFS(Cliente!$Y:$Y,Cliente!$C:$C,Geral!$C16,Cliente!$Y:$Y,">0"),0) -> 63.862632 | V16: =COUNTIF(Cliente!$C:$C,Geral!$C16) -> 20 | W16: =SUMIF(Rede!$C:$C,Geral!$C16,Rede!$P:$P) -> 17 | X16: =IFERROR(W16/V16,0) -> 0.85 | Y16: =W16-V16 -> -3 | Z16: =IFERROR(AVERAGEIFS(Cliente!$AE:$AE,Cliente!$C:$C,Geral!$C16,Cliente!$AE:$AE,">0"),0) -> 77.599706 | AA16: =COUNTIF(Cliente!$C:$C,Geral!$C16) -> 20 | AB16: =SUMIF(Rede!$C:$C,Geral!$C16,Rede!$S:$S) -> 10 | AC16: =IFERROR(AB16/AA16,0) -> 0.5 | AD16: =AB16-AA16 -> -10 | AE16: =IFERROR(AVERAGEIFS(Cliente!$AG:$AG,Cliente!$C:$C,Geral!$C16,Cliente!$AG:$AG,">0"),0) -> 49.455417 | AF16: =COUNTIF(Cliente!$C:$C,Geral!$C16) -> 20 | AG16: =SUMIF(Rede!$C:$C,Geral!$C16,Rede!$V:$V) -> 14 | AH16: =AG16/AF16 -> 0.7 | AI16: =AG16-AF16 -> -6 | AJ16: =IFERROR(AVERAGEIFS(Cliente!$AN:$AN,Cliente!$C:$C,Geral!$C16,Cliente!$AN:$AN,">0"),0) -> 62.919643 | AK16: =COUNTIF(Cliente!$C:$C,Geral!$C16) -> 20 | AL16: =SUMIF(Rede!$C:$C,Geral!$C16,Rede!$Y:$Y) -> 14 | AM16: =AL16/AK16 -> 0.7 | AN16: =AL16-AK16 -> -6 | AO16: =IFERROR(AVERAGEIFS(Cliente!$AU:$AU,Cliente!$C:$C,Geral!$C16,Cliente!$AU:$AU,">0"),0) -> 63.159286 | AP16: =COUNTIF(Cliente!$C:$C,Geral!$C16) -> 20 | AQ16: =SUMIF(Rede!$C:$C,Geral!$C16,Rede!$AB:$AB) -> 19 | AR16: =AQ16/AP16 -> 0.95 | AS16: =AQ16-AP16 -> -1 | AT16: =IFERROR(AVERAGEIFS(Cliente!$BB:$BB,Cliente!$C:$C,Geral!$C16,Cliente!$BB:$BB,">0"),0) -> 63.274737 | AU16: =COUNTIF(Cliente!$C:$C,Geral!$C16) -> 20 | AV16: =SUMIF(Rede!$C:$C,Geral!$C16,Rede!$AE:$AE) -> 15 | AW16: =IFERROR(AV16/AU16,0) -> 0.75 | AX16: =AV16-AU16 -> -5 | AY16: =AVERAGE(BD16,BI16,BN16) -> 79.834421 | AZ16: =COUNTIF(Cliente!$C:$C,Geral!$C16) -> 20 | BA16: =SUMIF(Rede!$C:$C,Geral!$C16,Rede!$AH:$AH) -> 20 | BB16: =BA16/AZ16 -> 1 | BC16: =BA16-AZ16 -> 0 | BD16: =IFERROR(AVERAGEIFS(Cliente!$BL:$BL,Cliente!$C:$C,Geral!$C16,Cliente!$BL:$BL,">0"),0) -> 73.76425 | BE16: =COUNTIF(Cliente!$C:$C,Geral!$C16) -> 20 | BF16: =SUMIF(Rede!$C:$C,Geral!$C16,Rede!$AK:$AK) -> 20 | BG16: =BF16/BE16 -> 1 | BH16: =BF16-BE16 -> 0 | BI16: =IFERROR(AVERAGEIFS(Cliente!$BS:$BS,Cliente!$C:$C,Geral!$C16,Cliente!$BS:$BS,">0"),0) -> 84.27375 | BJ16: =COUNTIF(Cliente!$C:$C,Geral!$C16) -> 20 | BK16: =SUMIF(Rede!$C:$C,Geral!$C16,Rede!$AN:$AN) -> 19 | BL16: =BK16/BJ16 -> 0.95 | BM16: =BK16-BJ16 -> -1 | BN16: =IFERROR(AVERAGEIFS(Cliente!$BZ:$BZ,Cliente!$C:$C,Geral!$C16,Cliente!$BZ:$BZ,">0"),0) -> 81.465263 | BO16: =COUNTIF(Cliente!$C:$C,Geral!$C16) -> 20 | BP16: =SUMIF(Rede!$C:$C,Geral!$C16,Rede!$AQ:$AQ) -> 15 | BQ16: =IFERROR(BP16/BO16,0) -> 0.75 | BR16: =BP16-BO16 -> -5 | BS16: =IFERROR(AVERAGEIFS(Cliente!$CB:$CB,Cliente!$C:$C,Geral!$C16,Cliente!$CB:$CB,">0"),0) -> 79.999583 | BT16: =COUNTIF(Cliente!$C:$C,Geral!$C16) -> 20 | BU16: =SUMIF(Rede!$C:$C,Geral!$C16,Rede!$AT:$AT) -> 20 | BV16: =BU16/BT16 -> 1 | BW16: =BU16-BT16 -> 0 | BX16: =IFERROR(AVERAGEIFS(Cliente!$CL:$CL,Cliente!$C:$C,Geral!$C16,Cliente!$CL:$CL,">0"),0) -> 86.2675 | BY16: =COUNTIF(Cliente!$C:$C,Geral!$C16) -> 20 | BZ16: =SUMIF(Rede!$C:$C,Geral!$C16,Rede!$AW:$AW) -> 20 | CA16: =BZ16/BY16 -> 1 | CB16: =BZ16-BY16 -> 0 | CC16: =IFERROR(AVERAGEIFS(Cliente!$CU:$CU,Cliente!$C:$C,Geral!$C16,Cliente!$CU:$CU,">0"),0) -> 89.71 | CD16: =COUNTIF(Cliente!$C:$C,Geral!$C16) -> 20 | CE16: =SUMIF(Rede!$C:$C,Geral!$C16,Rede!$AZ:$AZ) -> 15 | CF16: =CE16/CD16 -> 0.75 | CG16: =CE16-CD16 -> -5 | CH16: =IFERROR(AVERAGEIFS(Cliente!$DD:$DD,Cliente!$C:$C,Geral!$C16,Cliente!$DD:$DD,">0"),0) -> 85.361667
B17: FLP-SUL MC/KA D | C17: 3956 | D17: MC-IMB D | E17: RAFAEL BERNARDO VIEIRA | F17: =COUNTIF(Rede!$C:$C,Geral!$C17) -> 1 | G17: =COUNTIF(Cliente!$C:$C,Geral!$C17) -> 3 | H17: =SUMIF(Rede!$C:$C,Geral!$C17,Rede!$G:$G) -> 2 | I17: =IFERROR(H17/G17,0) -> 0.66666667 | J17: =H17-G17 -> -1 | K17: =IFERROR(AVERAGEIFS(Cliente!$L:$L,Cliente!$C:$C,Geral!$C17,Cliente!$L:$L,">0"),0) -> 72.658889 | L17: =COUNTIF(Cliente!$C:$C,Geral!$C17) -> 3 | M17: =SUMIF(Rede!$C:$C,Geral!$C17,Rede!$J:$J) -> 3 | N17: =IFERROR(M17/L17,0) -> 1 | O17: =M17-L17 -> 0 | P17: =IFERROR(AVERAGEIFS(Cliente!$S:$S,Cliente!$C:$C,Geral!$C17,Cliente!$S:$S,">0"),0) -> 70.488333 | Q17: =COUNTIF(Cliente!$C:$C,Geral!$C17) -> 3 | R17: =SUMIF(Rede!$C:$C,Geral!$C17,Rede!$M:$M) -> 2 | S17: =IFERROR(R17/Q17,0) -> 0.66666667 | T17: =R17-Q17 -> -1 | U17: =IFERROR(AVERAGEIFS(Cliente!$Y:$Y,Cliente!$C:$C,Geral!$C17,Cliente!$Y:$Y,">0"),0) -> 89.21 | V17: =COUNTIF(Cliente!$C:$C,Geral!$C17) -> 3 | W17: =SUMIF(Rede!$C:$C,Geral!$C17,Rede!$P:$P) -> 3 | X17: =IFERROR(W17/V17,0) -> 1 | Y17: =W17-V17 -> 0 | Z17: =IFERROR(AVERAGEIFS(Cliente!$AE:$AE,Cliente!$C:$C,Geral!$C17,Cliente!$AE:$AE,">0"),0) -> 88.015 | AA17: =COUNTIF(Cliente!$C:$C,Geral!$C17) -> 3 | AB17: =SUMIF(Rede!$C:$C,Geral!$C17,Rede!$S:$S) -> 3 | AC17: =IFERROR(AB17/AA17,0) -> 1 | AD17: =AB17-AA17 -> 0 | AE17: =IFERROR(AVERAGEIFS(Cliente!$AG:$AG,Cliente!$C:$C,Geral!$C17,Cliente!$AG:$AG,">0"),0) -> 78.671111 | AF17: =COUNTIF(Cliente!$C:$C,Geral!$C17) -> 3 | AG17: =SUMIF(Rede!$C:$C,Geral!$C17,Rede!$V:$V) -> 3 | AH17: =AG17/AF17 -> 1 | AI17: =AG17-AF17 -> 0 | AJ17: =IFERROR(AVERAGEIFS(Cliente!$AN:$AN,Cliente!$C:$C,Geral!$C17,Cliente!$AN:$AN,">0"),0) -> 71.993333 | AK17: =COUNTIF(Cliente!$C:$C,Geral!$C17) -> 3 | AL17: =SUMIF(Rede!$C:$C,Geral!$C17,Rede!$Y:$Y) -> 3 | AM17: =AL17/AK17 -> 1 | AN17: =AL17-AK17 -> 0 | AO17: =IFERROR(AVERAGEIFS(Cliente!$AU:$AU,Cliente!$C:$C,Geral!$C17,Cliente!$AU:$AU,">0"),0) -> 73.503333 | AP17: =COUNTIF(Cliente!$C:$C,Geral!$C17) -> 3 | AQ17: =SUMIF(Rede!$C:$C,Geral!$C17,Rede!$AB:$AB) -> 3 | AR17: =AQ17/AP17 -> 1 | AS17: =AQ17-AP17 -> 0 | AT17: =IFERROR(AVERAGEIFS(Cliente!$BB:$BB,Cliente!$C:$C,Geral!$C17,Cliente!$BB:$BB,">0"),0) -> 90.516667 | AU17: =COUNTIF(Cliente!$C:$C,Geral!$C17) -> 3 | AV17: =SUMIF(Rede!$C:$C,Geral!$C17,Rede!$AE:$AE) -> 3 | AW17: =IFERROR(AV17/AU17,0) -> 1 | AX17: =AV17-AU17 -> 0 | AY17: =AVERAGE(BD17,BI17,BN17) -> 87.269444 | AZ17: =COUNTIF(Cliente!$C:$C,Geral!$C17) -> 3 | BA17: =SUMIF(Rede!$C:$C,Geral!$C17,Rede!$AH:$AH) -> 3 | BB17: =BA17/AZ17 -> 1 | BC17: =BA17-AZ17 -> 0 | BD17: =IFERROR(AVERAGEIFS(Cliente!$BL:$BL,Cliente!$C:$C,Geral!$C17,Cliente!$BL:$BL,">0"),0) -> 78.608333 | BE17: =COUNTIF(Cliente!$C:$C,Geral!$C17) -> 3 | BF17: =SUMIF(Rede!$C:$C,Geral!$C17,Rede!$AK:$AK) -> 3 | BG17: =BF17/BE17 -> 1 | BH17: =BF17-BE17 -> 0 | BI17: =IFERROR(AVERAGEIFS(Cliente!$BS:$BS,Cliente!$C:$C,Geral!$C17,Cliente!$BS:$BS,">0"),0) -> 93 | BJ17: =COUNTIF(Cliente!$C:$C,Geral!$C17) -> 3 | BK17: =SUMIF(Rede!$C:$C,Geral!$C17,Rede!$AN:$AN) -> 3 | BL17: =BK17/BJ17 -> 1 | BM17: =BK17-BJ17 -> 0 | BN17: =IFERROR(AVERAGEIFS(Cliente!$BZ:$BZ,Cliente!$C:$C,Geral!$C17,Cliente!$BZ:$BZ,">0"),0) -> 90.2 | BO17: =COUNTIF(Cliente!$C:$C,Geral!$C17) -> 3 | BP17: =SUMIF(Rede!$C:$C,Geral!$C17,Rede!$AQ:$AQ) -> 3 | BQ17: =IFERROR(BP17/BO17,0) -> 1 | BR17: =BP17-BO17 -> 0 | BS17: =IFERROR(AVERAGEIFS(Cliente!$CB:$CB,Cliente!$C:$C,Geral!$C17,Cliente!$CB:$CB,">0"),0) -> 95.511111 | BT17: =COUNTIF(Cliente!$C:$C,Geral!$C17) -> 3 | BU17: =SUMIF(Rede!$C:$C,Geral!$C17,Rede!$AT:$AT) -> 3 | BV17: =BU17/BT17 -> 1 | BW17: =BU17-BT17 -> 0 | BX17: =IFERROR(AVERAGEIFS(Cliente!$CL:$CL,Cliente!$C:$C,Geral!$C17,Cliente!$CL:$CL,">0"),0) -> 89.6 | BY17: =COUNTIF(Cliente!$C:$C,Geral!$C17) -> 3 | BZ17: =SUMIF(Rede!$C:$C,Geral!$C17,Rede!$AW:$AW) -> 3 | CA17: =BZ17/BY17 -> 1 | CB17: =BZ17-BY17 -> 0 | CC17: =IFERROR(AVERAGEIFS(Cliente!$CU:$CU,Cliente!$C:$C,Geral!$C17,Cliente!$CU:$CU,">0"),0) -> 98.6 | CD17: =COUNTIF(Cliente!$C:$C,Geral!$C17) -> 3 | CE17: =SUMIF(Rede!$C:$C,Geral!$C17,Rede!$AZ:$AZ) -> 3 | CF17: =CE17/CD17 -> 1 | CG17: =CE17-CD17 -> 0 | CH17: =IFERROR(AVERAGEIFS(Cliente!$DD:$DD,Cliente!$C:$C,Geral!$C17,Cliente!$DD:$DD,">0"),0) -> 98.333333
B18: FLP-SUL MC/KA D | C18: 4054 | D18: MC-ARA D | E18: RAFAEL IZIDIO DE FARIAS | F18: =COUNTIF(Rede!$C:$C,Geral!$C18) -> 2 | G18: =COUNTIF(Cliente!$C:$C,Geral!$C18) -> 7 | H18: =SUMIF(Rede!$C:$C,Geral!$C18,Rede!$G:$G) -> 6 | I18: =IFERROR(H18/G18,0) -> 0.85714286 | J18: =H18-G18 -> -1 | K18: =IFERROR(AVERAGEIFS(Cliente!$L:$L,Cliente!$C:$C,Geral!$C18,Cliente!$L:$L,">0"),0) -> 57.412619 | L18: =COUNTIF(Cliente!$C:$C,Geral!$C18) -> 7 | M18: =SUMIF(Rede!$C:$C,Geral!$C18,Rede!$J:$J) -> 6 | N18: =IFERROR(M18/L18,0) -> 0.85714286 | O18: =M18-L18 -> -1 | P18: =IFERROR(AVERAGEIFS(Cliente!$S:$S,Cliente!$C:$C,Geral!$C18,Cliente!$S:$S,">0"),0) -> 64.156667 | Q18: =COUNTIF(Cliente!$C:$C,Geral!$C18) -> 7 | R18: =SUMIF(Rede!$C:$C,Geral!$C18,Rede!$M:$M) -> 7 | S18: =IFERROR(R18/Q18,0) -> 1 | T18: =R18-Q18 -> 0 | U18: =IFERROR(AVERAGEIFS(Cliente!$Y:$Y,Cliente!$C:$C,Geral!$C18,Cliente!$Y:$Y,">0"),0) -> 58.447857 | V18: =COUNTIF(Cliente!$C:$C,Geral!$C18) -> 7 | W18: =SUMIF(Rede!$C:$C,Geral!$C18,Rede!$P:$P) -> 7 | X18: =IFERROR(W18/V18,0) -> 1 | Y18: =W18-V18 -> 0 | Z18: =IFERROR(AVERAGEIFS(Cliente!$AE:$AE,Cliente!$C:$C,Geral!$C18,Cliente!$AE:$AE,">0"),0) -> 58.798571 | AA18: =COUNTIF(Cliente!$C:$C,Geral!$C18) -> 7 | AB18: =SUMIF(Rede!$C:$C,Geral!$C18,Rede!$S:$S) -> 2 | AC18: =IFERROR(AB18/AA18,0) -> 0.28571429 | AD18: =AB18-AA18 -> -5 | AE18: =IFERROR(AVERAGEIFS(Cliente!$AG:$AG,Cliente!$C:$C,Geral!$C18,Cliente!$AG:$AG,">0"),0) -> 38.915714 | AF18: =COUNTIF(Cliente!$C:$C,Geral!$C18) -> 7 | AG18: =SUMIF(Rede!$C:$C,Geral!$C18,Rede!$V:$V) -> 7 | AH18: =AG18/AF18 -> 1 | AI18: =AG18-AF18 -> 0 | AJ18: =IFERROR(AVERAGEIFS(Cliente!$AN:$AN,Cliente!$C:$C,Geral!$C18,Cliente!$AN:$AN,">0"),0) -> 57.550714 | AK18: =COUNTIF(Cliente!$C:$C,Geral!$C18) -> 7 | AL18: =SUMIF(Rede!$C:$C,Geral!$C18,Rede!$Y:$Y) -> 4 | AM18: =AL18/AK18 -> 0.57142857 | AN18: =AL18-AK18 -> -3 | AO18: =IFERROR(AVERAGEIFS(Cliente!$AU:$AU,Cliente!$C:$C,Geral!$C18,Cliente!$AU:$AU,">0"),0) -> 58.155 | AP18: =COUNTIF(Cliente!$C:$C,Geral!$C18) -> 7 | AQ18: =SUMIF(Rede!$C:$C,Geral!$C18,Rede!$AB:$AB) -> 3 | AR18: =AQ18/AP18 -> 0.42857143 | AS18: =AQ18-AP18 -> -4 | AT18: =IFERROR(AVERAGEIFS(Cliente!$BB:$BB,Cliente!$C:$C,Geral!$C18,Cliente!$BB:$BB,">0"),0) -> 60.585 | AU18: =COUNTIF(Cliente!$C:$C,Geral!$C18) -> 7 | AV18: =SUMIF(Rede!$C:$C,Geral!$C18,Rede!$AE:$AE) -> 3 | AW18: =IFERROR(AV18/AU18,0) -> 0.42857143 | AX18: =AV18-AU18 -> -4 | AY18: =AVERAGE(BD18,BI18,BN18) -> 81.883056 | AZ18: =COUNTIF(Cliente!$C:$C,Geral!$C18) -> 7 | BA18: =SUMIF(Rede!$C:$C,Geral!$C18,Rede!$AH:$AH) -> 4 | BB18: =BA18/AZ18 -> 0.57142857 | BC18: =BA18-AZ18 -> -3 | BD18: =IFERROR(AVERAGEIFS(Cliente!$BL:$BL,Cliente!$C:$C,Geral!$C18,Cliente!$BL:$BL,">0"),0) -> 59.5575 | BE18: =COUNTIF(Cliente!$C:$C,Geral!$C18) -> 7 | BF18: =SUMIF(Rede!$C:$C,Geral!$C18,Rede!$AK:$AK) -> 3 | BG18: =BF18/BE18 -> 0.42857143 | BH18: =BF18-BE18 -> -4 | BI18: =IFERROR(AVERAGEIFS(Cliente!$BS:$BS,Cliente!$C:$C,Geral!$C18,Cliente!$BS:$BS,">0"),0) -> 93.008333 | BJ18: =COUNTIF(Cliente!$C:$C,Geral!$C18) -> 7 | BK18: =SUMIF(Rede!$C:$C,Geral!$C18,Rede!$AN:$AN) -> 3 | BL18: =BK18/BJ18 -> 0.42857143 | BM18: =BK18-BJ18 -> -4 | BN18: =IFERROR(AVERAGEIFS(Cliente!$BZ:$BZ,Cliente!$C:$C,Geral!$C18,Cliente!$BZ:$BZ,">0"),0) -> 93.083333 | BO18: =COUNTIF(Cliente!$C:$C,Geral!$C18) -> 7 | BP18: =SUMIF(Rede!$C:$C,Geral!$C18,Rede!$AQ:$AQ) -> 1 | BQ18: =IFERROR(BP18/BO18,0) -> 0.14285714 | BR18: =BP18-BO18 -> -6 | BS18: =IFERROR(AVERAGEIFS(Cliente!$CB:$CB,Cliente!$C:$C,Geral!$C18,Cliente!$CB:$CB,">0"),0) -> 75.8 | BT18: =COUNTIF(Cliente!$C:$C,Geral!$C18) -> 7 | BU18: =SUMIF(Rede!$C:$C,Geral!$C18,Rede!$AT:$AT) -> 2 | BV18: =BU18/BT18 -> 0.28571429 | BW18: =BU18-BT18 -> -5 | BX18: =IFERROR(AVERAGEIFS(Cliente!$CL:$CL,Cliente!$C:$C,Geral!$C18,Cliente!$CL:$CL,">0"),0) -> 90.4 | BY18: =COUNTIF(Cliente!$C:$C,Geral!$C18) -> 7 | BZ18: =SUMIF(Rede!$C:$C,Geral!$C18,Rede!$AW:$AW) -> 2 | CA18: =BZ18/BY18 -> 0.28571429 | CB18: =BZ18-BY18 -> -5 | CC18: =IFERROR(AVERAGEIFS(Cliente!$CU:$CU,Cliente!$C:$C,Geral!$C18,Cliente!$CU:$CU,">0"),0) -> 90.8 | CD18: =COUNTIF(Cliente!$C:$C,Geral!$C18) -> 7 | CE18: =SUMIF(Rede!$C:$C,Geral!$C18,Rede!$AZ:$AZ) -> 1 | CF18: =CE18/CD18 -> 0.14285714 | CG18: =CE18-CD18 -> -6 | CH18: =IFERROR(AVERAGEIFS(Cliente!$DD:$DD,Cliente!$C:$C,Geral!$C18,Cliente!$DD:$DD,">0"),0) -> 92.4
B19: NORTE MC/KA D | C19: 179 | D19: KA-BRQ | E19: PEDRO PAULO ECCEL | F19: =COUNTIF(Rede!$C:$C,Geral!$C19) -> 1 | G19: =COUNTIF(Cliente!$C:$C,Geral!$C19) -> 6 | H19: =SUMIF(Rede!$C:$C,Geral!$C19,Rede!$G:$G) -> 6 | I19: =IFERROR(H19/G19,0) -> 1 | J19: =H19-G19 -> 0 | K19: =IFERROR(AVERAGEIFS(Cliente!$L:$L,Cliente!$C:$C,Geral!$C19,Cliente!$L:$L,">0"),0) -> 74.634722 | L19: =COUNTIF(Cliente!$C:$C,Geral!$C19) -> 6 | M19: =SUMIF(Rede!$C:$C,Geral!$C19,Rede!$J:$J) -> 6 | N19: =IFERROR(M19/L19,0) -> 1 | O19: =M19-L19 -> 0 | P19: =IFERROR(AVERAGEIFS(Cliente!$S:$S,Cliente!$C:$C,Geral!$C19,Cliente!$S:$S,">0"),0) -> 64.615833 | Q19: =COUNTIF(Cliente!$C:$C,Geral!$C19) -> 6 | R19: =SUMIF(Rede!$C:$C,Geral!$C19,Rede!$M:$M) -> 6 | S19: =IFERROR(R19/Q19,0) -> 1 | T19: =R19-Q19 -> 0 | U19: =IFERROR(AVERAGEIFS(Cliente!$Y:$Y,Cliente!$C:$C,Geral!$C19,Cliente!$Y:$Y,">0"),0) -> 77.273333 | V19: =COUNTIF(Cliente!$C:$C,Geral!$C19) -> 6 | W19: =SUMIF(Rede!$C:$C,Geral!$C19,Rede!$P:$P) -> 6 | X19: =IFERROR(W19/V19,0) -> 1 | Y19: =W19-V19 -> 0 | Z19: =IFERROR(AVERAGEIFS(Cliente!$AE:$AE,Cliente!$C:$C,Geral!$C19,Cliente!$AE:$AE,">0"),0) -> 82.015 | AA19: =COUNTIF(Cliente!$C:$C,Geral!$C19) -> 6 | AB19: =SUMIF(Rede!$C:$C,Geral!$C19,Rede!$S:$S) -> 4 | AC19: =IFERROR(AB19/AA19,0) -> 0.66666667 | AD19: =AB19-AA19 -> -2 | AE19: =IFERROR(AVERAGEIFS(Cliente!$AG:$AG,Cliente!$C:$C,Geral!$C19,Cliente!$AG:$AG,">0"),0) -> 58.011389 | AF19: =COUNTIF(Cliente!$C:$C,Geral!$C19) -> 6 | AG19: =SUMIF(Rede!$C:$C,Geral!$C19,Rede!$V:$V) -> 4 | AH19: =AG19/AF19 -> 0.66666667 | AI19: =AG19-AF19 -> -2 | AJ19: =IFERROR(AVERAGEIFS(Cliente!$AN:$AN,Cliente!$C:$C,Geral!$C19,Cliente!$AN:$AN,">0"),0) -> 65.75875 | AK19: =COUNTIF(Cliente!$C:$C,Geral!$C19) -> 6 | AL19: =SUMIF(Rede!$C:$C,Geral!$C19,Rede!$Y:$Y) -> 6 | AM19: =AL19/AK19 -> 1 | AN19: =AL19-AK19 -> 0 | AO19: =IFERROR(AVERAGEIFS(Cliente!$AU:$AU,Cliente!$C:$C,Geral!$C19,Cliente!$AU:$AU,">0"),0) -> 50.06 | AP19: =COUNTIF(Cliente!$C:$C,Geral!$C19) -> 6 | AQ19: =SUMIF(Rede!$C:$C,Geral!$C19,Rede!$AB:$AB) -> 6 | AR19: =AQ19/AP19 -> 1 | AS19: =AQ19-AP19 -> 0 | AT19: =IFERROR(AVERAGEIFS(Cliente!$BB:$BB,Cliente!$C:$C,Geral!$C19,Cliente!$BB:$BB,">0"),0) -> 80.135 | AU19: =COUNTIF(Cliente!$C:$C,Geral!$C19) -> 6 | AV19: =SUMIF(Rede!$C:$C,Geral!$C19,Rede!$AE:$AE) -> 6 | AW19: =IFERROR(AV19/AU19,0) -> 1 | AX19: =AV19-AU19 -> 0 | AY19: =AVERAGE(BD19,BI19,BN19) -> 74.015278 | AZ19: =COUNTIF(Cliente!$C:$C,Geral!$C19) -> 6 | BA19: =SUMIF(Rede!$C:$C,Geral!$C19,Rede!$AH:$AH) -> 6 | BB19: =BA19/AZ19 -> 1 | BC19: =BA19-AZ19 -> 0 | BD19: =IFERROR(AVERAGEIFS(Cliente!$BL:$BL,Cliente!$C:$C,Geral!$C19,Cliente!$BL:$BL,">0"),0) -> 70.141667 | BE19: =COUNTIF(Cliente!$C:$C,Geral!$C19) -> 6 | BF19: =SUMIF(Rede!$C:$C,Geral!$C19,Rede!$AK:$AK) -> 6 | BG19: =BF19/BE19 -> 1 | BH19: =BF19-BE19 -> 0 | BI19: =IFERROR(AVERAGEIFS(Cliente!$BS:$BS,Cliente!$C:$C,Geral!$C19,Cliente!$BS:$BS,">0"),0) -> 70.133333 | BJ19: =COUNTIF(Cliente!$C:$C,Geral!$C19) -> 6 | BK19: =SUMIF(Rede!$C:$C,Geral!$C19,Rede!$AN:$AN) -> 6 | BL19: =BK19/BJ19 -> 1 | BM19: =BK19-BJ19 -> 0 | BN19: =IFERROR(AVERAGEIFS(Cliente!$BZ:$BZ,Cliente!$C:$C,Geral!$C19,Cliente!$BZ:$BZ,">0"),0) -> 81.770833 | BO19: =COUNTIF(Cliente!$C:$C,Geral!$C19) -> 6 | BP19: =SUMIF(Rede!$C:$C,Geral!$C19,Rede!$AQ:$AQ) -> 0 | BQ19: =IFERROR(BP19/BO19,0) -> 0 | BR19: =BP19-BO19 -> -6 | BS19: =IFERROR(AVERAGEIFS(Cliente!$CB:$CB,Cliente!$C:$C,Geral!$C19,Cliente!$CB:$CB,">0"),0) -> 44.910278 | BT19: =COUNTIF(Cliente!$C:$C,Geral!$C19) -> 6 | BU19: =SUMIF(Rede!$C:$C,Geral!$C19,Rede!$AT:$AT) -> 6 | BV19: =BU19/BT19 -> 1 | BW19: =BU19-BT19 -> 0 | BX19: =IFERROR(AVERAGEIFS(Cliente!$CL:$CL,Cliente!$C:$C,Geral!$C19,Cliente!$CL:$CL,">0"),0) -> 68.993333 | BY19: =COUNTIF(Cliente!$C:$C,Geral!$C19) -> 6 | BZ19: =SUMIF(Rede!$C:$C,Geral!$C19,Rede!$AW:$AW) -> 6 | CA19: =BZ19/BY19 -> 1 | CB19: =BZ19-BY19 -> 0 | CC19: =IFERROR(AVERAGEIFS(Cliente!$CU:$CU,Cliente!$C:$C,Geral!$C19,Cliente!$CU:$CU,">0"),0) -> 65.7375 | CD19: =COUNTIF(Cliente!$C:$C,Geral!$C19) -> 6 | CE19: =SUMIF(Rede!$C:$C,Geral!$C19,Rede!$AZ:$AZ) -> 0 | CF19: =CE19/CD19 -> 0 | CG19: =CE19-CD19 -> -6 | CH19: =IFERROR(AVERAGEIFS(Cliente!$DD:$DD,Cliente!$C:$C,Geral!$C19,Cliente!$DD:$DD,">0"),0) -> 0
B20: NORTE MC/KA D | C20: 359 | D20: MC-ITPE D | E20: MARCELO SCHEFFLER | F20: =COUNTIF(Rede!$C:$C,Geral!$C20) -> 3 | G20: =COUNTIF(Cliente!$C:$C,Geral!$C20) -> 7 | H20: =SUMIF(Rede!$C:$C,Geral!$C20,Rede!$G:$G) -> 7 | I20: =IFERROR(H20/G20,0) -> 1 | J20: =H20-G20 -> 0 | K20: =IFERROR(AVERAGEIFS(Cliente!$L:$L,Cliente!$C:$C,Geral!$C20,Cliente!$L:$L,">0"),0) -> 71.365833 | L20: =COUNTIF(Cliente!$C:$C,Geral!$C20) -> 7 | M20: =SUMIF(Rede!$C:$C,Geral!$C20,Rede!$J:$J) -> 7 | N20: =IFERROR(M20/L20,0) -> 1 | O20: =M20-L20 -> 0 | P20: =IFERROR(AVERAGEIFS(Cliente!$S:$S,Cliente!$C:$C,Geral!$C20,Cliente!$S:$S,">0"),0) -> 69.185714 | Q20: =COUNTIF(Cliente!$C:$C,Geral!$C20) -> 7 | R20: =SUMIF(Rede!$C:$C,Geral!$C20,Rede!$M:$M) -> 7 | S20: =IFERROR(R20/Q20,0) -> 1 | T20: =R20-Q20 -> 0 | U20: =IFERROR(AVERAGEIFS(Cliente!$Y:$Y,Cliente!$C:$C,Geral!$C20,Cliente!$Y:$Y,">0"),0) -> 68.403929 | V20: =COUNTIF(Cliente!$C:$C,Geral!$C20) -> 7 | W20: =SUMIF(Rede!$C:$C,Geral!$C20,Rede!$P:$P) -> 7 | X20: =IFERROR(W20/V20,0) -> 1 | Y20: =W20-V20 -> 0 | Z20: =IFERROR(AVERAGEIFS(Cliente!$AE:$AE,Cliente!$C:$C,Geral!$C20,Cliente!$AE:$AE,">0"),0) -> 76.507857 | AA20: =COUNTIF(Cliente!$C:$C,Geral!$C20) -> 7 | AB20: =SUMIF(Rede!$C:$C,Geral!$C20,Rede!$S:$S) -> 3 | AC20: =IFERROR(AB20/AA20,0) -> 0.42857143 | AD20: =AB20-AA20 -> -4 | AE20: =IFERROR(AVERAGEIFS(Cliente!$AG:$AG,Cliente!$C:$C,Geral!$C20,Cliente!$AG:$AG,">0"),0) -> 52.657857 | AF20: =COUNTIF(Cliente!$C:$C,Geral!$C20) -> 7 | AG20: =SUMIF(Rede!$C:$C,Geral!$C20,Rede!$V:$V) -> 3 | AH20: =AG20/AF20 -> 0.42857143 | AI20: =AG20-AF20 -> -4 | AJ20: =IFERROR(AVERAGEIFS(Cliente!$AN:$AN,Cliente!$C:$C,Geral!$C20,Cliente!$AN:$AN,">0"),0) -> 63.428333 | AK20: =COUNTIF(Cliente!$C:$C,Geral!$C20) -> 7 | AL20: =SUMIF(Rede!$C:$C,Geral!$C20,Rede!$Y:$Y) -> 7 | AM20: =AL20/AK20 -> 1 | AN20: =AL20-AK20 -> 0 | AO20: =IFERROR(AVERAGEIFS(Cliente!$AU:$AU,Cliente!$C:$C,Geral!$C20,Cliente!$AU:$AU,">0"),0) -> 60.729286 | AP20: =COUNTIF(Cliente!$C:$C,Geral!$C20) -> 7 | AQ20: =SUMIF(Rede!$C:$C,Geral!$C20,Rede!$AB:$AB) -> 7 | AR20: =AQ20/AP20 -> 1 | AS20: =AQ20-AP20 -> 0 | AT20: =IFERROR(AVERAGEIFS(Cliente!$BB:$BB,Cliente!$C:$C,Geral!$C20,Cliente!$BB:$BB,">0"),0) -> 70.060714 | AU20: =COUNTIF(Cliente!$C:$C,Geral!$C20) -> 7 | AV20: =SUMIF(Rede!$C:$C,Geral!$C20,Rede!$AE:$AE) -> 3 | AW20: =IFERROR(AV20/AU20,0) -> 0.42857143 | AX20: =AV20-AU20 -> -4 | AY20: =AVERAGE(BD20,BI20,BN20) -> 84.385 | AZ20: =COUNTIF(Cliente!$C:$C,Geral!$C20) -> 7 | BA20: =SUMIF(Rede!$C:$C,Geral!$C20,Rede!$AH:$AH) -> 3 | BB20: =BA20/AZ20 -> 0.42857143 | BC20: =BA20-AZ20 -> -4 | BD20: =IFERROR(AVERAGEIFS(Cliente!$BL:$BL,Cliente!$C:$C,Geral!$C20,Cliente!$BL:$BL,">0"),0) -> 78.338333 | BE20: =COUNTIF(Cliente!$C:$C,Geral!$C20) -> 7 | BF20: =SUMIF(Rede!$C:$C,Geral!$C20,Rede!$AK:$AK) -> 3 | BG20: =BF20/BE20 -> 0.42857143 | BH20: =BF20-BE20 -> -4 | BI20: =IFERROR(AVERAGEIFS(Cliente!$BS:$BS,Cliente!$C:$C,Geral!$C20,Cliente!$BS:$BS,">0"),0) -> 86.666667 | BJ20: =COUNTIF(Cliente!$C:$C,Geral!$C20) -> 7 | BK20: =SUMIF(Rede!$C:$C,Geral!$C20,Rede!$AN:$AN) -> 4 | BL20: =BK20/BJ20 -> 0.57142857 | BM20: =BK20-BJ20 -> -3 | BN20: =IFERROR(AVERAGEIFS(Cliente!$BZ:$BZ,Cliente!$C:$C,Geral!$C20,Cliente!$BZ:$BZ,">0"),0) -> 88.15 | BO20: =COUNTIF(Cliente!$C:$C,Geral!$C20) -> 7 | BP20: =SUMIF(Rede!$C:$C,Geral!$C20,Rede!$AQ:$AQ) -> 4 | BQ20: =IFERROR(BP20/BO20,0) -> 0.57142857 | BR20: =BP20-BO20 -> -3 | BS20: =IFERROR(AVERAGEIFS(Cliente!$CB:$CB,Cliente!$C:$C,Geral!$C20,Cliente!$CB:$CB,">0"),0) -> 76.618056 | BT20: =COUNTIF(Cliente!$C:$C,Geral!$C20) -> 7 | BU20: =SUMIF(Rede!$C:$C,Geral!$C20,Rede!$AT:$AT) -> 4 | BV20: =BU20/BT20 -> 0.57142857 | BW20: =BU20-BT20 -> -3 | BX20: =IFERROR(AVERAGEIFS(Cliente!$CL:$CL,Cliente!$C:$C,Geral!$C20,Cliente!$CL:$CL,">0"),0) -> 92.25 | BY20: =COUNTIF(Cliente!$C:$C,Geral!$C20) -> 7 | BZ20: =SUMIF(Rede!$C:$C,Geral!$C20,Rede!$AW:$AW) -> 5 | CA20: =BZ20/BY20 -> 0.71428571 | CB20: =BZ20-BY20 -> -2 | CC20: =IFERROR(AVERAGEIFS(Cliente!$CU:$CU,Cliente!$C:$C,Geral!$C20,Cliente!$CU:$CU,">0"),0) -> 91.655 | CD20: =COUNTIF(Cliente!$C:$C,Geral!$C20) -> 7 | CE20: =SUMIF(Rede!$C:$C,Geral!$C20,Rede!$AZ:$AZ) -> 6 | CF20: =CE20/CD20 -> 0.85714286 | CG20: =CE20-CD20 -> -1 | CH20: =IFERROR(AVERAGEIFS(Cliente!$DD:$DD,Cliente!$C:$C,Geral!$C20,Cliente!$DD:$DD,">0"),0) -> 91.975
B21: NORTE MC/KA D | C21: 3655 | D21: KA-BNU D | E21: NATHAN FREITAS FUZINATO | F21: =COUNTIF(Rede!$C:$C,Geral!$C21) -> 1 | G21: =COUNTIF(Cliente!$C:$C,Geral!$C21) -> 24 | H21: =SUMIF(Rede!$C:$C,Geral!$C21,Rede!$G:$G) -> 20 | I21: =IFERROR(H21/G21,0) -> 0.83333333 | J21: =H21-G21 -> -4 | K21: =IFERROR(AVERAGEIFS(Cliente!$L:$L,Cliente!$C:$C,Geral!$C21,Cliente!$L:$L,">0"),0) -> 65.618958 | L21: =COUNTIF(Cliente!$C:$C,Geral!$C21) -> 24 | M21: =SUMIF(Rede!$C:$C,Geral!$C21,Rede!$J:$J) -> 24 | N21: =IFERROR(M21/L21,0) -> 1 | O21: =M21-L21 -> 0 | P21: =IFERROR(AVERAGEIFS(Cliente!$S:$S,Cliente!$C:$C,Geral!$C21,Cliente!$S:$S,">0"),0) -> 65.034896 | Q21: =COUNTIF(Cliente!$C:$C,Geral!$C21) -> 24 | R21: =SUMIF(Rede!$C:$C,Geral!$C21,Rede!$M:$M) -> 20 | S21: =IFERROR(R21/Q21,0) -> 0.83333333 | T21: =R21-Q21 -> -4 | U21: =IFERROR(AVERAGEIFS(Cliente!$Y:$Y,Cliente!$C:$C,Geral!$C21,Cliente!$Y:$Y,">0"),0) -> 66.477375 | V21: =COUNTIF(Cliente!$C:$C,Geral!$C21) -> 24 | W21: =SUMIF(Rede!$C:$C,Geral!$C21,Rede!$P:$P) -> 24 | X21: =IFERROR(W21/V21,0) -> 1 | Y21: =W21-V21 -> 0 | Z21: =IFERROR(AVERAGEIFS(Cliente!$AE:$AE,Cliente!$C:$C,Geral!$C21,Cliente!$AE:$AE,">0"),0) -> 76.424167 | AA21: =COUNTIF(Cliente!$C:$C,Geral!$C21) -> 24 | AB21: =SUMIF(Rede!$C:$C,Geral!$C21,Rede!$S:$S) -> 24 | AC21: =IFERROR(AB21/AA21,0) -> 1 | AD21: =AB21-AA21 -> 0 | AE21: =IFERROR(AVERAGEIFS(Cliente!$AG:$AG,Cliente!$C:$C,Geral!$C21,Cliente!$AG:$AG,">0"),0) -> 65.871736 | AF21: =COUNTIF(Cliente!$C:$C,Geral!$C21) -> 24 | AG21: =SUMIF(Rede!$C:$C,Geral!$C21,Rede!$V:$V) -> 24 | AH21: =AG21/AF21 -> 1 | AI21: =AG21-AF21 -> 0 | AJ21: =IFERROR(AVERAGEIFS(Cliente!$AN:$AN,Cliente!$C:$C,Geral!$C21,Cliente!$AN:$AN,">0"),0) -> 62.403125 | AK21: =COUNTIF(Cliente!$C:$C,Geral!$C21) -> 24 | AL21: =SUMIF(Rede!$C:$C,Geral!$C21,Rede!$Y:$Y) -> 24 | AM21: =AL21/AK21 -> 1 | AN21: =AL21-AK21 -> 0 | AO21: =IFERROR(AVERAGEIFS(Cliente!$AU:$AU,Cliente!$C:$C,Geral!$C21,Cliente!$AU:$AU,">0"),0) -> 61.493958 | AP21: =COUNTIF(Cliente!$C:$C,Geral!$C21) -> 24 | AQ21: =SUMIF(Rede!$C:$C,Geral!$C21,Rede!$AB:$AB) -> 24 | AR21: =AQ21/AP21 -> 1 | AS21: =AQ21-AP21 -> 0 | AT21: =IFERROR(AVERAGEIFS(Cliente!$BB:$BB,Cliente!$C:$C,Geral!$C21,Cliente!$BB:$BB,">0"),0) -> 73.718125 | AU21: =COUNTIF(Cliente!$C:$C,Geral!$C21) -> 24 | AV21: =SUMIF(Rede!$C:$C,Geral!$C21,Rede!$AE:$AE) -> 18 | AW21: =IFERROR(AV21/AU21,0) -> 0.75 | AX21: =AV21-AU21 -> -6 | AY21: =AVERAGE(BD21,BI21,BN21) -> 83.07277 | AZ21: =COUNTIF(Cliente!$C:$C,Geral!$C21) -> 24 | BA21: =SUMIF(Rede!$C:$C,Geral!$C21,Rede!$AH:$AH) -> 24 | BB21: =BA21/AZ21 -> 1 | BC21: =BA21-AZ21 -> 0 | BD21: =IFERROR(AVERAGEIFS(Cliente!$BL:$BL,Cliente!$C:$C,Geral!$C21,Cliente!$BL:$BL,">0"),0) -> 71.383333 | BE21: =COUNTIF(Cliente!$C:$C,Geral!$C21) -> 24 | BF21: =SUMIF(Rede!$C:$C,Geral!$C21,Rede!$AK:$AK) -> 20 | BG21: =BF21/BE21 -> 0.83333333 | BH21: =BF21-BE21 -> -4 | BI21: =IFERROR(AVERAGEIFS(Cliente!$BS:$BS,Cliente!$C:$C,Geral!$C21,Cliente!$BS:$BS,">0"),0) -> 86.0195 | BJ21: =COUNTIF(Cliente!$C:$C,Geral!$C21) -> 24 | BK21: =SUMIF(Rede!$C:$C,Geral!$C21,Rede!$AN:$AN) -> 21 | BL21: =BK21/BJ21 -> 0.875 | BM21: =BK21-BJ21 -> -3 | BN21: =IFERROR(AVERAGEIFS(Cliente!$BZ:$BZ,Cliente!$C:$C,Geral!$C21,Cliente!$BZ:$BZ,">0"),0) -> 91.815476 | BO21: =COUNTIF(Cliente!$C:$C,Geral!$C21) -> 24 | BP21: =SUMIF(Rede!$C:$C,Geral!$C21,Rede!$AQ:$AQ) -> 6 | BQ21: =IFERROR(BP21/BO21,0) -> 0.25 | BR21: =BP21-BO21 -> -18 | BS21: =IFERROR(AVERAGEIFS(Cliente!$CB:$CB,Cliente!$C:$C,Geral!$C21,Cliente!$CB:$CB,">0"),0) -> 67.372319 | BT21: =COUNTIF(Cliente!$C:$C,Geral!$C21) -> 24 | BU21: =SUMIF(Rede!$C:$C,Geral!$C21,Rede!$AT:$AT) -> 22 | BV21: =BU21/BT21 -> 0.91666667 | BW21: =BU21-BT21 -> -2 | BX21: =IFERROR(AVERAGEIFS(Cliente!$CL:$CL,Cliente!$C:$C,Geral!$C21,Cliente!$CL:$CL,">0"),0) -> 93.690909 | BY21: =COUNTIF(Cliente!$C:$C,Geral!$C21) -> 24 | BZ21: =SUMIF(Rede!$C:$C,Geral!$C21,Rede!$AW:$AW) -> 20 | CA21: =BZ21/BY21 -> 0.83333333 | CB21: =BZ21-BY21 -> -4 | CC21: =IFERROR(AVERAGEIFS(Cliente!$CU:$CU,Cliente!$C:$C,Geral!$C21,Cliente!$CU:$CU,">0"),0) -> 95.6195 | CD21: =COUNTIF(Cliente!$C:$C,Geral!$C21) -> 24 | CE21: =SUMIF(Rede!$C:$C,Geral!$C21,Rede!$AZ:$AZ) -> 7 | CF21: =CE21/CD21 -> 0.29166667 | CG21: =CE21-CD21 -> -17 | CH21: =IFERROR(AVERAGEIFS(Cliente!$DD:$DD,Cliente!$C:$C,Geral!$C21,Cliente!$DD:$DD,">0"),0) -> 96.442857
B22: NORTE MC/KA D | C22: 4066 | D22: MC-BNU D | E22: MURIEL DERCIO VOCKES | F22: =COUNTIF(Rede!$C:$C,Geral!$C22) -> 1 | G22: =COUNTIF(Cliente!$C:$C,Geral!$C22) -> 1 | H22: =SUMIF(Rede!$C:$C,Geral!$C22,Rede!$G:$G) -> 1 | I22: =IFERROR(H22/G22,0) -> 1 | J22: =H22-G22 -> 0 | K22: =IFERROR(AVERAGEIFS(Cliente!$L:$L,Cliente!$C:$C,Geral!$C22,Cliente!$L:$L,">0"),0) -> 86.575 | L22: =COUNTIF(Cliente!$C:$C,Geral!$C22) -> 1 | M22: =SUMIF(Rede!$C:$C,Geral!$C22,Rede!$J:$J) -> 1 | N22: =IFERROR(M22/L22,0) -> 1 | O22: =M22-L22 -> 0 | P22: =IFERROR(AVERAGEIFS(Cliente!$S:$S,Cliente!$C:$C,Geral!$C22,Cliente!$S:$S,">0"),0) -> 82.975 | Q22: =COUNTIF(Cliente!$C:$C,Geral!$C22) -> 1 | R22: =SUMIF(Rede!$C:$C,Geral!$C22,Rede!$M:$M) -> 1 | S22: =IFERROR(R22/Q22,0) -> 1 | T22: =R22-Q22 -> 0 | U22: =IFERROR(AVERAGEIFS(Cliente!$Y:$Y,Cliente!$C:$C,Geral!$C22,Cliente!$Y:$Y,">0"),0) -> 84.375 | V22: =COUNTIF(Cliente!$C:$C,Geral!$C22) -> 1 | W22: =SUMIF(Rede!$C:$C,Geral!$C22,Rede!$P:$P) -> 1 | X22: =IFERROR(W22/V22,0) -> 1 | Y22: =W22-V22 -> 0 | Z22: =IFERROR(AVERAGEIFS(Cliente!$AE:$AE,Cliente!$C:$C,Geral!$C22,Cliente!$AE:$AE,">0"),0) -> 92.375 | AA22: =COUNTIF(Cliente!$C:$C,Geral!$C22) -> 1 | AB22: =SUMIF(Rede!$C:$C,Geral!$C22,Rede!$S:$S) -> 1 | AC22: =IFERROR(AB22/AA22,0) -> 1 | AD22: =AB22-AA22 -> 0 | AE22: =IFERROR(AVERAGEIFS(Cliente!$AG:$AG,Cliente!$C:$C,Geral!$C22,Cliente!$AG:$AG,">0"),0) -> 68.908333 | AF22: =COUNTIF(Cliente!$C:$C,Geral!$C22) -> 1 | AG22: =SUMIF(Rede!$C:$C,Geral!$C22,Rede!$V:$V) -> 1 | AH22: =AG22/AF22 -> 1 | AI22: =AG22-AF22 -> 0 | AJ22: =IFERROR(AVERAGEIFS(Cliente!$AN:$AN,Cliente!$C:$C,Geral!$C22,Cliente!$AN:$AN,">0"),0) -> 62.58 | AK22: =COUNTIF(Cliente!$C:$C,Geral!$C22) -> 1 | AL22: =SUMIF(Rede!$C:$C,Geral!$C22,Rede!$Y:$Y) -> 1 | AM22: =AL22/AK22 -> 1 | AN22: =AL22-AK22 -> 0 | AO22: =IFERROR(AVERAGEIFS(Cliente!$AU:$AU,Cliente!$C:$C,Geral!$C22,Cliente!$AU:$AU,">0"),0) -> 69.105 | AP22: =COUNTIF(Cliente!$C:$C,Geral!$C22) -> 1 | AQ22: =SUMIF(Rede!$C:$C,Geral!$C22,Rede!$AB:$AB) -> 1 | AR22: =AQ22/AP22 -> 1 | AS22: =AQ22-AP22 -> 0 | AT22: =IFERROR(AVERAGEIFS(Cliente!$BB:$BB,Cliente!$C:$C,Geral!$C22,Cliente!$BB:$BB,">0"),0) -> 75.04 | AU22: =COUNTIF(Cliente!$C:$C,Geral!$C22) -> 1 | AV22: =SUMIF(Rede!$C:$C,Geral!$C22,Rede!$AE:$AE) -> 1 | AW22: =IFERROR(AV22/AU22,0) -> 1 | AX22: =AV22-AU22 -> 0 | AY22: =AVERAGE(BD22,BI22,BN22) -> 85.578333 | AZ22: =COUNTIF(Cliente!$C:$C,Geral!$C22) -> 1 | BA22: =SUMIF(Rede!$C:$C,Geral!$C22,Rede!$AH:$AH) -> 1 | BB22: =BA22/AZ22 -> 1 | BC22: =BA22-AZ22 -> 0 | BD22: =IFERROR(AVERAGEIFS(Cliente!$BL:$BL,Cliente!$C:$C,Geral!$C22,Cliente!$BL:$BL,">0"),0) -> 80 | BE22: =COUNTIF(Cliente!$C:$C,Geral!$C22) -> 1 | BF22: =SUMIF(Rede!$C:$C,Geral!$C22,Rede!$AK:$AK) -> 1 | BG22: =BF22/BE22 -> 1 | BH22: =BF22-BE22 -> 0 | BI22: =IFERROR(AVERAGEIFS(Cliente!$BS:$BS,Cliente!$C:$C,Geral!$C22,Cliente!$BS:$BS,">0"),0) -> 80 | BJ22: =COUNTIF(Cliente!$C:$C,Geral!$C22) -> 1 | BK22: =SUMIF(Rede!$C:$C,Geral!$C22,Rede!$AN:$AN) -> 1 | BL22: =BK22/BJ22 -> 1 | BM22: =BK22-BJ22 -> 0 | BN22: =IFERROR(AVERAGEIFS(Cliente!$BZ:$BZ,Cliente!$C:$C,Geral!$C22,Cliente!$BZ:$BZ,">0"),0) -> 96.735 | BO22: =COUNTIF(Cliente!$C:$C,Geral!$C22) -> 1 | BP22: =SUMIF(Rede!$C:$C,Geral!$C22,Rede!$AQ:$AQ) -> 1 | BQ22: =IFERROR(BP22/BO22,0) -> 1 | BR22: =BP22-BO22 -> 0 | BS22: =IFERROR(AVERAGEIFS(Cliente!$CB:$CB,Cliente!$C:$C,Geral!$C22,Cliente!$CB:$CB,">0"),0) -> 98.4 | BT22: =COUNTIF(Cliente!$C:$C,Geral!$C22) -> 1 | BU22: =SUMIF(Rede!$C:$C,Geral!$C22,Rede!$AT:$AT) -> 1 | BV22: =BU22/BT22 -> 1 | BW22: =BU22-BT22 -> 0 | BX22: =IFERROR(AVERAGEIFS(Cliente!$CL:$CL,Cliente!$C:$C,Geral!$C22,Cliente!$CL:$CL,">0"),0) -> 95.2 | BY22: =COUNTIF(Cliente!$C:$C,Geral!$C22) -> 1 | BZ22: =SUMIF(Rede!$C:$C,Geral!$C22,Rede!$AW:$AW) -> 1 | CA22: =BZ22/BY22 -> 1 | CB22: =BZ22-BY22 -> 0 | CC22: =IFERROR(AVERAGEIFS(Cliente!$CU:$CU,Cliente!$C:$C,Geral!$C22,Cliente!$CU:$CU,">0"),0) -> 100 | CD22: =COUNTIF(Cliente!$C:$C,Geral!$C22) -> 1 | CE22: =SUMIF(Rede!$C:$C,Geral!$C22,Rede!$AZ:$AZ) -> 1 | CF22: =CE22/CD22 -> 1 | CG22: =CE22-CD22 -> 0 | CH22: =IFERROR(AVERAGEIFS(Cliente!$DD:$DD,Cliente!$C:$C,Geral!$C22,Cliente!$DD:$DD,">0"),0) -> 100
B23: TT | F23: =SUM(F15:F22) -> 14 | G23: =SUBTOTAL(9,G15:G22) -> 71 | H23: =SUM(H15:H22) -> 58 | I23: =IFERROR(H23/G23,0) -> 0.81690141 | J23: =H23-G23 -> -13 | K23: =K8 -> 63.814401 | L23: =SUM(L15:L22) -> 71 | M23: =SUM(M15:M22) -> 67 | N23: =M23/L23 -> 0.94366197 | O23: =M23-L23 -> -4 | P23: =P8 -> 61.70153 | Q23: =SUM(Q15:Q22) -> 71 | R23: =SUM(R15:R22) -> 65 | S23: =R23/Q23 -> 0.91549296 | T23: =R23-Q23 -> -6 | U23: =U8 -> 65.5923 | V23: =SUM(V15:V22) -> 71 | W23: =SUM(W15:W22) -> 68 | X23: =IFERROR(W23/V23,0) -> 0.95774648 | Y23: =W23-V23 -> -3 | Z23: =Z8 -> 75.672451 | AA23: =SUBTOTAL(9,AA15:AA22) -> 71 | AB23: =SUM(AB15:AB22) -> 47 | AC23: =IFERROR(AB23/AA23,0) -> 0.66197183 | AD23: =AB23-AA23 -> -24 | AE23: =AE8 -> 52.335566 | AF23: =SUM(AF15:AF22) -> 71 | AG23: =SUM(AG15:AG22) -> 58 | AH23: =AG23/AF23 -> 0.81690141 | AI23: =AG23-AF23 -> -13 | AJ23: =AJ8 -> 80.4 | AK23: =SUM(AK15:AK22) -> 71 | AL23: =SUM(AL15:AL22) -> 59 | AM23: =AL23/AK23 -> 0.83098592 | AN23: =AL23-AK23 -> -12 | AO23: =AO8 -> 80.4 | AP23: =SUM(AP15:AP22) -> 71 | AQ23: =SUM(AQ15:AQ22) -> 63 | AR23: =AQ23/AP23 -> 0.88732394 | AS23: =AQ23-AP23 -> -8 | AT23: =AT8 -> 69.654891 | AU23: =SUBTOTAL(9,AU15:AU22) -> 71 | AV23: =SUM(AV15:AV22) -> 50 | AW23: =IFERROR(AV23/AU23,0) -> 0.70422535 | AX23: =AV23-AU23 -> -21 | AY23: =AVERAGE(BD23,BI23,BN23) -> 81.127772 | AZ23: =SUM(AZ15:AZ22) -> 71 | BA23: =SUM(BA15:BA22) -> 63 | BB23: =BA23/AZ23 -> 0.88732394 | BC23: =BA23-AZ23 -> -8 | BD23: =Cliente!$BL$2 -> 72.09254 | BE23: =SUM(BE15:BE22) -> 71 | BF23: =SUM(BF15:BF22) -> 58 | BG23: =BF23/BE23 -> 0.81690141 | BH23: =BF23-BE23 -> -13 | BI23: =Cliente!$BS$2 -> 84.198103 | BJ23: =SUM(BJ15:BJ22) -> 71 | BK23: =SUM(BK15:BK22) -> 58 | BL23: =BK23/BJ23 -> 0.81690141 | BM23: =BK23-BJ23 -> -13 | BN23: =Cliente!$BZ$2 -> 87.092672 | BO23: =SUBTOTAL(9,BO15:BO22) -> 71 | BP23: =SUM(BP15:BP22) -> 30 | BQ23: =IFERROR(BP23/BO23,0) -> 0.42253521 | BR23: =BP23-BO23 -> -41 | BS23: =Cliente!$CB$2 -> 89.555484 | BT23: =SUM(BT15:BT22) -> 71 | BU23: =SUM(BU15:BU22) -> 58 | BV23: =BU23/BT23 -> 0.81690141 | BW23: =BU23-BT23 -> -13 | BX23: =Cliente!$CL$2 -> 88.177759 | BY23: =SUM(BY15:BY22) -> 71 | BZ23: =SUM(BZ15:BZ22) -> 57 | CA23: =BZ23/BY23 -> 0.8028169 | CB23: =BZ23-BY23 -> -14 | CC23: =Cliente!$CU$2 -> 90.117368 | CD23: =SUM(CD15:CD22) -> 71 | CE23: =SUM(CE15:CE22) -> 34 | CF23: =CE23/CD23 -> 0.47887324 | CG23: =CE23-CD23 -> -37 | CH23: =Cliente!$DD$2 -> 90.371324

Sheet Rede
E3: SOMA: | F3: =SUM(F6:F19) -> 71 | G3: =SUM(G6:G19) -> 58 | H3: =Cliente!L2 -> 63.814401 | I3: =SUM(I6:I19) -> 71 | J3: =SUM(J6:J19) -> 67 | K3: =Cliente!S2 -> 61.70153 | L3: =SUM(L6:L19) -> 71 | M3: =SUM(M6:M19) -> 65 | N3: =Cliente!Y2 -> 65.5923 | O3: =SUM(O6:O19) -> 71 | P3: =SUM(P6:P19) -> 68 | Q3: =Cliente!AE2 -> 75.672451 | R3: =SUM(R6:R19) -> 71 | S3: =SUM(S6:S19) -> 47 | T3: =Cliente!AG2 -> 52.335566 | U3: =SUM(U6:U19) -> 71 | V3: =SUM(V6:V19) -> 58 | W3: =Cliente!AN2 -> 62.570854 | X3: =SUM(X6:X19) -> 71 | Y3: =SUM(Y6:Y19) -> 59 | Z3: =Cliente!AU2 -> 60.757738 | AA3: =SUM(AA6:AA19) -> 71 | AB3: =SUM(AB6:AB19) -> 63 | AC3: =Cliente!BB2 -> 69.654891 | AD3: =SUM(AD6:AD19) -> 71 | AE3: =SUM(AE6:AE19) -> 50 | AF3: =Cliente!BF2 -> 42 | AG3: =SUM(AG6:AG19) -> 71 | AH3: =SUM(AH6:AH19) -> 63 | AI3: =Cliente!BL2 -> 72.09254 | AJ3: =SUM(AJ6:AJ19) -> 71 | AK3: =SUM(AK6:AK19) -> 58 | AL3: =Cliente!BS2 -> 84.198103 | AM3: =SUM(AM6:AM19) -> 71 | AN3: =SUM(AN6:AN19) -> 58 | AO3: =Cliente!BZ2 -> 87.092672 | AP3: =SUM(AP6:AP19) -> 71 | AQ3: =SUM(AQ6:AQ19) -> 30 | AR3: =Cliente!CB2 -> 89.555484 | AS3: =SUM(AS6:AS19) -> 71 | AT3: =SUM(AT6:AT19) -> 58 | AU3: =Cliente!CL2 -> 88.177759 | AV3: =SUM(AV6:AV19) -> 71 | AW3: =SUM(AW6:AW19) -> 57 | AX3: =Cliente!CU2 -> 90.117368 | AY3: =SUM(AY6:AY19) -> 71 | AZ3: =SUM(AZ6:AZ19) -> 34 | BA3: =Cliente!DD2 -> 90.371324
F4: Q1 - JUL A SET 25 | I4: JULHO 2025 | L4: AGOSTO 2025 | O4: SETEMBRO 2025 | R4: Q2 - OUT A DEZ 25 | U4: OUTUBRO 2025 | X4: NOVEMBRO 2025 | AA4: DEZEMBRO 2025 | AD4: Q3 - JAN A MAR 26 | AG4: JANEIRO 2026 | AJ4: FEVEREIRO 2026 | AM4: MARÇO 2026 | AP4: Q4 - ABR A JUN 26 | AS4: ABRIL 2026 | AV4: MAIO 2026 | AY4: JUNHO 2026
B5: EQUIPE | C5: CÓD | D5: ÁREA | E5: REDE | F5: LOJAS | G5: AUDITADA TRIMESTRE | H5: MÉDIA P/ REDE | I5: LOJAS | J5: AUDITADA | K5: MÉDIA P/ REDE | L5: LOJAS | M5: AUDITADA | N5: MÉDIA P/ REDE | O5: LOJAS | P5: AUDITADA | Q5: MÉDIA P/ REDE | R5: LOJAS | S5: AUDITADA TRIMESTRE | T5: MÉDIA P/ REDE | U5: LOJAS | V5: AUDITADA | W5: MÉDIA P/ REDE | X5: LOJAS | Y5: AUDITADA | Z5: MÉDIA P/ REDE | AA5: LOJAS | AB5: AUDITADA | AC5: MÉDIA P/ REDE | AD5: LOJAS | AE5: AUDITADA TRIMESTRE | AF5: MÉDIA P/ REDE | AG5: LOJAS | AH5: AUDITADA | AI5: MÉDIA P/ REDE | AJ5: LOJAS | AK5: AUDITADA | AL5: MÉDIA P/ REDE | AM5: LOJAS | AN5: AUDITADA | AO5: MÉDIA P/ REDE | AP5: LOJAS | AQ5: AUDITADA TRIMESTRE | AR5: MÉDIA P/ REDE | AS5: LOJAS | AT5: AUDITADA | AU5: MÉDIA P/ REDE | AV5: LOJAS | AW5: AUDITADA | AX5: MÉDIA P/ REDE | AY5: LOJAS | AZ5: AUDITADA | BA5: MÉDIA P/ REDE
B6: FLP-SUL MC/KA D | C6: 771 | D6: MC-FLP D | E6: REDE HIPER SELECT | F6: =COUNTIF(Cliente!$K:$K,Rede!$E6) -> 3 | G6: =SUMIF(Cliente!$K:$K,Rede!$E6,Cliente!$M:$M) -> 3 | H6: =IFERROR(AVERAGE(K6,N6,Q6),"") -> 50.060278 | I6: =COUNTIF(Cliente!$K:$K,Rede!$E6) -> 3 | J6: =COUNTIFS(Cliente!$K:$K,Rede!$E6,Cliente!$S:$S,">=0,01") -> 3 | K6: =IFERROR(AVERAGEIFS(Cliente!$S:$S,Cliente!$K:$K,Rede!$E6,Cliente!$S:$S,">0"),0) -> 32.814167 | L6: =COUNTIF(Cliente!$K:$K,Rede!$E6) -> 3 | M6: =COUNTIFS(Cliente!$K:$K,Rede!$E6,Cliente!$Y:$Y,">=0,01") -> 3 | N6: =IFERROR(AVERAGEIFS(Cliente!$Y:$Y,Cliente!$K:$K,Rede!$E6,Cliente!$Y:$Y,">0"),0) -> 46.045 | O6: =COUNTIF(Cliente!$K:$K,Rede!$E6) -> 3 | P6: =COUNTIFS(Cliente!$K:$K,Rede!$E6,Cliente!$AE:$AE,">=0,01") -> 3 | Q6: =IFERROR(AVERAGEIFS(Cliente!$AE:$AE,Cliente!$K:$K,Rede!$E6,Cliente!$AE:$AE,">0"),0) -> 71.321667 | R6: =COUNTIF(Cliente!$K:$K,Rede!$E6) -> 3 | S6: =SUMIF(Cliente!$K:$K,Rede!$E6,Cliente!$AH:$AH) -> 0 | T6: =IFERROR(AVERAGE(W6,Z6,AC6),"") -> 19.734167 | U6: =COUNTIF(Cliente!$K:$K,Rede!$E6) -> 3 | V6: =COUNTIFS(Cliente!$K:$K,Rede!$E6,Cliente!$AN:$AN,">=0,01") -> 2 | W6: =IFERROR(AVERAGEIFS(Cliente!$AN:$AN,Cliente!$K:$K,Rede!$E6,Cliente!AN:AN,">0"),0) -> 59.2025 | X6: =COUNTIF(Cliente!$K:$K,Rede!$E6) -> 3 | Y6: =COUNTIFS(Cliente!$K:$K,Rede!$E6,Cliente!$AU:$AU,">=0,01") -> 0 | Z6: =IFERROR(AVERAGEIFS(Cliente!$AU:$AU,Cliente!$K:$K,Rede!$E6,Cliente!$AU:$AU,">0"),0) -> 0 | AA6: =COUNTIF(Cliente!$K:$K,Rede!$E6) -> 3 | AB6: =COUNTIFS(Cliente!$K:$K,Rede!$E6,Cliente!$BB:$BB,">=0,01") -> 0 | AC6: =IFERROR(AVERAGEIFS(Cliente!$BB:$BB,Cliente!$K:$K,Rede!$E6,Cliente!$BB:$BB,">0"),0) -> 0 | AD6: =COUNTIF(Cliente!$K:$K,Rede!$E6) -> 3 | AE6: =SUMIF(Cliente!$K:$K,Rede!$E6,Cliente!$BE:$BE) -> 1 | AF6: =IFERROR(AVERAGE(AI6,AL6,AO6),"") -> 78.904167 | AG6: =COUNTIF(Cliente!$K:$K,Rede!$E6) -> 3 | AH6: =COUNTIFS(Cliente!$K:$K,Rede!$E6,Cliente!$BL:$BL,">=0,01") -> 2 | AI6: =IFERROR(AVERAGEIFS(Cliente!$BL:$BL,Cliente!$K:$K,Rede!$E6,Cliente!$BL:$BL,">0"),0) -> 71.7125 | AJ6: =COUNTIF(Cliente!$K:$K,Rede!$E6) -> 3 | AK6: =COUNTIFS(Cliente!$K:$K,Rede!$E6,Cliente!$BS:$BS,">=0,01") -> 2 | AL6: =IFERROR(AVERAGEIFS(Cliente!$BS:$BS,Cliente!$K:$K,Rede!$E6,Cliente!$BS:$BS,">0"),0) -> 79.4 | AM6: =COUNTIF(Cliente!$K:$K,Rede!$E6) -> 3 | AN6: =COUNTIFS(Cliente!$K:$K,Rede!$E6,Cliente!$BZ:$BZ,">=0,01") -> 1 | AO6: =IFERROR(AVERAGEIFS(Cliente!$BZ:$BZ,Cliente!$K:$K,Rede!$E6,Cliente!$BZ:$BZ,">0"),0) -> 85.6 | AP6: =COUNTIF(Cliente!$K:$K,Rede!$E6) -> 3 | AQ6: =SUMIF(Cliente!$K:$K,Rede!$E6,Cliente!$CC:$CC) -> 0 | AR6: =IFERROR(AVERAGE(AU6,AX6,BA6),"") -> 25.95 | AS6: =COUNTIF(Cliente!$K:$K,Rede!$E6) -> 3 | AT6: =COUNTIFS(Cliente!$K:$K,Rede!$E6,Cliente!$CL:$CL,">=0,01") -> 0 | AU6: =IFERROR(AVERAGEIFS(Cliente!$CL:$CL,Cliente!$K:$K,Rede!$E6,Cliente!$CL:$CL,">0"),0) -> 0 | AV6: =COUNTIF(Cliente!$K:$K,Rede!$E6) -> 3 | AW6: =COUNTIFS(Cliente!$K:$K,Rede!$E6,Cliente!$CU:$CU,">=0,01") -> 0 | AX6: =IFERROR(AVERAGEIFS(Cliente!$CU:$CU,Cliente!$K:$K,Rede!$E6,Cliente!$CU:$CU,">0"),0) -> 0 | AY6: =COUNTIF(Cliente!$K:$K,Rede!$E6) -> 3 | AZ6: =COUNTIFS(Cliente!$K:$K,Rede!$E6,Cliente!$DD:$DD,">=0,01") -> 1 | BA6: =IFERROR(AVERAGEIFS(Cliente!$DD:$DD,Cliente!$K:$K,Rede!$E6,Cliente!$DD:$DD,">0"),0) -> 77.85
B7: FLP-SUL MC/KA D | C7: 3919 | D7: MC-TBCR D | E7: REDE SM ROSSO | F7: =COUNTIF(Cliente!$K:$K,Rede!$E7) -> 6 | G7: =SUMIF(Cliente!$K:$K,Rede!$E7,Cliente!$M:$M) -> 4 | H7: =IFERROR(AVERAGE(K7,N7,Q7),"") -> 63.867 | I7: =COUNTIF(Cliente!$K:$K,Rede!$E7) -> 6 | J7: =COUNTIFS(Cliente!$K:$K,Rede!$E7,Cliente!$S:$S,">=0,01") -> 5 | K7: =IFERROR(AVERAGEIFS(Cliente!$S:$S,Cliente!$K:$K,Rede!$E7,Cliente!$S:$S,">0"),0) -> 58.7225 | L7: =COUNTIF(Cliente!$K:$K,Rede!$E7) -> 6 | M7: =COUNTIFS(Cliente!$K:$K,Rede!$E7,Cliente!$Y:$Y,">=0,01") -> 5 | N7: =IFERROR(AVERAGEIFS(Cliente!$Y:$Y,Cliente!$K:$K,Rede!$E7,Cliente!$Y:$Y,">0"),0) -> 57.411 | O7: =COUNTIF(Cliente!$K:$K,Rede!$E7) -> 6 | P7: =COUNTIFS(Cliente!$K:$K,Rede!$E7,Cliente!$AE:$AE,">=0,01") -> 6 | Q7: =IFERROR(AVERAGEIFS(Cliente!$AE:$AE,Cliente!$K:$K,Rede!$E7,Cliente!$AE:$AE,">0"),0) -> 75.4675 | R7: =COUNTIF(Cliente!$K:$K,Rede!$E7) -> 6 | S7: =SUMIF(Cliente!$K:$K,Rede!$E7,Cliente!$AH:$AH) -> 4 | T7: =IFERROR(AVERAGE(W7,Z7,AC7),"") -> 64.332667 | U7: =COUNTIF(Cliente!$K:$K,Rede!$E7) -> 6 | V7: =COUNTIFS(Cliente!$K:$K,Rede!$E7,Cliente!$AN:$AN,">=0,01") -> 5 | W7: =IFERROR(AVERAGEIFS(Cliente!$AN:$AN,Cliente!$K:$K,Rede!$E7,Cliente!AN:AN,">0"),0) -> 57.095 | X7: =COUNTIF(Cliente!$K:$K,Rede!$E7) -> 6 | Y7: =COUNTIFS(Cliente!$K:$K,Rede!$E7,Cliente!$AU:$AU,">=0,01") -> 5 | Z7: =IFERROR(AVERAGEIFS(Cliente!$AU:$AU,Cliente!$K:$K,Rede!$E7,Cliente!$AU:$AU,">0"),0) -> 65.596 | AA7: =COUNTIF(Cliente!$K:$K,Rede!$E7) -> 6 | AB7: =COUNTIFS(Cliente!$K:$K,Rede!$E7,Cliente!$BB:$BB,">=0,01") -> 5 | AC7: =IFERROR(AVERAGEIFS(Cliente!$BB:$BB,Cliente!$K:$K,Rede!$E7,Cliente!$BB:$BB,">0"),0) -> 70.307 | AD7: =COUNTIF(Cliente!$K:$K,Rede!$E7) -> 6 | AE7: =SUMIF(Cliente!$K:$K,Rede!$E7,Cliente!$BE:$BE) -> 6 | AF7: =IFERROR(AVERAGE(AI7,AL7,AO7),"") -> 76.6425 | AG7: =COUNTIF(Cliente!$K:$K,Rede!$E7) -> 6 | AH7: =COUNTIFS(Cliente!$K:$K,Rede!$E7,Cliente!$BL:$BL,">=0,01") -> 6 | AI7: =IFERROR(AVERAGEIFS(Cliente!$BL:$BL,Cliente!$K:$K,Rede!$E7,Cliente!$BL:$BL,">0"),0) -> 72.395833 | AJ7: =COUNTIF(Cliente!$K:$K,Rede!$E7) -> 6 | AK7: =COUNTIFS(Cliente!$K:$K,Rede!$E7,Cliente!$BS:$BS,">=0,01") -> 6 | AL7: =IFERROR(AVERAGEIFS(Cliente!$BS:$BS,Cliente!$K:$K,Rede!$E7,Cliente!$BS:$BS,">0"),0) -> 79.9625 | AM7: =COUNTIF(Cliente!$K:$K,Rede!$E7) -> 6 | AN7: =COUNTIFS(Cliente!$K:$K,Rede!$E7,Cliente!$BZ:$BZ,">=0,01") -> 6 | AO7: =IFERROR(AVERAGEIFS(Cliente!$BZ:$BZ,Cliente!$K:$K,Rede!$E7,Cliente!$BZ:$BZ,">0"),0) -> 77.569167 | AP7: =COUNTIF(Cliente!$K:$K,Rede!$E7) -> 6 | AQ7: =SUMIF(Cliente!$K:$K,Rede!$E7,Cliente!$CC:$CC) -> 4 | AR7: =IFERROR(AVERAGE(AU7,AX7,BA7),"") -> 82.718889 | AS7: =COUNTIF(Cliente!$K:$K,Rede!$E7) -> 6 | AT7: =COUNTIFS(Cliente!$K:$K,Rede!$E7,Cliente!$CL:$CL,">=0,01") -> 6 | AU7: =IFERROR(AVERAGEIFS(Cliente!$CL:$CL,Cliente!$K:$K,Rede!$E7,Cliente!$CL:$CL,">0"),0) -> 79.106667 | AV7: =COUNTIF(Cliente!$K:$K,Rede!$E7) -> 6 | AW7: =COUNTIFS(Cliente!$K:$K,Rede!$E7,Cliente!$CU:$CU,">=0,01") -> 6 | AX7: =IFERROR(AVERAGEIFS(Cliente!$CU:$CU,Cliente!$K:$K,Rede!$E7,Cliente!$CU:$CU,">0"),0) -> 87.325 | AY7: =COUNTIF(Cliente!$K:$K,Rede!$E7) -> 6 | AZ7: =COUNTIFS(Cliente!$K:$K,Rede!$E7,Cliente!$DD:$DD,">=0,01") -> 4 | BA7: =IFERROR(AVERAGEIFS(Cliente!$DD:$DD,Cliente!$K:$K,Rede!$E7,Cliente!$DD:$DD,">0"),0) -> 81.725
